Workbook

Sheet register_한솔55"
V1: MCLK
V2: mhz | W2: 16.128 | X2: 16.128 | Y2: 16.128 | Z2: 15.912 | AA2: 16.128 | AB2: 15.84 | AC2: 16.128 | AD2: 15.984 | AE2: 15.6 | AF2: 16.128
V3: ns | W3: =1/W2*1000 -> 62.003968 | X3: =1/X2*1000 -> 62.003968 | Y3: =1/Y2*1000 -> 62.003968 | Z3: =1/Z2*1000 -> 62.845651 | AA3: =1/AA2*1000 -> 62.003968 | AB3: =1/AB2*1000 -> 63.131313 | AC3: =1/AC2*1000 -> 62.003968 | AD3: =1/AD2*1000 -> 62.562563 | ... AF3: =1/AF2*1000 -> 62.003968 | AG3: =1/AE2 -> 0.064102564
B4: Type | C4: Address | D4: Register | F4: D15 | G4: D14 | H4: D13 | I4: D12 | J4: D11 | K4: D10 | L4: D9 | M4: D8 | N4: D7 | O4: D6 | P4: D5 | Q4: D4 | R4: D3 | S4: D2 | T4: D1 | U4: D0 | V4: SF# | W4: 128 | X4: 120 | Y4: 112 | Z4: 104 | AA4: 96 | AB4: 88 | AC4: 80 | AD4: 72 | AE4: 64 | AF4: 56
B6: CMD1 | C6: ‘h00 | D6: SOFT RESET | K6: x | L6: x | M6: BROADCAST | N6: x | O6: x | P6: x | Q6: x | R6: x | S6: RST3 | T6: RST2 | U6: RST1 | W6: 0x0001→0x0000 | X6: @ initial
M7: 0 | S7: 0 | T7: 0 | U7: 1 → 0
C8: ‘h01 | D8: MODE CONTROL | K8: INT_MCLK | L8: VS_FT | M8: VS_COMP | N8: KEEP_FRAME | O8: X2 | P8: X8 | Q8: NORMAL | R8: x | S8: x | T8: x | U8: DRV_MODE | W8: 0x0091
K9: 0 | L9: 0 | M9: 0 | N9: 1 | O9: 0 | P9: 0 | Q9: 1 | U9: 1
C10: ‘h02 | D10: FIX CONTROL | K10: DUP_O | L10: x | M10: LD_FORCE | N10: x | O10: LD_I_FIX | P10: DUTY_FIX | Q10: HD_FIX | R10: CS_OUT | S10: HOLD_OUT | T10: x | U10: CS/HD_FIX | W10: 0x0x0x→0x0400 | X10: CZ[1:0]= 1→2→3→0@1*6 (2→3→0→1@2*3)
K11: 1 | M11: var | O11: 0 | P11: 0 | Q11: 0 | R11: var | S11: var | U11: var
C12: ‘h03 | D12: CS/HOLD FIX CH | K12: x | L12: FIX_CH10 | M12: FIX_CH9 | N12: FIX_CH8 | O12: FIX_CH7 | P12: FIX_CH6 | Q12: FIX_CH5 | R12: FIX_CH4 | S12: FIX_CH3 | T12: FIX_CH2 | U12: FIX_CH1 | W12: 0x0063 | X12: CH1, CH6은 1*6 config
K13: 0 | L13: 0 | M13: 0 | N13: 0 | O13: 1 | P13: 1 | Q13: 0 | R13: 0 | S13: 0 | T13: 1 | U13: 1
B15: CMD2 | C15: ‘h00 | D15: FRAME SIZE | F15: x | G15: x | H15: SHSYNC_SIZE [5:0] | N15: SVSYNC_SIZE [7:0] | W15: 0x0680 | X15: 0x0678 | Y15: 0x0670 | Z15: 0x0668 | AA15: 0x0660 | AB15: 0x0658 | AC15: 0x0650 | AD15: 0x0648 | AE15: 0x0640 | AF15: 0x0638
K16: 6 | W16: =DEC2HEX(W4) -> 80 | X16: =DEC2HEX(X4) -> 78 | Y16: =DEC2HEX(Y4) -> 70 | Z16: =DEC2HEX(Z4) -> 68 | AA16: =DEC2HEX(AA4) -> 60 | AB16: =DEC2HEX(AB4) -> 58 | AC16: =DEC2HEX(AC4) -> 50 | AD16: =DEC2HEX(AD4) -> 48 | ... AF16: =DEC2HEX(AF4) -> 38
C17: ‘h01 | D17: FRAME START | F17: x | G17: SVSYNC_START2 [6:0] | N17: x | O17: SVSYNC_START1 [6:0] | W17: 0x4701 | X17: 0x4301 | Y17: 0x3F01 | Z17: 0x3B01 | AA17: 0x3601 | AB17: 0x3001 | AC17: 0x2C01 | AD17: 0x2801 | AE17: 0x2401 | AF17: 0x2001
W18: 71 | X18: 67 | Y18: 63 | Z18: 59 | AA18: 54 | AB18: 48 | AC18: 44 | AD18: 40 | AE18: 36 | AF18: 32
C19: ‘h02 | D19: CH S/SVSYNC DLY | F19: x | G19: x | H19: x | I19: CH_SIZE [4:0] | N19: x | O19: x | P19: x | Q19: SVSYNC_DELAY [4:0] | W19: 0x140E | X19: 0x140D | Y19: 0x140C | Z19: 0x140B | AA19: 0x140A | AB19: 0x140A | AC19: 0x1409 | AD19: 0x1408 | AE19: 0x1407 | AF19: 0x1406
W20: 14 | X20: 13 | Y20: 12 | Z20: 11 | AA20: 10 | AB20: 10 | AC20: 9 | AD20: 8 | AE20: 7 | AF20: 6
C21: ‘h03 | D21: SVSYNC OFFSET | F21: x | G21: SVSYNC_OFFSET [14:0] | W21: 0x0000
C23: ‘h04 | D23: SVSYNC PERIOD | F23: x | G23: SVSYNC_PERIOD [14:0] | W23: 0x041A | X23: 0x0460 | Y23: 0x04B0 | Z23: 0x04FB | AA23: 0x0578 | AB23: 0x05DC | AC23: 0x0690 | AD23: 0x073A | AE23: 0x0834 | AF23: 0x0960 | AG23: =10000/64/AG3 -> 2437.5 | AH23: 2435 | AI23: =_xlfn.CONCAT("0x", DEC2HEX(AH23)) -> 0x983
C25: ‘h05 | D25: SHSYNC PERIOD | F25: x | G25: x | H25: x | I25: SHSYNC_PERIOD [12:0] | W25: 0x00AF | X25: 0x00BA | Y25: 0x00C8 | Z25: 0x00D4 | AA25: 0x00E9 | AB25: 0x00FA | AC25: 0x0118 | AD25: 0x0134 | AE25: 0x015E | AF25: 0x0190 | AG25: =10000/64/6/AG3 -> 406.25 | AH25: 406 | AI25: =_xlfn.CONCAT("0x", DEC2HEX(AH25)) -> 0x196
C27: ‘h06 | D27: HOLD SIZE R1 | F27: HOLD_SIZE4 [3:0] | J27: HOLD_SIZE3 [3:0] | N27: HOLD_SIZE2 [3:0] | R27: HOLD_SIZE1 [3:0] | W27: 0x0005
C29: ‘h07 | D29: HOLD SIZE R2 | F29: HOLD_SIZE8 [3:0] | J29: HOLD_SIZE7 [3:0] | N29: HOLD_SIZE6 [3:0] | R29: HOLD_SIZE5[3:0] | W29: 0x0050
C31: ‘h08 | D31: HOLD SIZE R3 | F31: x | G31: x | H31: x | I31: x | J31: x | K31: x | L31: x | M31: x | N31: HOLD_SIZE10 [3:0] | R31: HOLD_SIZE9 [3:0] | W31: 0x0000
C33: ‘h09 | D33: HOLD DUMY S1 | F33: x | G33: HOLD5_DUMY_SIZE [2:0] | J33: HOLD4_DUMY_SIZE [2:0] | M33: HOLD3_DUMY_SIZE [2:0] | P33: HOLD2_DUMY_SIZE [2:0] | S33: HOLD1_DUMY_SIZE [2:0] | W33: 0x0001
C35: ‘h0A | D35: HOLD DUMY S2 | F35: x | G35: HOLD10_DUMY_SIZE [2:0] | J35: HOLD9_DUMY_SIZE [2:0] | M35: HOLD8_DUMY_SIZE [2:0] | P35: HOLD7_DUMY_SIZE [2:0] | S35: HOLD6_DUMY_SIZE [2:0] | W35: 0x0001
C37: ‘h0B | D37: HOLD SETUP | F37: x | G37: x | H37: x | I37: x | J37: x | K37: x | L37: HOLD_SU [9:0] | W37: 0x0089 | X37: 0x0095 | Y37: 0x00A2 | Z37: 0x00AE | AA37: 0x00C3 | AB37: 0x00D4 | AC37: 0x00F2 | AD37: 0x010E | AE37: 0x0138 | AF37: 0x016A
C39: ‘h0C | D39: HOLD ON | F39: x | G39: x | H39: x | I39: x | J39: x | K39: x | L39: x | M39: HOLD_ON [8:0] | W39: 0x0020
C41: ‘h0D | D41: X PERIOD | F41: x | G41: x | H41: x | I41: x | J41: x | K41: x | L41: x | M41: x | N41: x | O41: X_PERIOD [6:0] | W41: 0x0010 | X41: 0x000F | Y41: 0x000E | Z41: 0x000D | AA41: 0x000C | AB41: 0x000B | AC41: 0x000A | AD41: 0x0009 | AE41: 0x0008 | AF41: 0x0007
C43: ‘h0E | D43: VSYNC_COMP1 | F43: x | G43: x | H43: x | I43: x | J43: VS_COMP1 [11:0] | W43: 0x0000
C45: ‘h0F | D45: VSYNC_COMP2 | F45: x | G45: x | H45: x | I45: x | J45: x | K45: x | L45: VS_COMP2 [9:0] | W45: 0x0000
C47: ‘h10 | D47: FRAME HD FIX | F47: x | G47: x | H47: FRAME_CZ [1:0] | J47: FRAME_VREF [11:0] | W47: variable
C49: ‘h11 | D49: DUTY FIX | F49: x | G49: x | H49: x | I49: x | J49: x | K49: x | L49: x | M49: x | N49: DUTY_FIX [7:0] | W49: 0x0000
C51: ‘h12 | D51: LD_I FIX | F51: x | G51: x | H51: x | I51: x | J51: LD_I_FIX [11:0] | W51: 0x0000
C53: ‘h13 | D53: STRB DUP EN | F53: x | G53: x | H53: x | I53: x | J53: x | K53: x | L53: ch10 | M53: ch9 | N53: ch8 | O53: ch7 | P53: ch6 | Q53: ch5 | R53: ch4 | S53: ch3 | T53: ch2 | U53: ch1 | W53: 0x0042
O54: 1 | T54: 1
C55: ‘h14 | D55: STB DUP CH R1 | F55: CH4_STB_DUP_CH[3:0] | J55: CH3_STB_DUP_CH[3:0] | N55: CH2_STB_DUP_CH[3:0] | R55: CH1_STB_DUP_CH[3:0] | W55: 0x0010
O56: 1
C57: ‘h15 | D57: STB DUP CH R2 | F57: CH8_STB_DUP_CH[3:0] | J57: CH7_STB_DUP_CH[3:0] | N57: CH6_STB_DUP_CH[3:0] | R57: CH5_STB_DUP_CH[3:0] | W57: 0x0600
L58: 6
...

Sheet mclk_dual
B3: basic common freqeucy | C3: khz | E3: 72 | G3: 72 | I3: 72 | K3: 72 | M3: 72 | O3: 72 | Q3: 72 | S3: 72 | U3: 72
B4: x | C4: ea | E4: 224 | G4: 224 | I4: 224 | K4: 221 | M4: 224 | O4: 220 | Q4: 224 | S4: 222 | U4: 224
B5: common frequence | C5: mhz | E5: 16.1666 | G5: =G3*G4/1000 -> 16.128 | I5: =I3*I4/1000 -> 16.128 | K5: =K3*K4/1000 -> 15.912 | M5: =M3*M4/1000 -> 16.128 | O5: =O3*O4/1000 -> 15.84 | Q5: =Q3*Q4/1000 -> 16.128 | S5: =S3*S4/1000 -> 15.984 | U5: =U3*U4/1000 -> 16.128
B6: tolerance | C6: -0.02
C7: 0.02
B9: mclk | C9: mhz | E9: =E5 -> 16.1666 | F9: =1/E9*1000 -> 61.855925 | G9: =G5 -> 16.128 | H9: =1/G9*1000 -> 62.003968 | I9: =I5 -> 16.128 | J9: =1/I9*1000 -> 62.003968 | K9: =K5 -> 15.912 | L9: =1/K9*1000 -> 62.845651 | M9: =M5 -> 16.128 | N9: =1/M9*1000 -> 62.003968 | O9: =O5 -> 15.84 | P9: =1/O9*1000 -> 63.131313 | Q9: =Q5 -> 16.128 | R9: =1/Q9*1000 -> 62.003968 | S9: =S5 -> 15.984 | T9: =1/S9*1000 -> 62.562563 | U9: =U5 -> 16.128 | V9: =1/U9*1000 -> 62.003968
B10: frame frequency | C10: hz | E10: 120 | F10: 100 | G10: 120 | H10: 100 | I10: 120 | J10: 100 | K10: 120 | L10: 100 | M10: 120 | N10: 100 | O10: 120 | P10: 100 | Q10: 120 | R10: 100 | S10: 120 | T10: 100 | U10: 120 | V10: 100
B11: frame period | C11: us | E11: =1/E10*1000000 -> 8333.3333 | F11: =1/F10*1000000 -> 10000 | G11: =1/G10*1000000 -> 8333.3333 | H11: =1/H10*1000000 -> 10000 | I11: =1/I10*1000000 -> 8333.3333 | J11: =1/J10*1000000 -> 10000 | K11: =1/K10*1000000 -> 8333.3333 | L11: =1/L10*1000000 -> 10000 | ... V11: =1/V10*1000000 -> 10000
B12: drive | C12: ea | E12: 2 | F12: =E12 -> 2 | G12: =F12 -> 2 | H12: =G12 -> 2 | I12: =H12 -> 2 | J12: =I12 -> 2 | K12: =J12 -> 2 | L12: =K12 -> 2 | M12: =L12 -> 2 | ... V12: =U12 -> 2
B13: total line # | C13: ea | E13: 12 | F13: =E13 -> 12 | G13: =F13 -> 12 | H13: =G13 -> 12 | I13: =H13 -> 12 | J13: =I13 -> 12 | K13: =J13 -> 12 | L13: =K13 -> 12 | M13: =L13 -> 12 | ... V13: =U13 -> 12
B15: SVSYNC_SIZE | C15: ea | E15: 64 | F15: =E15 -> 64 | G15: 120 | H15: =G15 -> 120 | I15: 112 | J15: =I15 -> 112 | K15: 104 | L15: =K15 -> 104 | M15: 128 | N15: =M15 -> 128 | O15: 88 | P15: =O15 -> 88 | Q15: 80 | R15: =Q15 -> 80 | S15: 72 | T15: =S15 -> 72 | U15: 64 | V15: =U15 -> 64
C16: hex | E16: =DEC2HEX(E15) -> 40 | F16: =DEC2HEX(F15) -> 40 | G16: =DEC2HEX(G15) -> 78 | H16: =DEC2HEX(H15) -> 78 | I16: =DEC2HEX(I15) -> 70 | J16: =DEC2HEX(J15) -> 70 | K16: =DEC2HEX(K15) -> 68 | L16: =DEC2HEX(L15) -> 68 | ... V16: =DEC2HEX(V15) -> 40
B17: sub frame period | C17: us | E17: =E11/E15 -> 130.20833 | F17: =F11/F15 -> 156.25 | G17: =G11/G15 -> 69.444444 | H17: =H11/H15 -> 83.333333 | I17: =I11/I15 -> 74.404762 | J17: =J11/J15 -> 89.285714 | K17: =K11/K15 -> 80.128205 | L17: =L11/L15 -> 96.153846 | ... V17: =V11/V15 -> 156.25
B18: clk#/sub frame | C18: ea | E18: =E17*1000/$F$9 -> 2105.026 | F18: =F17*1000/$F$9 -> 2526.0312 | G18: =G17*1000/$H$9 -> 1120 | H18: =H17*1000/$H$9 -> 1344 | I18: =I17*1000/$J$9 -> 1200 | J18: =J17*1000/$J$9 -> 1440 | K18: =K17*1000/$L$9 -> 1275 | L18: =L17*1000/$L$9 -> 1530 | M18: =M17*1000/$N$9 -> 1050 | N18: =N17*1000/$N$9 -> 1260 | O18: =O17*1000/$P$9 -> 1500 | P18: =P17*1000/$P$9 -> 1800 | Q18: =Q17*1000/$R$9 -> 1680 | R18: =R17*1000/$R$9 -> 2016 | S18: =S17*1000/$T$9 -> 1850 | T18: =T17*1000/$T$9 -> 2220 | U18: =U17*1000/$V$9 -> 2100 | V18: =V17*1000/$V$9 -> 2520
B19: SVSYNC_PERIOD | C19: ea | E19: =ROUNDDOWN(E18,0) -> 2105 | F19: =ROUNDDOWN(F18,0) -> 2526 | G19: =ROUNDDOWN(G18,0) -> 1120 | H19: =ROUNDDOWN(H18,0) -> 1344 | I19: =ROUNDDOWN(I18,0) -> 1200 | J19: =ROUNDDOWN(J18,0) -> 1440 | K19: =ROUNDDOWN(K18,0) -> 1275 | L19: =ROUNDDOWN(L18,0) -> 1530 | ... V19: =ROUNDDOWN(V18,0) -> 2520
C20: hex | E20: =DEC2HEX(E19) -> 839 | F20: =DEC2HEX(F19) -> 9DE | G20: =DEC2HEX(G19) -> 460 | H20: =DEC2HEX(H19) -> 540 | I20: =DEC2HEX(I19) -> 4B0 | J20: =DEC2HEX(J19) -> 5A0 | K20: =DEC2HEX(K19) -> 4FB | L20: =DEC2HEX(L19) -> 5FA | ... V20: =DEC2HEX(V19) -> 9D8
C21: us | E21: =E19*$F$9/1000 -> 130.20672 | F21: =F19*$F$9/1000 -> 156.24807 | G21: =G19*$H$9/1000 -> 69.444444 | H21: =H19*$H$9/1000 -> 83.333333 | I21: =I19*$J$9/1000 -> 74.404762 | J21: =J19*$J$9/1000 -> 89.285714 | K21: =K19*$L$9/1000 -> 80.128205 | L21: =L19*$L$9/1000 -> 96.153846 | M21: =M19*$N$9/1000 -> 65.104167 | N21: =N19*$N$9/1000 -> 78.125 | O21: =O19*$P$9/1000 -> 94.69697 | P21: =P19*$P$9/1000 -> 113.63636 | Q21: =Q19*$R$9/1000 -> 104.16667 | R21: =R19*$R$9/1000 -> 125 | S21: =S19*$T$9/1000 -> 115.74074 | T21: =T19*$T$9/1000 -> 138.88889 | U21: =U19*$V$9/1000 -> 130.20833 | V21: =V19*$V$9/1000 -> 156.25
B22: residue/sub frame | C22: ns | E22: =(E17-E21)*1000 -> 1.6108314 | F22: =(F17-F21)*1000 -> 1.9329977 | G22: =(G17-G21)*1000 -> 0 | H22: =(H17-H21)*1000 -> 0 | I22: =(I17-I21)*1000 -> 0 | J22: =(J17-J21)*1000 -> 0 | K22: =(K17-K21)*1000 -> 1.4210855e-11 | L22: =(L17-L21)*1000 -> 0 | ... V22: =(V17-V21)*1000 -> 0
C23: % | E23: =(E17-E21)/E17 -> 1.2371185e-05 | F23: =(F17-F21)/F17 -> 1.2371185e-05 | G23: =(G17-G21)/G17 -> 0 | H23: =(H17-H21)/H17 -> 0 | I23: =(I17-I21)/I17 -> 0 | J23: =(J17-J21)/J17 -> 0 | K23: =(K17-K21)/K17 -> 1.7735147e-16 | L23: =(L17-L21)/L17 -> 0 | ... V23: =(V17-V21)/V17 -> 0
B24: residue/frame | C24: us | E24: =E11-E21*E15 -> 0.10309321 | F24: =F11-F21*F15 -> 0.12371185 | G24: =G11-G21*G15 -> 0 | H24: =H11-H21*H15 -> 0 | I24: =I11-I21*I15 -> 0 | J24: =J11-J21*J15 -> 0 | K24: =K11-K21*K15 -> 0 | L24: =L11-L21*L15 -> 0 | ... V24: =V11-V21*V15 -> 0
C25: % | E25: =E24/E11 -> 1.2371185e-05 | F25: =F24/F11 -> 1.2371185e-05 | G25: =G24/G11 -> 0 | H25: =H24/H11 -> 0 | I25: =I24/I11 -> 0 | J25: =J24/J11 -> 0 | K25: =K24/K11 -> 0 | L25: =L24/L11 -> 0 | ... V25: =V24/V11 -> 0
B26: worst divi/SVSYNC | C26: % | E26: =E24/E21 -> 0.00079176564 | F26: =F24/F21 -> 0.00079176564 | G26: =G24/G21 -> 0 | H26: =H24/H21 -> 0 | I26: =I24/I21 -> 0 | J26: =J24/J21 -> 0 | K26: =K24/K21 -> 0 | L26: =L24/L21 -> 0 | ... V26: =V24/V21 -> 0
B28: SHSYNC_SIZE | C28: ea | E28: =E13/E12 -> 6 | F28: =F13/F12 -> 6 | G28: =G13/G12 -> 6 | H28: =H13/H12 -> 6 | I28: =I13/I12 -> 6 | J28: =J13/J12 -> 6 | K28: =K13/K12 -> 6 | L28: =L13/L12 -> 6 | ... V28: =V13/V12 -> 6
C29: hex | E29: =DEC2HEX(E28) -> 6 | F29: =DEC2HEX(F28) -> 6 | G29: =DEC2HEX(G28) -> 6 | H29: =DEC2HEX(H28) -> 6 | I29: =DEC2HEX(I28) -> 6 | J29: =DEC2HEX(J28) -> 6 | K29: =DEC2HEX(K28) -> 6 | L29: =DEC2HEX(L28) -> 6 | ... V29: =DEC2HEX(V28) -> 6
B30: shsync_period | C30: us | E30: =E17/E28 -> 21.701389 | F30: =F17/F28 -> 26.041667 | G30: =G17/G28 -> 11.574074 | H30: =H17/H28 -> 13.888889 | I30: =I17/I28 -> 12.400794 | J30: =J17/J28 -> 14.880952 | K30: =K17/K28 -> 13.354701 | L30: =L17/L28 -> 16.025641 | ... V30: =V17/V28 -> 26.041667
B31: clk#/shsync | C31: ea | E31: =E30*1000/$F$9 -> 350.83767 | F31: =F30*1000/$F$9 -> 421.00521 | G31: =G30*1000/$H$9 -> 186.66667 | H31: =H30*1000/$H$9 -> 224 | I31: =I30*1000/$J$9 -> 200 | J31: =J30*1000/$J$9 -> 240 | K31: =K30*1000/$L$9 -> 212.5 | L31: =L30*1000/$L$9 -> 255 | M31: =M30*1000/$N$9 -> 175 | N31: =N30*1000/$N$9 -> 210 | O31: =O30*1000/$P$9 -> 250 | P31: =P30*1000/$P$9 -> 300 | Q31: =Q30*1000/$R$9 -> 280 | R31: =R30*1000/$R$9 -> 336 | S31: =S30*1000/$T$9 -> 308.33333 | T31: =T30*1000/$T$9 -> 370 | U31: =U30*1000/$V$9 -> 350 | V31: =V30*1000/$V$9 -> 420
B32: SHSYNC_PERIOD | C32: ea | E32: =ROUNDDOWN(E31,0) -> 350 | F32: =ROUNDDOWN(F31,0) -> 421 | G32: =ROUNDDOWN(G31,0) -> 186 | H32: =ROUNDDOWN(H31,0) -> 224 | I32: =ROUNDDOWN(I31,0) -> 200 | J32: =ROUNDDOWN(J31,0) -> 240 | K32: =ROUNDDOWN(K31,0) -> 212 | L32: =ROUNDDOWN(L31,0) -> 255 | ... V32: =ROUNDDOWN(V31,0) -> 420
C33: hex | E33: =DEC2HEX(E32) -> 15E | F33: =DEC2HEX(F32) -> 1A5 | G33: =DEC2HEX(G32) -> BA | H33: =DEC2HEX(H32) -> E0 | I33: =DEC2HEX(I32) -> C8 | J33: =DEC2HEX(J32) -> F0 | K33: =DEC2HEX(K32) -> D4 | L33: =DEC2HEX(L32) -> FF | ... V33: =DEC2HEX(V32) -> 1A4
C34: us | E34: =E32*$F$9/1000 -> 21.649574 | F34: =F32*$F$9/1000 -> 26.041345 | G34: =G32*$H$9/1000 -> 11.532738 | H34: =H32*$H$9/1000 -> 13.888889 | I34: =I32*$J$9/1000 -> 12.400794 | J34: =J32*$J$9/1000 -> 14.880952 | K34: =K32*$L$9/1000 -> 13.323278 | L34: =L32*$L$9/1000 -> 16.025641 | M34: =M32*$N$9/1000 -> 10.850694 | N34: =N32*$N$9/1000 -> 13.020833 | O34: =O32*$P$9/1000 -> 15.782828 | P34: =P32*$P$9/1000 -> 18.939394 | Q34: =Q32*$R$9/1000 -> 17.361111 | R34: =R32*$R$9/1000 -> 20.833333 | S34: =S32*$T$9/1000 -> 19.269269 | T34: =T32*$T$9/1000 -> 23.148148 | U34: =U32*$V$9/1000 -> 21.701389 | V34: =V32*$V$9/1000 -> 26.041667
B35: residue/sub hsync | C35: us | E35: =E30-E34 -> 0.051815076 | F35: =F30-F34 -> 0.00032216628 | G35: =G30-G34 -> 0.041335979 | H35: =H30-H34 -> 0 | I35: =I30-I34 -> 0 | J35: =J30-J34 -> 0 | K35: =K30-K34 -> 0.031422826 | L35: =L30-L34 -> 0 | ... V35: =V30-V34 -> 0
B37: HOLD_SU | C37: ea | E37: =E32-E41-E40 -> 312 | F37: =F32-F41-F40 -> 383 | G37: =G32-G41-G40 -> 148 | H37: =H32-H41-H40 -> 186 | I37: =I32-I41-I40 -> 162 | J37: =J32-J41-J40 -> 202 | K37: =K32-K41-K40 -> 174 | L37: =L32-L41-L40 -> 217 | ... V37: =V32-V41-V40 -> 382
C38: hex | E38: =DEC2HEX(E37) -> 138 | F38: =DEC2HEX(F37) -> 17F | G38: =DEC2HEX(G37) -> 94 | H38: =DEC2HEX(H37) -> BA | I38: =DEC2HEX(I37) -> A2 | J38: =DEC2HEX(J37) -> CA | K38: =DEC2HEX(K37) -> AE | L38: =DEC2HEX(L37) -> D9 | ... V38: =DEC2HEX(V37) -> 17E
C39: us | E39: =E37*$F$9/1000 -> 19.299049 | F39: =F37*$F$9/1000 -> 23.690819 | G39: =G37*$H$9/1000 -> 9.1765873 | H39: =H37*$H$9/1000 -> 11.532738 | I39: =I37*$J$9/1000 -> 10.044643 | J39: =J37*$J$9/1000 -> 12.524802 | K39: =K37*$L$9/1000 -> 10.935143 | L39: =L37*$L$9/1000 -> 13.637506 | M39: =M37*$N$9/1000 -> 8.4945437 | N39: =N37*$N$9/1000 -> 10.664683 | O39: =O37*$P$9/1000 -> 13.383838 | P39: =P37*$P$9/1000 -> 16.540404 | Q39: =Q37*$R$9/1000 -> 15.00496 | R39: =R37*$R$9/1000 -> 18.477183 | S39: =S37*$T$9/1000 -> 16.891892 | T39: =T37*$T$9/1000 -> 20.770771 | U39: =U37*$V$9/1000 -> 19.345238 | V39: =V37*$V$9/1000 -> 23.685516
B40: adj cofficient | C40: ea | E40: 6 | F40: =E40 -> 6 | G40: 6 | H40: =G40 -> 6 | I40: 6 | J40: =I40 -> 6 | K40: 6 | L40: =K40 -> 6 | M40: 6 | N40: =M40 -> 6 | O40: 6 | P40: =O40 -> 6 | Q40: 6 | R40: =Q40 -> 6 | S40: 6 | T40: =S40 -> 6 | U40: 6 | V40: =U40 -> 6
B41: HOLD_ON | C41: ea | E41: 32 | F41: =E41 -> 32 | G41: 32 | H41: =G41 -> 32 | I41: 32 | J41: =I41 -> 32 | K41: 32 | L41: =K41 -> 32 | M41: 32 | N41: =M41 -> 32 | O41: 32 | P41: =O41 -> 32 | Q41: 32 | R41: =Q41 -> 32 | S41: 32 | T41: =S41 -> 32 | U41: 32 | V41: =U41 -> 32
C42: hex | E42: =DEC2HEX(E41) -> 20 | F42: =DEC2HEX(F41) -> 20 | G42: =DEC2HEX(G41) -> 20 | H42: =DEC2HEX(H41) -> 20 | I42: =DEC2HEX(I41) -> 20 | J42: =DEC2HEX(J41) -> 20 | K42: =DEC2HEX(K41) -> 20 | L42: =DEC2HEX(L41) -> 20 | ... V42: =DEC2HEX(V41) -> 20
C43: us | E43: =E41*$F$9/1000 -> 1.9793896 | F43: =F41*$F$9/1000 -> 1.9793896 | G43: =G41*$H$9/1000 -> 1.984127 | H43: =H41*$H$9/1000 -> 1.984127 | I43: =I41*$J$9/1000 -> 1.984127 | J43: =J41*$J$9/1000 -> 1.984127 | K43: =K41*$L$9/1000 -> 2.0110608 | L43: =L41*$L$9/1000 -> 2.0110608 | M43: =M41*$N$9/1000 -> 1.984127 | N43: =N41*$N$9/1000 -> 1.984127 | O43: =O41*$P$9/1000 -> 2.020202 | P43: =P41*$P$9/1000 -> 2.020202 | Q43: =Q41*$R$9/1000 -> 1.984127 | R43: =R41*$R$9/1000 -> 1.984127 | S43: =S41*$T$9/1000 -> 2.002002 | T43: =T41*$T$9/1000 -> 2.002002 | U43: =U41*$V$9/1000 -> 1.984127 | V43: =V41*$V$9/1000 -> 1.984127
B45: ADO setup time | C45: us | E45: =(E37-3)*$F$9/1000 -> 19.113481 | F45: =(F37-3)*$F$9/1000 -> 23.505252 | G45: =(G37-3)*$H$9/1000 -> 8.9905754 | H45: =(H37-3)*$H$9/1000 -> 11.346726 | I45: =(I37-3)*$J$9/1000 -> 9.858631 | J45: =(J37-3)*$J$9/1000 -> 12.33879 | K45: =(K37-3)*$L$9/1000 -> 10.746606 | L45: =(L37-3)*$L$9/1000 -> 13.448969 | M45: =(M37-3)*$N$9/1000 -> 8.3085317 | N45: =(N37-3)*$N$9/1000 -> 10.478671 | O45: =(O37-3)*$P$9/1000 -> 13.194444 | P45: =(P37-3)*$P$9/1000 -> 16.35101 | Q45: =(Q37-3)*$R$9/1000 -> 14.818948 | R45: =(R37-3)*$R$9/1000 -> 18.291171 | S45: =(S37-3)*$T$9/1000 -> 16.704204 | T45: =(T37-3)*$T$9/1000 -> 20.583083 | U45: =(U37-3)*$V$9/1000 -> 19.159226 | V45: =(V37-3)*$V$9/1000 -> 23.499504
B46: ADO hold time | C46: us | E46: =(E32-E37-E41+3)*$F$9/1000 -> 0.55670333 | F46: =(F32-F37-F41+3)*$F$9/1000 -> 0.55670333 | G46: =(G32-G37-G41+3)*$H$9/1000 -> 0.55803571 | H46: =(H32-H37-H41+3)*$H$9/1000 -> 0.55803571 | I46: =(I32-I37-I41+3)*$J$9/1000 -> 0.55803571 | J46: =(J32-J37-J41+3)*$J$9/1000 -> 0.55803571 | K46: =(K32-K37-K41+3)*$L$9/1000 -> 0.56561086 | L46: =(L32-L37-L41+3)*$L$9/1000 -> 0.56561086 | M46: =(M32-M37-M41+3)*$N$9/1000 -> 0.55803571 | N46: =(N32-N37-N41+3)*$N$9/1000 -> 0.55803571 | O46: =(O32-O37-O41+3)*$P$9/1000 -> 0.56818182 | P46: =(P32-P37-P41+3)*$P$9/1000 -> 0.56818182 | Q46: =(Q32-Q37-Q41+3)*$R$9/1000 -> 0.55803571 | R46: =(R32-R37-R41+3)*$R$9/1000 -> 0.55803571 | S46: =(S32-S37-S41+3)*$T$9/1000 -> 0.56306306 | T46: =(T32-T37-T41+3)*$T$9/1000 -> 0.56306306 | U46: =(U32-U37-U41+3)*$V$9/1000 -> 0.55803571 | V46: =(V32-V37-V41+3)*$V$9/1000 -> 0.55803571
B47: HOLD falling to CS rising | C47: us | E47: =(E32-E37-E41+9)*$F$9/1000 -> 0.92783888 | F47: =(F32-F37-F41+9)*$F$9/1000 -> 0.92783888 | G47: =(G32-G37-G41+9)*$H$9/1000 -> 0.93005952 | H47: =(H32-H37-H41+9)*$H$9/1000 -> 0.93005952 | I47: =(I32-I37-I41+9)*$J$9/1000 -> 0.93005952 | J47: =(J32-J37-J41+9)*$J$9/1000 -> 0.93005952 | K47: =(K32-K37-K41+9)*$L$9/1000 -> 0.94268477 | L47: =(L32-L37-L41+9)*$L$9/1000 -> 0.94268477 | M47: =(M32-M37-M41+9)*$N$9/1000 -> 0.93005952 | N47: =(N32-N37-N41+9)*$N$9/1000 -> 0.93005952 | O47: =(O32-O37-O41+9)*$P$9/1000 -> 0.9469697 | P47: =(P32-P37-P41+9)*$P$9/1000 -> 0.9469697 | Q47: =(Q32-Q37-Q41+9)*$R$9/1000 -> 0.93005952 | R47: =(R32-R37-R41+9)*$R$9/1000 -> 0.93005952 | S47: =(S32-S37-S41+9)*$T$9/1000 -> 0.93843844 | T47: =(T32-T37-T41+9)*$T$9/1000 -> 0.93843844 | U47: =(U32-U37-U41+9)*$V$9/1000 -> 0.93005952 | V47: =(V32-V37-V41+9)*$V$9/1000 -> 0.93005952
...

Sheet line delay
B2: dual drive | C2: 2 | E2: 2 | G2: 2 | I2: 2 | K2: 2 | M2: 2 | O2: 2 | Q2: 2 | S2: 2 | U2: 2
B3: sub-frame | C3: 128 | E3: 120 | G3: 112 | I3: 104 | K3: 96 | M3: 88 | O3: 80 | Q3: 72 | S3: 64 | U3: 56
B4: line # | C4: 5 | E4: 5 | G4: 5 | I4: 5 | K4: 5 | M4: 5 | O4: 5 | Q4: 5 | S4: 5 | U4: 5
B6: svsync_delay | C6: =(C3/K2)/(C4) -> 12.8 | E6: =(E3/$K$2)/(E4) -> 12 | G6: =(G3/$K$2)/(G4) -> 11.2 | I6: =(I3/$K$2)/(I4) -> 10.4 | K6: =(K3/$K$2)/(K4) -> 9.6 | M6: =(M3/$K$2)/(M4) -> 8.8 | O6: =(O3/$K$2)/(O4) -> 8 | Q6: =(Q3/$K$2)/(Q4) -> 7.2 | S6: =(S3/$K$2)/(S4) -> 6.4 | U6: =(U3/$K$2)/(U4) -> 5.6
C7: 14 | E7: 13 | G7: 12 | I7: 11 | K7: 10 | M7: 10 | O7: 9 | Q7: 8 | S7: 7 | U7: 6
B8: start1 | C8: 1 | E8: 1 | G8: 1 | I8: 1 | K8: 1 | M8: 1 | O8: 1 | Q8: 1 | S8: 1 | U8: 1
B9: start2 | C9: =C3/$K$2+1 -> 65 | E9: =E3/$K$2+1 -> 61 | G9: =G3/$K$2+1 -> 57 | I9: =I3/$K$2+1 -> 53 | K9: =K3/$K$2+1 -> 49 | M9: =M3/$K$2+1 -> 45 | O9: =O3/$K$2+1 -> 41 | Q9: =Q3/$K$2+1 -> 37 | S9: =S3/$K$2+1 -> 33 | U9: =U3/$K$2+1 -> 29
C11: start # | D11: gap | E11: start # | F11: gap | G11: start # | H11: gap | I11: start # | J11: gap | K11: start # | L11: gap | M11: start # | N11: gap | O11: start # | P11: gap | Q11: start # | R11: gap | S11: start # | T11: gap | U11: start # | V11: gap
B12: 1 | C12: =C8 -> 1 | E12: =E8 -> 1 | G12: =G8 -> 1 | I12: =I8 -> 1 | K12: =K8 -> 1 | M12: =M8 -> 1 | O12: =O8 -> 1 | Q12: =Q8 -> 1 | S12: =S8 -> 1 | U12: =U8 -> 1
B13: 2 | C13: =C12+C7 -> 15 | D13: =C13-C12 -> 14 | E13: =E12+E7 -> 14 | F13: =E13-E12 -> 13 | G13: =G12+G7 -> 13 | H13: =G13-G12 -> 12 | I13: =I12+I7 -> 12 | J13: =I13-I12 -> 11 | K13: =K12+K7 -> 11 | L13: =K13-K12 -> 10 | M13: =M12+M7 -> 11 | N13: =M13-M12 -> 10 | O13: =O12+O7 -> 10 | P13: =O13-O12 -> 9 | Q13: =Q12+Q7 -> 9 | R13: =Q13-Q12 -> 8 | S13: =S12+S7 -> 8 | T13: =S13-S12 -> 7 | U13: =U12+U7 -> 7 | V13: =U13-U12 -> 6
B14: 3 | C14: =C13+C7 -> 29 | D14: =C14-C13 -> 14 | E14: =E13+E7 -> 27 | F14: =E14-E13 -> 13 | G14: =G13+G7 -> 25 | H14: =G14-G13 -> 12 | I14: =I13+I7 -> 23 | J14: =I14-I13 -> 11 | K14: =K13+K7 -> 21 | L14: =K14-K13 -> 10 | M14: =M13+M7 -> 21 | N14: =M14-M13 -> 10 | O14: =O13+O7 -> 19 | P14: =O14-O13 -> 9 | Q14: =Q13+Q7 -> 17 | R14: =Q14-Q13 -> 8 | S14: =S13+S7 -> 15 | T14: =S14-S13 -> 7 | U14: =U13+U7 -> 13 | V14: =U14-U13 -> 6
B15: 4 | C15: =C14+C7 -> 43 | D15: =C15-C14 -> 14 | E15: =E14+E7 -> 40 | F15: =E15-E14 -> 13 | G15: =G14+G7 -> 37 | H15: =G15-G14 -> 12 | I15: =I14+I7 -> 34 | J15: =I15-I14 -> 11 | K15: =K14+K7 -> 31 | L15: =K15-K14 -> 10 | M15: =M14+M7 -> 31 | N15: =M15-M14 -> 10 | O15: =O14+O7 -> 28 | P15: =O15-O14 -> 9 | Q15: =Q14+Q7 -> 25 | R15: =Q15-Q14 -> 8 | S15: =S14+S7 -> 22 | T15: =S15-S14 -> 7 | U15: =U14+U7 -> 19 | V15: =U15-U14 -> 6
B16: 5 | C16: =C15+C7 -> 57 | D16: =C16-C15 -> 14 | E16: =E15+E7 -> 53 | F16: =E16-E15 -> 13 | G16: =G15+G7 -> 49 | H16: =G16-G15 -> 12 | I16: =I15+I7 -> 45 | J16: =I16-I15 -> 11 | K16: =K15+K7 -> 41 | L16: =K16-K15 -> 10 | M16: =M15+M7 -> 41 | N16: =M16-M15 -> 10 | O16: =O15+O7 -> 37 | P16: =O16-O15 -> 9 | Q16: =Q15+Q7 -> 33 | R16: =Q16-Q15 -> 8 | S16: =S15+S7 -> 29 | T16: =S16-S15 -> 7 | U16: =U15+U7 -> 25 | V16: =U16-U15 -> 6
B18: 6 | C18: =C9+6 -> 71 | D18: =C18-C16 -> 14 | E18: =E9+6 -> 67 | F18: =E18-E16 -> 14 | G18: =G9+6 -> 63 | H18: =G18-G16 -> 14 | I18: =I9+6 -> 59 | J18: =I18-I16 -> 14 | K18: =K9+5 -> 54 | L18: =K18-K16 -> 13 | M18: =M9+3 -> 48 | N18: =M18-M16 -> 7 | O18: =O9+3 -> 44 | P18: =O18-O16 -> 7 | Q18: =Q9+3 -> 40 | R18: =Q18-Q16 -> 7 | S18: =S9+3 -> 36 | T18: =S18-S16 -> 7 | U18: =U9+3 -> 32 | V18: =U18-U16 -> 7
B19: 7 | C19: =C18+C7 -> 85 | D19: =C19-C18 -> 14 | E19: =E18+E7 -> 80 | F19: =E19-E18 -> 13 | G19: =G18+G7 -> 75 | H19: =G19-G18 -> 12 | I19: =I18+I7 -> 70 | J19: =I19-I18 -> 11 | K19: =K18+K7 -> 64 | L19: =K19-K18 -> 10 | M19: =M18+M7 -> 58 | N19: =M19-M18 -> 10 | O19: =O18+O7 -> 53 | P19: =O19-O18 -> 9 | Q19: =Q18+Q7 -> 48 | R19: =Q19-Q18 -> 8 | S19: =S18+S7 -> 43 | T19: =S19-S18 -> 7 | U19: =U18+U7 -> 38 | V19: =U19-U18 -> 6
B20: 8 | C20: =C19+C7 -> 99 | D20: =C20-C19 -> 14 | E20: =E19+E7 -> 93 | F20: =E20-E19 -> 13 | G20: =G19+G7 -> 87 | H20: =G20-G19 -> 12 | I20: =I19+I7 -> 81 | J20: =I20-I19 -> 11 | K20: =K19+K7 -> 74 | L20: =K20-K19 -> 10 | M20: =M19+M7 -> 68 | N20: =M20-M19 -> 10 | O20: =O19+O7 -> 62 | P20: =O20-O19 -> 9 | Q20: =Q19+Q7 -> 56 | R20: =Q20-Q19 -> 8 | S20: =S19+S7 -> 50 | T20: =S20-S19 -> 7 | U20: =U19+U7 -> 44 | V20: =U20-U19 -> 6
B21: 9 | C21: =C20+C7 -> 113 | D21: =C21-C20 -> 14 | E21: =E20+E7 -> 106 | F21: =E21-E20 -> 13 | G21: =G20+G7 -> 99 | H21: =G21-G20 -> 12 | I21: =I20+I7 -> 92 | J21: =I21-I20 -> 11 | K21: =K20+K7 -> 84 | L21: =K21-K20 -> 10 | M21: =M20+M7 -> 78 | N21: =M21-M20 -> 10 | O21: =O20+O7 -> 71 | P21: =O21-O20 -> 9 | Q21: =Q20+Q7 -> 64 | R21: =Q21-Q20 -> 8 | S21: =S20+S7 -> 57 | T21: =S21-S20 -> 7 | U21: =U20+U7 -> 50 | V21: =U21-U20 -> 6
B22: 10 | C22: =C21+C7 -> 127 | D22: =C22-C21 -> 14 | E22: =E21+E7 -> 119 | F22: =E22-E21 -> 13 | G22: =G21+G7 -> 111 | H22: =G22-G21 -> 12 | I22: =I21+I7 -> 103 | J22: =I22-I21 -> 11 | K22: =K21+K7 -> 94 | L22: =K22-K21 -> 10 | M22: =M21+M7 -> 88 | N22: =M22-M21 -> 10 | O22: =O21+O7 -> 80 | P22: =O22-O21 -> 9 | Q22: =Q21+Q7 -> 72 | R22: =Q22-Q21 -> 8 | S22: =S21+S7 -> 64 | T22: =S22-S21 -> 7 | U22: =U21+U7 -> 56 | V22: =U22-U21 -> 6

Sheet SYSCLK
A1: STM32G473RCTx | J1: VCO output frequency | AA1: PLLCLK | AB1: system clock | AQ1: PLLCLK | AR1: system clock | BG1: PLLCLK | BH1: system clock | BW1: PLLCLK | BX1: system clock
D2: /PLLM | E2: VCO input frequency | I2: *PLLN | J2: 1 | K2: 2 | L2: 3 | M2: 4 | N2: 5 | O2: 6 | P2: 7 | Q2: 8 | R2: 9 | S2: 10 | T2: 11 | U2: 12 | V2: 13 | W2: 14 | X2: 15 | Y2: 16 | AA2: /PLLR | AB2: 2 | AQ2: /PLLR | AR2: 4 | BG2: /PLLR | BH2: 6 | BW2: /PLLR | BX2: 8 | DW2: /R
A3: HSE CLK | B3: 16 | D3: 1 | E3: =$B$3/D3 -> 16 | I3: 8 | J3: =$E$3*I3 -> 128 | K3: =$E$4*I3 -> 64 | L3: =$E$5*I3 -> 42.666667 | M3: =$E$6*I3 -> 32 | N3: =$E$7*I3 -> 25.6 | O3: =$E$8*I3 -> 21.333333 | P3: =$E$9*I3 -> 18.285714 | Q3: =$E$10*I3 -> 16 | R3: =$E$11*I3 -> 14.222222 | S3: =$E$12*I3 -> 12.8 | T3: =$E$13*I3 -> 11.636364 | U3: =$E$14*I3 -> 10.666667 | V3: =$E$15*I3 -> 9.8461538 | W3: =$E$16*I3 -> 9.1428571 | X3: =$E$17*I3 -> 8.5333333 | Y3: =$E$18*I3 -> 8 | AA3: =J3/$AB$2 -> 64 | AB3: =K3/$AB$2 -> 32 | AC3: =L3/$AB$2 -> 21.333333 | AD3: =M3/$AB$2 -> 16 | AE3: =N3/$AB$2 -> 12.8 | AF3: =O3/$AB$2 -> 10.666667 | AG3: =P3/$AB$2 -> 9.1428571 | AH3: =Q3/$AB$2 -> 8 | ... AP3: =Y3/$AB$2 -> 4 | AQ3: =J3/$AR$2 -> 32 | AR3: =K3/$AR$2 -> 16 | AS3: =L3/$AR$2 -> 10.666667 | AT3: =M3/$AR$2 -> 8 | AU3: =N3/$AR$2 -> 6.4 | AV3: =O3/$AR$2 -> 5.3333333 | AW3: =P3/$AR$2 -> 4.5714286 | AX3: =Q3/$AR$2 -> 4 | ... BF3: =Y3/$AR$2 -> 2 | BG3: =J3/$BH$2 -> 21.333333 | BH3: =K3/$BH$2 -> 10.666667 | BI3: =L3/$BH$2 -> 7.1111111 | BJ3: =M3/$BH$2 -> 5.3333333 | BK3: =N3/$BH$2 -> 4.2666667 | BL3: =O3/$BH$2 -> 3.5555556 | BM3: =P3/$BH$2 -> 3.047619 | BN3: =Q3/$BH$2 -> 2.6666667 | ... BV3: =Y3/$BH$2 -> 1.3333333 | BW3: =J3/$BX$2 -> 16 | BX3: =K3/$BX$2 -> 8 | BY3: =L3/$BX$2 -> 5.3333333 | BZ3: =M3/$BX$2 -> 4 | CA3: =N3/$BX$2 -> 3.2 | CB3: =O3/$BX$2 -> 2.6666667 | CC3: =P3/$BX$2 -> 2.2857143 | CD3: =Q3/$BX$2 -> 2 | ... CL3: =Y3/$BX$2 -> 1 | DW3: 2 | DX3: 4 | DY3: 6 | DZ3: 8
D4: 2 | E4: =$B$3/D4 -> 8 | I4: 9 | J4: =$E$3*I4 -> 144 | K4: =$E$4*I4 -> 72 | L4: =$E$5*I4 -> 48 | M4: =$E$6*I4 -> 36 | N4: =$E$7*I4 -> 28.8 | O4: =$E$8*I4 -> 24 | P4: =$E$9*I4 -> 20.571429 | Q4: =$E$10*I4 -> 18 | R4: =$E$11*I4 -> 16 | S4: =$E$12*I4 -> 14.4 | T4: =$E$13*I4 -> 13.090909 | U4: =$E$14*I4 -> 12 | V4: =$E$15*I4 -> 11.076923 | W4: =$E$16*I4 -> 10.285714 | X4: =$E$17*I4 -> 9.6 | Y4: =$E$18*I4 -> 9 | AA4: =J4/$AB$2 -> 72 | AB4: =K4/$AB$2 -> 36 | AC4: =L4/$AB$2 -> 24 | AD4: =M4/$AB$2 -> 18 | AE4: =N4/$AB$2 -> 14.4 | AF4: =O4/$AB$2 -> 12 | AG4: =P4/$AB$2 -> 10.285714 | AH4: =Q4/$AB$2 -> 9 | ... AP4: =Y4/$AB$2 -> 4.5 | AQ4: =J4/$AR$2 -> 36 | AR4: =K4/$AR$2 -> 18 | AS4: =L4/$AR$2 -> 12 | AT4: =M4/$AR$2 -> 9 | AU4: =N4/$AR$2 -> 7.2 | AV4: =O4/$AR$2 -> 6 | AW4: =P4/$AR$2 -> 5.1428571 | AX4: =Q4/$AR$2 -> 4.5 | ... BF4: =Y4/$AR$2 -> 2.25 | BG4: =J4/$BH$2 -> 24 | BH4: =K4/$BH$2 -> 12 | BI4: =L4/$BH$2 -> 8 | BJ4: =M4/$BH$2 -> 6 | BK4: =N4/$BH$2 -> 4.8 | BL4: =O4/$BH$2 -> 4 | BM4: =P4/$BH$2 -> 3.4285714 | BN4: =Q4/$BH$2 -> 3 | ... BV4: =Y4/$BH$2 -> 1.5 | BW4: =J4/$BX$2 -> 18 | BX4: =K4/$BX$2 -> 9 | BY4: =L4/$BX$2 -> 6 | BZ4: =M4/$BX$2 -> 4.5 | CA4: =N4/$BX$2 -> 3.6 | CB4: =O4/$BX$2 -> 3 | CC4: =P4/$BX$2 -> 2.5714286 | CD4: =Q4/$BX$2 -> 2.25 | ... CL4: =Y4/$BX$2 -> 1.125
D5: 3 | E5: =$B$3/D5 -> 5.3333333 | I5: 10 | J5: =$E$3*I5 -> 160 | K5: =$E$4*I5 -> 80 | L5: =$E$5*I5 -> 53.333333 | M5: =$E$6*I5 -> 40 | N5: =$E$7*I5 -> 32 | O5: =$E$8*I5 -> 26.666667 | P5: =$E$9*I5 -> 22.857143 | Q5: =$E$10*I5 -> 20 | R5: =$E$11*I5 -> 17.777778 | S5: =$E$12*I5 -> 16 | T5: =$E$13*I5 -> 14.545455 | U5: =$E$14*I5 -> 13.333333 | V5: =$E$15*I5 -> 12.307692 | W5: =$E$16*I5 -> 11.428571 | X5: =$E$17*I5 -> 10.666667 | Y5: =$E$18*I5 -> 10 | AA5: =J5/$AB$2 -> 80 | AB5: =K5/$AB$2 -> 40 | AC5: =L5/$AB$2 -> 26.666667 | AD5: =M5/$AB$2 -> 20 | AE5: =N5/$AB$2 -> 16 | AF5: =O5/$AB$2 -> 13.333333 | AG5: =P5/$AB$2 -> 11.428571 | AH5: =Q5/$AB$2 -> 10 | ... AP5: =Y5/$AB$2 -> 5 | AQ5: =J5/$AR$2 -> 40 | AR5: =K5/$AR$2 -> 20 | AS5: =L5/$AR$2 -> 13.333333 | AT5: =M5/$AR$2 -> 10 | AU5: =N5/$AR$2 -> 8 | AV5: =O5/$AR$2 -> 6.6666667 | AW5: =P5/$AR$2 -> 5.7142857 | AX5: =Q5/$AR$2 -> 5 | ... BF5: =Y5/$AR$2 -> 2.5 | BG5: =J5/$BH$2 -> 26.666667 | BH5: =K5/$BH$2 -> 13.333333 | BI5: =L5/$BH$2 -> 8.8888889 | BJ5: =M5/$BH$2 -> 6.6666667 | BK5: =N5/$BH$2 -> 5.3333333 | BL5: =O5/$BH$2 -> 4.4444444 | BM5: =P5/$BH$2 -> 3.8095238 | BN5: =Q5/$BH$2 -> 3.3333333 | ... BV5: =Y5/$BH$2 -> 1.6666667 | BW5: =J5/$BX$2 -> 20 | BX5: =K5/$BX$2 -> 10 | BY5: =L5/$BX$2 -> 6.6666667 | BZ5: =M5/$BX$2 -> 5 | CA5: =N5/$BX$2 -> 4 | CB5: =O5/$BX$2 -> 3.3333333 | CC5: =P5/$BX$2 -> 2.8571429 | CD5: =Q5/$BX$2 -> 2.5 | ... CL5: =Y5/$BX$2 -> 1.25
D6: 4 | E6: =$B$3/D6 -> 4 | I6: 11 | J6: =$E$3*I6 -> 176 | K6: =$E$4*I6 -> 88 | L6: =$E$5*I6 -> 58.666667 | M6: =$E$6*I6 -> 44 | N6: =$E$7*I6 -> 35.2 | O6: =$E$8*I6 -> 29.333333 | P6: =$E$9*I6 -> 25.142857 | Q6: =$E$10*I6 -> 22 | R6: =$E$11*I6 -> 19.555556 | S6: =$E$12*I6 -> 17.6 | T6: =$E$13*I6 -> 16 | U6: =$E$14*I6 -> 14.666667 | V6: =$E$15*I6 -> 13.538462 | W6: =$E$16*I6 -> 12.571429 | X6: =$E$17*I6 -> 11.733333 | Y6: =$E$18*I6 -> 11 | AA6: =J6/$AB$2 -> 88 | AB6: =K6/$AB$2 -> 44 | AC6: =L6/$AB$2 -> 29.333333 | AD6: =M6/$AB$2 -> 22 | AE6: =N6/$AB$2 -> 17.6 | AF6: =O6/$AB$2 -> 14.666667 | AG6: =P6/$AB$2 -> 12.571429 | AH6: =Q6/$AB$2 -> 11 | ... AP6: =Y6/$AB$2 -> 5.5 | AQ6: =J6/$AR$2 -> 44 | AR6: =K6/$AR$2 -> 22 | AS6: =L6/$AR$2 -> 14.666667 | AT6: =M6/$AR$2 -> 11 | AU6: =N6/$AR$2 -> 8.8 | AV6: =O6/$AR$2 -> 7.3333333 | AW6: =P6/$AR$2 -> 6.2857143 | AX6: =Q6/$AR$2 -> 5.5 | ... BF6: =Y6/$AR$2 -> 2.75 | BG6: =J6/$BH$2 -> 29.333333 | BH6: =K6/$BH$2 -> 14.666667 | BI6: =L6/$BH$2 -> 9.7777778 | BJ6: =M6/$BH$2 -> 7.3333333 | BK6: =N6/$BH$2 -> 5.8666667 | BL6: =O6/$BH$2 -> 4.8888889 | BM6: =P6/$BH$2 -> 4.1904762 | BN6: =Q6/$BH$2 -> 3.6666667 | ... BV6: =Y6/$BH$2 -> 1.8333333 | BW6: =J6/$BX$2 -> 22 | BX6: =K6/$BX$2 -> 11 | BY6: =L6/$BX$2 -> 7.3333333 | BZ6: =M6/$BX$2 -> 5.5 | CA6: =N6/$BX$2 -> 4.4 | CB6: =O6/$BX$2 -> 3.6666667 | CC6: =P6/$BX$2 -> 3.1428571 | CD6: =Q6/$BX$2 -> 2.75 | ... CL6: =Y6/$BX$2 -> 1.375
D7: 5 | E7: =$B$3/D7 -> 3.2 | I7: 12 | J7: =$E$3*I7 -> 192 | K7: =$E$4*I7 -> 96 | L7: =$E$5*I7 -> 64 | M7: =$E$6*I7 -> 48 | N7: =$E$7*I7 -> 38.4 | O7: =$E$8*I7 -> 32 | P7: =$E$9*I7 -> 27.428571 | Q7: =$E$10*I7 -> 24 | R7: =$E$11*I7 -> 21.333333 | S7: =$E$12*I7 -> 19.2 | T7: =$E$13*I7 -> 17.454545 | U7: =$E$14*I7 -> 16 | V7: =$E$15*I7 -> 14.769231 | W7: =$E$16*I7 -> 13.714286 | X7: =$E$17*I7 -> 12.8 | Y7: =$E$18*I7 -> 12 | AA7: =J7/$AB$2 -> 96 | AB7: =K7/$AB$2 -> 48 | AC7: =L7/$AB$2 -> 32 | AD7: =M7/$AB$2 -> 24 | AE7: =N7/$AB$2 -> 19.2 | AF7: =O7/$AB$2 -> 16 | AG7: =P7/$AB$2 -> 13.714286 | AH7: =Q7/$AB$2 -> 12 | ... AP7: =Y7/$AB$2 -> 6 | AQ7: =J7/$AR$2 -> 48 | AR7: =K7/$AR$2 -> 24 | AS7: =L7/$AR$2 -> 16 | AT7: =M7/$AR$2 -> 12 | AU7: =N7/$AR$2 -> 9.6 | AV7: =O7/$AR$2 -> 8 | AW7: =P7/$AR$2 -> 6.8571429 | AX7: =Q7/$AR$2 -> 6 | ... BF7: =Y7/$AR$2 -> 3 | BG7: =J7/$BH$2 -> 32 | BH7: =K7/$BH$2 -> 16 | BI7: =L7/$BH$2 -> 10.666667 | BJ7: =M7/$BH$2 -> 8 | BK7: =N7/$BH$2 -> 6.4 | BL7: =O7/$BH$2 -> 5.3333333 | BM7: =P7/$BH$2 -> 4.5714286 | BN7: =Q7/$BH$2 -> 4 | ... BV7: =Y7/$BH$2 -> 2 | BW7: =J7/$BX$2 -> 24 | BX7: =K7/$BX$2 -> 12 | BY7: =L7/$BX$2 -> 8 | BZ7: =M7/$BX$2 -> 6 | CA7: =N7/$BX$2 -> 4.8 | CB7: =O7/$BX$2 -> 4 | CC7: =P7/$BX$2 -> 3.4285714 | CD7: =Q7/$BX$2 -> 3 | ... CL7: =Y7/$BX$2 -> 1.5
D8: 6 | E8: =$B$3/D8 -> 2.6666667 | I8: 13 | J8: =$E$3*I8 -> 208 | K8: =$E$4*I8 -> 104 | L8: =$E$5*I8 -> 69.333333 | M8: =$E$6*I8 -> 52 | N8: =$E$7*I8 -> 41.6 | O8: =$E$8*I8 -> 34.666667 | P8: =$E$9*I8 -> 29.714286 | Q8: =$E$10*I8 -> 26 | R8: =$E$11*I8 -> 23.111111 | S8: =$E$12*I8 -> 20.8 | T8: =$E$13*I8 -> 18.909091 | U8: =$E$14*I8 -> 17.333333 | V8: =$E$15*I8 -> 16 | W8: =$E$16*I8 -> 14.857143 | X8: =$E$17*I8 -> 13.866667 | Y8: =$E$18*I8 -> 13 | AA8: =J8/$AB$2 -> 104 | AB8: =K8/$AB$2 -> 52 | AC8: =L8/$AB$2 -> 34.666667 | AD8: =M8/$AB$2 -> 26 | AE8: =N8/$AB$2 -> 20.8 | AF8: =O8/$AB$2 -> 17.333333 | AG8: =P8/$AB$2 -> 14.857143 | AH8: =Q8/$AB$2 -> 13 | ... AP8: =Y8/$AB$2 -> 6.5 | AQ8: =J8/$AR$2 -> 52 | AR8: =K8/$AR$2 -> 26 | AS8: =L8/$AR$2 -> 17.333333 | AT8: =M8/$AR$2 -> 13 | AU8: =N8/$AR$2 -> 10.4 | AV8: =O8/$AR$2 -> 8.6666667 | AW8: =P8/$AR$2 -> 7.4285714 | AX8: =Q8/$AR$2 -> 6.5 | ... BF8: =Y8/$AR$2 -> 3.25 | BG8: =J8/$BH$2 -> 34.666667 | BH8: =K8/$BH$2 -> 17.333333 | BI8: =L8/$BH$2 -> 11.555556 | BJ8: =M8/$BH$2 -> 8.6666667 | BK8: =N8/$BH$2 -> 6.9333333 | BL8: =O8/$BH$2 -> 5.7777778 | BM8: =P8/$BH$2 -> 4.952381 | BN8: =Q8/$BH$2 -> 4.3333333 | ... BV8: =Y8/$BH$2 -> 2.1666667 | BW8: =J8/$BX$2 -> 26 | BX8: =K8/$BX$2 -> 13 | BY8: =L8/$BX$2 -> 8.6666667 | BZ8: =M8/$BX$2 -> 6.5 | CA8: =N8/$BX$2 -> 5.2 | CB8: =O8/$BX$2 -> 4.3333333 | CC8: =P8/$BX$2 -> 3.7142857 | CD8: =Q8/$BX$2 -> 3.25 | ... CL8: =Y8/$BX$2 -> 1.625
D9: 7 | E9: =$B$3/D9 -> 2.2857143 | I9: 14 | J9: =$E$3*I9 -> 224 | K9: =$E$4*I9 -> 112 | L9: =$E$5*I9 -> 74.666667 | M9: =$E$6*I9 -> 56 | N9: =$E$7*I9 -> 44.8 | O9: =$E$8*I9 -> 37.333333 | P9: =$E$9*I9 -> 32 | Q9: =$E$10*I9 -> 28 | R9: =$E$11*I9 -> 24.888889 | S9: =$E$12*I9 -> 22.4 | T9: =$E$13*I9 -> 20.363636 | U9: =$E$14*I9 -> 18.666667 | V9: =$E$15*I9 -> 17.230769 | W9: =$E$16*I9 -> 16 | X9: =$E$17*I9 -> 14.933333 | Y9: =$E$18*I9 -> 14 | AA9: =J9/$AB$2 -> 112 | AB9: =K9/$AB$2 -> 56 | AC9: =L9/$AB$2 -> 37.333333 | AD9: =M9/$AB$2 -> 28 | AE9: =N9/$AB$2 -> 22.4 | AF9: =O9/$AB$2 -> 18.666667 | AG9: =P9/$AB$2 -> 16 | AH9: =Q9/$AB$2 -> 14 | ... AP9: =Y9/$AB$2 -> 7 | AQ9: =J9/$AR$2 -> 56 | AR9: =K9/$AR$2 -> 28 | AS9: =L9/$AR$2 -> 18.666667 | AT9: =M9/$AR$2 -> 14 | AU9: =N9/$AR$2 -> 11.2 | AV9: =O9/$AR$2 -> 9.3333333 | AW9: =P9/$AR$2 -> 8 | AX9: =Q9/$AR$2 -> 7 | ... BF9: =Y9/$AR$2 -> 3.5 | BG9: =J9/$BH$2 -> 37.333333 | BH9: =K9/$BH$2 -> 18.666667 | BI9: =L9/$BH$2 -> 12.444444 | BJ9: =M9/$BH$2 -> 9.3333333 | BK9: =N9/$BH$2 -> 7.4666667 | BL9: =O9/$BH$2 -> 6.2222222 | BM9: =P9/$BH$2 -> 5.3333333 | BN9: =Q9/$BH$2 -> 4.6666667 | ... BV9: =Y9/$BH$2 -> 2.3333333 | BW9: =J9/$BX$2 -> 28 | BX9: =K9/$BX$2 -> 14 | BY9: =L9/$BX$2 -> 9.3333333 | BZ9: =M9/$BX$2 -> 7 | CA9: =N9/$BX$2 -> 5.6 | CB9: =O9/$BX$2 -> 4.6666667 | CC9: =P9/$BX$2 -> 4 | CD9: =Q9/$BX$2 -> 3.5 | ... CL9: =Y9/$BX$2 -> 1.75
D10: 8 | E10: =$B$3/D10 -> 2 | I10: 15 | J10: =$E$3*I10 -> 240 | K10: =$E$4*I10 -> 120 | L10: =$E$5*I10 -> 80 | M10: =$E$6*I10 -> 60 | N10: =$E$7*I10 -> 48 | O10: =$E$8*I10 -> 40 | P10: =$E$9*I10 -> 34.285714 | Q10: =$E$10*I10 -> 30 | R10: =$E$11*I10 -> 26.666667 | S10: =$E$12*I10 -> 24 | T10: =$E$13*I10 -> 21.818182 | U10: =$E$14*I10 -> 20 | V10: =$E$15*I10 -> 18.461538 | W10: =$E$16*I10 -> 17.142857 | X10: =$E$17*I10 -> 16 | Y10: =$E$18*I10 -> 15 | AA10: =J10/$AB$2 -> 120 | AB10: =K10/$AB$2 -> 60 | AC10: =L10/$AB$2 -> 40 | AD10: =M10/$AB$2 -> 30 | AE10: =N10/$AB$2 -> 24 | AF10: =O10/$AB$2 -> 20 | AG10: =P10/$AB$2 -> 17.142857 | AH10: =Q10/$AB$2 -> 15 | ... AP10: =Y10/$AB$2 -> 7.5 | AQ10: =J10/$AR$2 -> 60 | AR10: =K10/$AR$2 -> 30 | AS10: =L10/$AR$2 -> 20 | AT10: =M10/$AR$2 -> 15 | AU10: =N10/$AR$2 -> 12 | AV10: =O10/$AR$2 -> 10 | AW10: =P10/$AR$2 -> 8.5714286 | AX10: =Q10/$AR$2 -> 7.5 | ... BF10: =Y10/$AR$2 -> 3.75 | BG10: =J10/$BH$2 -> 40 | BH10: =K10/$BH$2 -> 20 | BI10: =L10/$BH$2 -> 13.333333 | BJ10: =M10/$BH$2 -> 10 | BK10: =N10/$BH$2 -> 8 | BL10: =O10/$BH$2 -> 6.6666667 | BM10: =P10/$BH$2 -> 5.7142857 | BN10: =Q10/$BH$2 -> 5 | ... BV10: =Y10/$BH$2 -> 2.5 | BW10: =J10/$BX$2 -> 30 | BX10: =K10/$BX$2 -> 15 | BY10: =L10/$BX$2 -> 10 | BZ10: =M10/$BX$2 -> 7.5 | CA10: =N10/$BX$2 -> 6 | CB10: =O10/$BX$2 -> 5 | CC10: =P10/$BX$2 -> 4.2857143 | CD10: =Q10/$BX$2 -> 3.75 | ... CL10: =Y10/$BX$2 -> 1.875
D11: 9 | E11: =$B$3/D11 -> 1.7777778 | I11: 16 | J11: =$E$3*I11 -> 256 | K11: =$E$4*I11 -> 128 | L11: =$E$5*I11 -> 85.333333 | M11: =$E$6*I11 -> 64 | N11: =$E$7*I11 -> 51.2 | O11: =$E$8*I11 -> 42.666667 | P11: =$E$9*I11 -> 36.571429 | Q11: =$E$10*I11 -> 32 | R11: =$E$11*I11 -> 28.444444 | S11: =$E$12*I11 -> 25.6 | T11: =$E$13*I11 -> 23.272727 | U11: =$E$14*I11 -> 21.333333 | V11: =$E$15*I11 -> 19.692308 | W11: =$E$16*I11 -> 18.285714 | X11: =$E$17*I11 -> 17.066667 | Y11: =$E$18*I11 -> 16 | AA11: =J11/$AB$2 -> 128 | AB11: =K11/$AB$2 -> 64 | AC11: =L11/$AB$2 -> 42.666667 | AD11: =M11/$AB$2 -> 32 | AE11: =N11/$AB$2 -> 25.6 | AF11: =O11/$AB$2 -> 21.333333 | AG11: =P11/$AB$2 -> 18.285714 | AH11: =Q11/$AB$2 -> 16 | ... AP11: =Y11/$AB$2 -> 8 | AQ11: =J11/$AR$2 -> 64 | AR11: =K11/$AR$2 -> 32 | AS11: =L11/$AR$2 -> 21.333333 | AT11: =M11/$AR$2 -> 16 | AU11: =N11/$AR$2 -> 12.8 | AV11: =O11/$AR$2 -> 10.666667 | AW11: =P11/$AR$2 -> 9.1428571 | AX11: =Q11/$AR$2 -> 8 | ... BF11: =Y11/$AR$2 -> 4 | BG11: =J11/$BH$2 -> 42.666667 | BH11: =K11/$BH$2 -> 21.333333 | BI11: =L11/$BH$2 -> 14.222222 | BJ11: =M11/$BH$2 -> 10.666667 | BK11: =N11/$BH$2 -> 8.5333333 | BL11: =O11/$BH$2 -> 7.1111111 | BM11: =P11/$BH$2 -> 6.0952381 | BN11: =Q11/$BH$2 -> 5.3333333 | ... BV11: =Y11/$BH$2 -> 2.6666667 | BW11: =J11/$BX$2 -> 32 | BX11: =K11/$BX$2 -> 16 | BY11: =L11/$BX$2 -> 10.666667 | BZ11: =M11/$BX$2 -> 8 | CA11: =N11/$BX$2 -> 6.4 | CB11: =O11/$BX$2 -> 5.3333333 | CC11: =P11/$BX$2 -> 4.5714286 | CD11: =Q11/$BX$2 -> 4 | ... CL11: =Y11/$BX$2 -> 2
D12: 10 | E12: =$B$3/D12 -> 1.6 | I12: 17 | J12: =$E$3*I12 -> 272 | K12: =$E$4*I12 -> 136 | L12: =$E$5*I12 -> 90.666667 | M12: =$E$6*I12 -> 68 | N12: =$E$7*I12 -> 54.4 | O12: =$E$8*I12 -> 45.333333 | P12: =$E$9*I12 -> 38.857143 | Q12: =$E$10*I12 -> 34 | R12: =$E$11*I12 -> 30.222222 | S12: =$E$12*I12 -> 27.2 | T12: =$E$13*I12 -> 24.727273 | U12: =$E$14*I12 -> 22.666667 | V12: =$E$15*I12 -> 20.923077 | W12: =$E$16*I12 -> 19.428571 | X12: =$E$17*I12 -> 18.133333 | Y12: =$E$18*I12 -> 17 | AA12: =J12/$AB$2 -> 136 | AB12: =K12/$AB$2 -> 68 | AC12: =L12/$AB$2 -> 45.333333 | AD12: =M12/$AB$2 -> 34 | AE12: =N12/$AB$2 -> 27.2 | AF12: =O12/$AB$2 -> 22.666667 | AG12: =P12/$AB$2 -> 19.428571 | AH12: =Q12/$AB$2 -> 17 | ... AP12: =Y12/$AB$2 -> 8.5 | AQ12: =J12/$AR$2 -> 68 | AR12: =K12/$AR$2 -> 34 | AS12: =L12/$AR$2 -> 22.666667 | AT12: =M12/$AR$2 -> 17 | AU12: =N12/$AR$2 -> 13.6 | AV12: =O12/$AR$2 -> 11.333333 | AW12: =P12/$AR$2 -> 9.7142857 | AX12: =Q12/$AR$2 -> 8.5 | ... BF12: =Y12/$AR$2 -> 4.25 | BG12: =J12/$BH$2 -> 45.333333 | BH12: =K12/$BH$2 -> 22.666667 | BI12: =L12/$BH$2 -> 15.111111 | BJ12: =M12/$BH$2 -> 11.333333 | BK12: =N12/$BH$2 -> 9.0666667 | BL12: =O12/$BH$2 -> 7.5555556 | BM12: =P12/$BH$2 -> 6.4761905 | BN12: =Q12/$BH$2 -> 5.6666667 | ... BV12: =Y12/$BH$2 -> 2.8333333 | BW12: =J12/$BX$2 -> 34 | BX12: =K12/$BX$2 -> 17 | BY12: =L12/$BX$2 -> 11.333333 | BZ12: =M12/$BX$2 -> 8.5 | CA12: =N12/$BX$2 -> 6.8 | CB12: =O12/$BX$2 -> 5.6666667 | CC12: =P12/$BX$2 -> 4.8571429 | CD12: =Q12/$BX$2 -> 4.25 | ... CL12: =Y12/$BX$2 -> 2.125
D13: 11 | E13: =$B$3/D13 -> 1.4545455 | I13: 18 | J13: =$E$3*I13 -> 288 | K13: =$E$4*I13 -> 144 | L13: =$E$5*I13 -> 96 | M13: =$E$6*I13 -> 72 | N13: =$E$7*I13 -> 57.6 | O13: =$E$8*I13 -> 48 | P13: =$E$9*I13 -> 41.142857 | Q13: =$E$10*I13 -> 36 | R13: =$E$11*I13 -> 32 | S13: =$E$12*I13 -> 28.8 | T13: =$E$13*I13 -> 26.181818 | U13: =$E$14*I13 -> 24 | V13: =$E$15*I13 -> 22.153846 | W13: =$E$16*I13 -> 20.571429 | X13: =$E$17*I13 -> 19.2 | Y13: =$E$18*I13 -> 18 | AA13: =J13/$AB$2 -> 144 | AB13: =K13/$AB$2 -> 72 | AC13: =L13/$AB$2 -> 48 | AD13: =M13/$AB$2 -> 36 | AE13: =N13/$AB$2 -> 28.8 | AF13: =O13/$AB$2 -> 24 | AG13: =P13/$AB$2 -> 20.571429 | AH13: =Q13/$AB$2 -> 18 | ... AP13: =Y13/$AB$2 -> 9 | AQ13: =J13/$AR$2 -> 72 | AR13: =K13/$AR$2 -> 36 | AS13: =L13/$AR$2 -> 24 | AT13: =M13/$AR$2 -> 18 | AU13: =N13/$AR$2 -> 14.4 | AV13: =O13/$AR$2 -> 12 | AW13: =P13/$AR$2 -> 10.285714 | AX13: =Q13/$AR$2 -> 9 | ... BF13: =Y13/$AR$2 -> 4.5 | BG13: =J13/$BH$2 -> 48 | BH13: =K13/$BH$2 -> 24 | BI13: =L13/$BH$2 -> 16 | BJ13: =M13/$BH$2 -> 12 | BK13: =N13/$BH$2 -> 9.6 | BL13: =O13/$BH$2 -> 8 | BM13: =P13/$BH$2 -> 6.8571429 | BN13: =Q13/$BH$2 -> 6 | ... BV13: =Y13/$BH$2 -> 3 | BW13: =J13/$BX$2 -> 36 | BX13: =K13/$BX$2 -> 18 | BY13: =L13/$BX$2 -> 12 | BZ13: =M13/$BX$2 -> 9 | CA13: =N13/$BX$2 -> 7.2 | CB13: =O13/$BX$2 -> 6 | CC13: =P13/$BX$2 -> 5.1428571 | CD13: =Q13/$BX$2 -> 4.5 | ... CL13: =Y13/$BX$2 -> 2.25
D14: 12 | E14: =$B$3/D14 -> 1.3333333 | I14: 19 | J14: =$E$3*I14 -> 304 | K14: =$E$4*I14 -> 152 | L14: =$E$5*I14 -> 101.33333 | M14: =$E$6*I14 -> 76 | N14: =$E$7*I14 -> 60.8 | O14: =$E$8*I14 -> 50.666667 | P14: =$E$9*I14 -> 43.428571 | Q14: =$E$10*I14 -> 38 | R14: =$E$11*I14 -> 33.777778 | S14: =$E$12*I14 -> 30.4 | T14: =$E$13*I14 -> 27.636364 | U14: =$E$14*I14 -> 25.333333 | V14: =$E$15*I14 -> 23.384615 | W14: =$E$16*I14 -> 21.714286 | X14: =$E$17*I14 -> 20.266667 | Y14: =$E$18*I14 -> 19 | AA14: =J14/$AB$2 -> 152 | AB14: =K14/$AB$2 -> 76 | AC14: =L14/$AB$2 -> 50.666667 | AD14: =M14/$AB$2 -> 38 | AE14: =N14/$AB$2 -> 30.4 | AF14: =O14/$AB$2 -> 25.333333 | AG14: =P14/$AB$2 -> 21.714286 | AH14: =Q14/$AB$2 -> 19 | ... AP14: =Y14/$AB$2 -> 9.5 | AQ14: =J14/$AR$2 -> 76 | AR14: =K14/$AR$2 -> 38 | AS14: =L14/$AR$2 -> 25.333333 | AT14: =M14/$AR$2 -> 19 | AU14: =N14/$AR$2 -> 15.2 | AV14: =O14/$AR$2 -> 12.666667 | AW14: =P14/$AR$2 -> 10.857143 | AX14: =Q14/$AR$2 -> 9.5 | ... BF14: =Y14/$AR$2 -> 4.75 | BG14: =J14/$BH$2 -> 50.666667 | BH14: =K14/$BH$2 -> 25.333333 | BI14: =L14/$BH$2 -> 16.888889 | BJ14: =M14/$BH$2 -> 12.666667 | BK14: =N14/$BH$2 -> 10.133333 | BL14: =O14/$BH$2 -> 8.4444444 | BM14: =P14/$BH$2 -> 7.2380952 | BN14: =Q14/$BH$2 -> 6.3333333 | ... BV14: =Y14/$BH$2 -> 3.1666667 | BW14: =J14/$BX$2 -> 38 | BX14: =K14/$BX$2 -> 19 | BY14: =L14/$BX$2 -> 12.666667 | BZ14: =M14/$BX$2 -> 9.5 | CA14: =N14/$BX$2 -> 7.6 | CB14: =O14/$BX$2 -> 6.3333333 | CC14: =P14/$BX$2 -> 5.4285714 | CD14: =Q14/$BX$2 -> 4.75 | ... CL14: =Y14/$BX$2 -> 2.375
D15: 13 | E15: =$B$3/D15 -> 1.2307692 | I15: 20 | J15: =$E$3*I15 -> 320 | K15: =$E$4*I15 -> 160 | L15: =$E$5*I15 -> 106.66667 | M15: =$E$6*I15 -> 80 | N15: =$E$7*I15 -> 64 | O15: =$E$8*I15 -> 53.333333 | P15: =$E$9*I15 -> 45.714286 | Q15: =$E$10*I15 -> 40 | R15: =$E$11*I15 -> 35.555556 | S15: =$E$12*I15 -> 32 | T15: =$E$13*I15 -> 29.090909 | U15: =$E$14*I15 -> 26.666667 | V15: =$E$15*I15 -> 24.615385 | W15: =$E$16*I15 -> 22.857143 | X15: =$E$17*I15 -> 21.333333 | Y15: =$E$18*I15 -> 20 | AA15: =J15/$AB$2 -> 160 | AB15: =K15/$AB$2 -> 80 | AC15: =L15/$AB$2 -> 53.333333 | AD15: =M15/$AB$2 -> 40 | AE15: =N15/$AB$2 -> 32 | AF15: =O15/$AB$2 -> 26.666667 | AG15: =P15/$AB$2 -> 22.857143 | AH15: =Q15/$AB$2 -> 20 | ... AP15: =Y15/$AB$2 -> 10 | AQ15: =J15/$AR$2 -> 80 | AR15: =K15/$AR$2 -> 40 | AS15: =L15/$AR$2 -> 26.666667 | AT15: =M15/$AR$2 -> 20 | AU15: =N15/$AR$2 -> 16 | AV15: =O15/$AR$2 -> 13.333333 | AW15: =P15/$AR$2 -> 11.428571 | AX15: =Q15/$AR$2 -> 10 | ... BF15: =Y15/$AR$2 -> 5 | BG15: =J15/$BH$2 -> 53.333333 | BH15: =K15/$BH$2 -> 26.666667 | BI15: =L15/$BH$2 -> 17.777778 | BJ15: =M15/$BH$2 -> 13.333333 | BK15: =N15/$BH$2 -> 10.666667 | BL15: =O15/$BH$2 -> 8.8888889 | BM15: =P15/$BH$2 -> 7.6190476 | BN15: =Q15/$BH$2 -> 6.6666667 | ... BV15: =Y15/$BH$2 -> 3.3333333 | BW15: =J15/$BX$2 -> 40 | BX15: =K15/$BX$2 -> 20 | BY15: =L15/$BX$2 -> 13.333333 | BZ15: =M15/$BX$2 -> 10 | CA15: =N15/$BX$2 -> 8 | CB15: =O15/$BX$2 -> 6.6666667 | CC15: =P15/$BX$2 -> 5.7142857 | CD15: =Q15/$BX$2 -> 5 | ... CL15: =Y15/$BX$2 -> 2.5
D16: 14 | E16: =$B$3/D16 -> 1.1428571 | I16: 21 | J16: =$E$3*I16 -> 336 | K16: =$E$4*I16 -> 168 | L16: =$E$5*I16 -> 112 | M16: =$E$6*I16 -> 84 | N16: =$E$7*I16 -> 67.2 | O16: =$E$8*I16 -> 56 | P16: =$E$9*I16 -> 48 | Q16: =$E$10*I16 -> 42 | R16: =$E$11*I16 -> 37.333333 | S16: =$E$12*I16 -> 33.6 | T16: =$E$13*I16 -> 30.545455 | U16: =$E$14*I16 -> 28 | V16: =$E$15*I16 -> 25.846154 | W16: =$E$16*I16 -> 24 | X16: =$E$17*I16 -> 22.4 | Y16: =$E$18*I16 -> 21 | AA16: =J16/$AB$2 -> 168 | AB16: =K16/$AB$2 -> 84 | AC16: =L16/$AB$2 -> 56 | AD16: =M16/$AB$2 -> 42 | AE16: =N16/$AB$2 -> 33.6 | AF16: =O16/$AB$2 -> 28 | AG16: =P16/$AB$2 -> 24 | AH16: =Q16/$AB$2 -> 21 | ... AP16: =Y16/$AB$2 -> 10.5 | AQ16: =J16/$AR$2 -> 84 | AR16: =K16/$AR$2 -> 42 | AS16: =L16/$AR$2 -> 28 | AT16: =M16/$AR$2 -> 21 | AU16: =N16/$AR$2 -> 16.8 | AV16: =O16/$AR$2 -> 14 | AW16: =P16/$AR$2 -> 12 | AX16: =Q16/$AR$2 -> 10.5 | ... BF16: =Y16/$AR$2 -> 5.25 | BG16: =J16/$BH$2 -> 56 | BH16: =K16/$BH$2 -> 28 | BI16: =L16/$BH$2 -> 18.666667 | BJ16: =M16/$BH$2 -> 14 | BK16: =N16/$BH$2 -> 11.2 | BL16: =O16/$BH$2 -> 9.3333333 | BM16: =P16/$BH$2 -> 8 | BN16: =Q16/$BH$2 -> 7 | ... BV16: =Y16/$BH$2 -> 3.5 | BW16: =J16/$BX$2 -> 42 | BX16: =K16/$BX$2 -> 21 | BY16: =L16/$BX$2 -> 14 | BZ16: =M16/$BX$2 -> 10.5 | CA16: =N16/$BX$2 -> 8.4 | CB16: =O16/$BX$2 -> 7 | CC16: =P16/$BX$2 -> 6 | CD16: =Q16/$BX$2 -> 5.25 | ... CL16: =Y16/$BX$2 -> 2.625
D17: 15 | E17: =$B$3/D17 -> 1.0666667 | I17: 22 | J17: =$E$3*I17 -> 352 | K17: =$E$4*I17 -> 176 | L17: =$E$5*I17 -> 117.33333 | M17: =$E$6*I17 -> 88 | N17: =$E$7*I17 -> 70.4 | O17: =$E$8*I17 -> 58.666667 | P17: =$E$9*I17 -> 50.285714 | Q17: =$E$10*I17 -> 44 | R17: =$E$11*I17 -> 39.111111 | S17: =$E$12*I17 -> 35.2 | T17: =$E$13*I17 -> 32 | U17: =$E$14*I17 -> 29.333333 | V17: =$E$15*I17 -> 27.076923 | W17: =$E$16*I17 -> 25.142857 | X17: =$E$17*I17 -> 23.466667 | Y17: =$E$18*I17 -> 22 | AB17: =K17/$AB$2 -> 88 | AC17: =L17/$AB$2 -> 58.666667 | AD17: =M17/$AB$2 -> 44 | AE17: =N17/$AB$2 -> 35.2 | AF17: =O17/$AB$2 -> 29.333333 | AG17: =P17/$AB$2 -> 25.142857 | AH17: =Q17/$AB$2 -> 22 | AI17: =R17/$AB$2 -> 19.555556 | ... AP17: =Y17/$AB$2 -> 11 | AQ17: =J17/$AR$2 -> 88 | AR17: =K17/$AR$2 -> 44 | AS17: =L17/$AR$2 -> 29.333333 | AT17: =M17/$AR$2 -> 22 | AU17: =N17/$AR$2 -> 17.6 | AV17: =O17/$AR$2 -> 14.666667 | AW17: =P17/$AR$2 -> 12.571429 | AX17: =Q17/$AR$2 -> 11 | ... BF17: =Y17/$AR$2 -> 5.5 | BG17: =J17/$BH$2 -> 58.666667 | BH17: =K17/$BH$2 -> 29.333333 | BI17: =L17/$BH$2 -> 19.555556 | BJ17: =M17/$BH$2 -> 14.666667 | BK17: =N17/$BH$2 -> 11.733333 | BL17: =O17/$BH$2 -> 9.7777778 | BM17: =P17/$BH$2 -> 8.3809524 | BN17: =Q17/$BH$2 -> 7.3333333 | ... BV17: =Y17/$BH$2 -> 3.6666667 | BW17: =J17/$BX$2 -> 44 | BX17: =K17/$BX$2 -> 22 | BY17: =L17/$BX$2 -> 14.666667 | BZ17: =M17/$BX$2 -> 11 | CA17: =N17/$BX$2 -> 8.8 | CB17: =O17/$BX$2 -> 7.3333333 | CC17: =P17/$BX$2 -> 6.2857143 | CD17: =Q17/$BX$2 -> 5.5 | ... CL17: =Y17/$BX$2 -> 2.75
D18: 16 | E18: =$B$3/D18 -> 1 | I18: 23 | J18: =$E$3*I18 -> 368 | K18: =$E$4*I18 -> 184 | L18: =$E$5*I18 -> 122.66667 | M18: =$E$6*I18 -> 92 | N18: =$E$7*I18 -> 73.6 | O18: =$E$8*I18 -> 61.333333 | P18: =$E$9*I18 -> 52.571429 | Q18: =$E$10*I18 -> 46 | R18: =$E$11*I18 -> 40.888889 | S18: =$E$12*I18 -> 36.8 | T18: =$E$13*I18 -> 33.454545 | U18: =$E$14*I18 -> 30.666667 | V18: =$E$15*I18 -> 28.307692 | W18: =$E$16*I18 -> 26.285714 | X18: =$E$17*I18 -> 24.533333 | Y18: =$E$18*I18 -> 23 | AB18: =K18/$AB$2 -> 92 | AC18: =L18/$AB$2 -> 61.333333 | AD18: =M18/$AB$2 -> 46 | AE18: =N18/$AB$2 -> 36.8 | AF18: =O18/$AB$2 -> 30.666667 | AG18: =P18/$AB$2 -> 26.285714 | AH18: =Q18/$AB$2 -> 23 | AI18: =R18/$AB$2 -> 20.444444 | ... AP18: =Y18/$AB$2 -> 11.5 | AQ18: =J18/$AR$2 -> 92 | AR18: =K18/$AR$2 -> 46 | AS18: =L18/$AR$2 -> 30.666667 | AT18: =M18/$AR$2 -> 23 | AU18: =N18/$AR$2 -> 18.4 | AV18: =O18/$AR$2 -> 15.333333 | AW18: =P18/$AR$2 -> 13.142857 | AX18: =Q18/$AR$2 -> 11.5 | ... BF18: =Y18/$AR$2 -> 5.75 | BG18: =J18/$BH$2 -> 61.333333 | BH18: =K18/$BH$2 -> 30.666667 | BI18: =L18/$BH$2 -> 20.444444 | BJ18: =M18/$BH$2 -> 15.333333 | BK18: =N18/$BH$2 -> 12.266667 | BL18: =O18/$BH$2 -> 10.222222 | BM18: =P18/$BH$2 -> 8.7619048 | BN18: =Q18/$BH$2 -> 7.6666667 | ... BV18: =Y18/$BH$2 -> 3.8333333 | BW18: =J18/$BX$2 -> 46 | BX18: =K18/$BX$2 -> 23 | BY18: =L18/$BX$2 -> 15.333333 | BZ18: =M18/$BX$2 -> 11.5 | CA18: =N18/$BX$2 -> 9.2 | CB18: =O18/$BX$2 -> 7.6666667 | CC18: =P18/$BX$2 -> 6.5714286 | CD18: =Q18/$BX$2 -> 5.75 | ... CL18: =Y18/$BX$2 -> 2.875
I19: 24 | J19: =$E$3*I19 -> 384 | K19: =$E$4*I19 -> 192 | L19: =$E$5*I19 -> 128 | M19: =$E$6*I19 -> 96 | N19: =$E$7*I19 -> 76.8 | O19: =$E$8*I19 -> 64 | P19: =$E$9*I19 -> 54.857143 | Q19: =$E$10*I19 -> 48 | R19: =$E$11*I19 -> 42.666667 | S19: =$E$12*I19 -> 38.4 | T19: =$E$13*I19 -> 34.909091 | U19: =$E$14*I19 -> 32 | V19: =$E$15*I19 -> 29.538462 | W19: =$E$16*I19 -> 27.428571 | X19: =$E$17*I19 -> 25.6 | Y19: =$E$18*I19 -> 24 | AB19: =K19/$AB$2 -> 96 | AC19: =L19/$AB$2 -> 64 | AD19: =M19/$AB$2 -> 48 | AE19: =N19/$AB$2 -> 38.4 | AF19: =O19/$AB$2 -> 32 | AG19: =P19/$AB$2 -> 27.428571 | AH19: =Q19/$AB$2 -> 24 | AI19: =R19/$AB$2 -> 21.333333 | ... AP19: =Y19/$AB$2 -> 12 | AQ19: =J19/$AR$2 -> 96 | AR19: =K19/$AR$2 -> 48 | AS19: =L19/$AR$2 -> 32 | AT19: =M19/$AR$2 -> 24 | AU19: =N19/$AR$2 -> 19.2 | AV19: =O19/$AR$2 -> 16 | AW19: =P19/$AR$2 -> 13.714286 | AX19: =Q19/$AR$2 -> 12 | ... BF19: =Y19/$AR$2 -> 6 | BG19: =J19/$BH$2 -> 64 | BH19: =K19/$BH$2 -> 32 | BI19: =L19/$BH$2 -> 21.333333 | BJ19: =M19/$BH$2 -> 16 | BK19: =N19/$BH$2 -> 12.8 | BL19: =O19/$BH$2 -> 10.666667 | BM19: =P19/$BH$2 -> 9.1428571 | BN19: =Q19/$BH$2 -> 8 | ... BV19: =Y19/$BH$2 -> 4 | BW19: =J19/$BX$2 -> 48 | BX19: =K19/$BX$2 -> 24 | BY19: =L19/$BX$2 -> 16 | BZ19: =M19/$BX$2 -> 12 | CA19: =N19/$BX$2 -> 9.6 | CB19: =O19/$BX$2 -> 8 | CC19: =P19/$BX$2 -> 6.8571429 | CD19: =Q19/$BX$2 -> 6 | ... CL19: =Y19/$BX$2 -> 3
I20: 25 | J20: =$E$3*I20 -> 400 | K20: =$E$4*I20 -> 200 | L20: =$E$5*I20 -> 133.33333 | M20: =$E$6*I20 -> 100 | N20: =$E$7*I20 -> 80 | O20: =$E$8*I20 -> 66.666667 | P20: =$E$9*I20 -> 57.142857 | Q20: =$E$10*I20 -> 50 | R20: =$E$11*I20 -> 44.444444 | S20: =$E$12*I20 -> 40 | T20: =$E$13*I20 -> 36.363636 | U20: =$E$14*I20 -> 33.333333 | V20: =$E$15*I20 -> 30.769231 | W20: =$E$16*I20 -> 28.571429 | X20: =$E$17*I20 -> 26.666667 | Y20: =$E$18*I20 -> 25 | AB20: =K20/$AB$2 -> 100 | AC20: =L20/$AB$2 -> 66.666667 | AD20: =M20/$AB$2 -> 50 | AE20: =N20/$AB$2 -> 40 | AF20: =O20/$AB$2 -> 33.333333 | AG20: =P20/$AB$2 -> 28.571429 | AH20: =Q20/$AB$2 -> 25 | AI20: =R20/$AB$2 -> 22.222222 | ... AP20: =Y20/$AB$2 -> 12.5 | AQ20: =J20/$AR$2 -> 100 | AR20: =K20/$AR$2 -> 50 | AS20: =L20/$AR$2 -> 33.333333 | AT20: =M20/$AR$2 -> 25 | AU20: =N20/$AR$2 -> 20 | AV20: =O20/$AR$2 -> 16.666667 | AW20: =P20/$AR$2 -> 14.285714 | AX20: =Q20/$AR$2 -> 12.5 | ... BF20: =Y20/$AR$2 -> 6.25 | BG20: =J20/$BH$2 -> 66.666667 | BH20: =K20/$BH$2 -> 33.333333 | BI20: =L20/$BH$2 -> 22.222222 | BJ20: =M20/$BH$2 -> 16.666667 | BK20: =N20/$BH$2 -> 13.333333 | BL20: =O20/$BH$2 -> 11.111111 | BM20: =P20/$BH$2 -> 9.5238095 | BN20: =Q20/$BH$2 -> 8.3333333 | ... BV20: =Y20/$BH$2 -> 4.1666667 | BW20: =J20/$BX$2 -> 50 | BX20: =K20/$BX$2 -> 25 | BY20: =L20/$BX$2 -> 16.666667 | BZ20: =M20/$BX$2 -> 12.5 | CA20: =N20/$BX$2 -> 10 | CB20: =O20/$BX$2 -> 8.3333333 | CC20: =P20/$BX$2 -> 7.1428571 | CD20: =Q20/$BX$2 -> 6.25 | ... CL20: =Y20/$BX$2 -> 3.125
I21: 26 | J21: =$E$3*I21 -> 416 | K21: =$E$4*I21 -> 208 | L21: =$E$5*I21 -> 138.66667 | M21: =$E$6*I21 -> 104 | N21: =$E$7*I21 -> 83.2 | O21: =$E$8*I21 -> 69.333333 | P21: =$E$9*I21 -> 59.428571 | Q21: =$E$10*I21 -> 52 | R21: =$E$11*I21 -> 46.222222 | S21: =$E$12*I21 -> 41.6 | T21: =$E$13*I21 -> 37.818182 | U21: =$E$14*I21 -> 34.666667 | V21: =$E$15*I21 -> 32 | W21: =$E$16*I21 -> 29.714286 | X21: =$E$17*I21 -> 27.733333 | Y21: =$E$18*I21 -> 26 | AB21: =K21/$AB$2 -> 104 | AC21: =L21/$AB$2 -> 69.333333 | AD21: =M21/$AB$2 -> 52 | AE21: =N21/$AB$2 -> 41.6 | AF21: =O21/$AB$2 -> 34.666667 | AG21: =P21/$AB$2 -> 29.714286 | AH21: =Q21/$AB$2 -> 26 | AI21: =R21/$AB$2 -> 23.111111 | ... AP21: =Y21/$AB$2 -> 13 | AQ21: =J21/$AR$2 -> 104 | AR21: =K21/$AR$2 -> 52 | AS21: =L21/$AR$2 -> 34.666667 | AT21: =M21/$AR$2 -> 26 | AU21: =N21/$AR$2 -> 20.8 | AV21: =O21/$AR$2 -> 17.333333 | AW21: =P21/$AR$2 -> 14.857143 | AX21: =Q21/$AR$2 -> 13 | ... BF21: =Y21/$AR$2 -> 6.5 | BG21: =J21/$BH$2 -> 69.333333 | BH21: =K21/$BH$2 -> 34.666667 | BI21: =L21/$BH$2 -> 23.111111 | BJ21: =M21/$BH$2 -> 17.333333 | BK21: =N21/$BH$2 -> 13.866667 | BL21: =O21/$BH$2 -> 11.555556 | BM21: =P21/$BH$2 -> 9.9047619 | BN21: =Q21/$BH$2 -> 8.6666667 | ... BV21: =Y21/$BH$2 -> 4.3333333 | BW21: =J21/$BX$2 -> 52 | BX21: =K21/$BX$2 -> 26 | BY21: =L21/$BX$2 -> 17.333333 | BZ21: =M21/$BX$2 -> 13 | CA21: =N21/$BX$2 -> 10.4 | CB21: =O21/$BX$2 -> 8.6666667 | CC21: =P21/$BX$2 -> 7.4285714 | CD21: =Q21/$BX$2 -> 6.5 | ... CL21: =Y21/$BX$2 -> 3.25
I22: 27 | J22: =$E$3*I22 -> 432 | K22: =$E$4*I22 -> 216 | L22: =$E$5*I22 -> 144 | M22: =$E$6*I22 -> 108 | N22: =$E$7*I22 -> 86.4 | O22: =$E$8*I22 -> 72 | P22: =$E$9*I22 -> 61.714286 | Q22: =$E$10*I22 -> 54 | R22: =$E$11*I22 -> 48 | S22: =$E$12*I22 -> 43.2 | T22: =$E$13*I22 -> 39.272727 | U22: =$E$14*I22 -> 36 | V22: =$E$15*I22 -> 33.230769 | W22: =$E$16*I22 -> 30.857143 | X22: =$E$17*I22 -> 28.8 | Y22: =$E$18*I22 -> 27 | AB22: =K22/$AB$2 -> 108 | AC22: =L22/$AB$2 -> 72 | AD22: =M22/$AB$2 -> 54 | AE22: =N22/$AB$2 -> 43.2 | AF22: =O22/$AB$2 -> 36 | AG22: =P22/$AB$2 -> 30.857143 | AH22: =Q22/$AB$2 -> 27 | AI22: =R22/$AB$2 -> 24 | ... AP22: =Y22/$AB$2 -> 13.5 | AQ22: =J22/$AR$2 -> 108 | AR22: =K22/$AR$2 -> 54 | AS22: =L22/$AR$2 -> 36 | AT22: =M22/$AR$2 -> 27 | AU22: =N22/$AR$2 -> 21.6 | AV22: =O22/$AR$2 -> 18 | AW22: =P22/$AR$2 -> 15.428571 | AX22: =Q22/$AR$2 -> 13.5 | ... BF22: =Y22/$AR$2 -> 6.75 | BG22: =J22/$BH$2 -> 72 | BH22: =K22/$BH$2 -> 36 | BI22: =L22/$BH$2 -> 24 | BJ22: =M22/$BH$2 -> 18 | BK22: =N22/$BH$2 -> 14.4 | BL22: =O22/$BH$2 -> 12 | BM22: =P22/$BH$2 -> 10.285714 | BN22: =Q22/$BH$2 -> 9 | ... BV22: =Y22/$BH$2 -> 4.5 | BW22: =J22/$BX$2 -> 54 | BX22: =K22/$BX$2 -> 27 | BY22: =L22/$BX$2 -> 18 | BZ22: =M22/$BX$2 -> 13.5 | CA22: =N22/$BX$2 -> 10.8 | CB22: =O22/$BX$2 -> 9 | CC22: =P22/$BX$2 -> 7.7142857 | CD22: =Q22/$BX$2 -> 6.75 | ... CL22: =Y22/$BX$2 -> 3.375
I23: 28 | J23: =$E$3*I23 -> 448 | K23: =$E$4*I23 -> 224 | L23: =$E$5*I23 -> 149.33333 | M23: =$E$6*I23 -> 112 | N23: =$E$7*I23 -> 89.6 | O23: =$E$8*I23 -> 74.666667 | P23: =$E$9*I23 -> 64 | Q23: =$E$10*I23 -> 56 | R23: =$E$11*I23 -> 49.777778 | S23: =$E$12*I23 -> 44.8 | T23: =$E$13*I23 -> 40.727273 | U23: =$E$14*I23 -> 37.333333 | V23: =$E$15*I23 -> 34.461538 | W23: =$E$16*I23 -> 32 | X23: =$E$17*I23 -> 29.866667 | Y23: =$E$18*I23 -> 28 | AB23: =K23/$AB$2 -> 112 | AC23: =L23/$AB$2 -> 74.666667 | AD23: =M23/$AB$2 -> 56 | AE23: =N23/$AB$2 -> 44.8 | AF23: =O23/$AB$2 -> 37.333333 | AG23: =P23/$AB$2 -> 32 | AH23: =Q23/$AB$2 -> 28 | AI23: =R23/$AB$2 -> 24.888889 | ... AP23: =Y23/$AB$2 -> 14 | AQ23: =J23/$AR$2 -> 112 | AR23: =K23/$AR$2 -> 56 | AS23: =L23/$AR$2 -> 37.333333 | AT23: =M23/$AR$2 -> 28 | AU23: =N23/$AR$2 -> 22.4 | AV23: =O23/$AR$2 -> 18.666667 | AW23: =P23/$AR$2 -> 16 | AX23: =Q23/$AR$2 -> 14 | ... BF23: =Y23/$AR$2 -> 7 | BG23: =J23/$BH$2 -> 74.666667 | BH23: =K23/$BH$2 -> 37.333333 | BI23: =L23/$BH$2 -> 24.888889 | BJ23: =M23/$BH$2 -> 18.666667 | BK23: =N23/$BH$2 -> 14.933333 | BL23: =O23/$BH$2 -> 12.444444 | BM23: =P23/$BH$2 -> 10.666667 | BN23: =Q23/$BH$2 -> 9.3333333 | ... BV23: =Y23/$BH$2 -> 4.6666667 | BW23: =J23/$BX$2 -> 56 | BX23: =K23/$BX$2 -> 28 | BY23: =L23/$BX$2 -> 18.666667 | BZ23: =M23/$BX$2 -> 14 | CA23: =N23/$BX$2 -> 11.2 | CB23: =O23/$BX$2 -> 9.3333333 | CC23: =P23/$BX$2 -> 8 | CD23: =Q23/$BX$2 -> 7 | ... CL23: =Y23/$BX$2 -> 3.5
I24: 29 | J24: =$E$3*I24 -> 464 | K24: =$E$4*I24 -> 232 | L24: =$E$5*I24 -> 154.66667 | M24: =$E$6*I24 -> 116 | N24: =$E$7*I24 -> 92.8 | O24: =$E$8*I24 -> 77.333333 | P24: =$E$9*I24 -> 66.285714 | Q24: =$E$10*I24 -> 58 | R24: =$E$11*I24 -> 51.555556 | S24: =$E$12*I24 -> 46.4 | T24: =$E$13*I24 -> 42.181818 | U24: =$E$14*I24 -> 38.666667 | V24: =$E$15*I24 -> 35.692308 | W24: =$E$16*I24 -> 33.142857 | X24: =$E$17*I24 -> 30.933333 | Y24: =$E$18*I24 -> 29 | AB24: =K24/$AB$2 -> 116 | AC24: =L24/$AB$2 -> 77.333333 | AD24: =M24/$AB$2 -> 58 | AE24: =N24/$AB$2 -> 46.4 | AF24: =O24/$AB$2 -> 38.666667 | AG24: =P24/$AB$2 -> 33.142857 | AH24: =Q24/$AB$2 -> 29 | AI24: =R24/$AB$2 -> 25.777778 | ... AP24: =Y24/$AB$2 -> 14.5 | AQ24: =J24/$AR$2 -> 116 | AR24: =K24/$AR$2 -> 58 | AS24: =L24/$AR$2 -> 38.666667 | AT24: =M24/$AR$2 -> 29 | AU24: =N24/$AR$2 -> 23.2 | AV24: =O24/$AR$2 -> 19.333333 | AW24: =P24/$AR$2 -> 16.571429 | AX24: =Q24/$AR$2 -> 14.5 | ... BF24: =Y24/$AR$2 -> 7.25 | BG24: =J24/$BH$2 -> 77.333333 | BH24: =K24/$BH$2 -> 38.666667 | BI24: =L24/$BH$2 -> 25.777778 | BJ24: =M24/$BH$2 -> 19.333333 | BK24: =N24/$BH$2 -> 15.466667 | BL24: =O24/$BH$2 -> 12.888889 | BM24: =P24/$BH$2 -> 11.047619 | BN24: =Q24/$BH$2 -> 9.6666667 | ... BV24: =Y24/$BH$2 -> 4.8333333 | BW24: =J24/$BX$2 -> 58 | BX24: =K24/$BX$2 -> 29 | BY24: =L24/$BX$2 -> 19.333333 | BZ24: =M24/$BX$2 -> 14.5 | CA24: =N24/$BX$2 -> 11.6 | CB24: =O24/$BX$2 -> 9.6666667 | CC24: =P24/$BX$2 -> 8.2857143 | CD24: =Q24/$BX$2 -> 7.25 | ... CL24: =Y24/$BX$2 -> 3.625
I25: 30 | J25: =$E$3*I25 -> 480 | K25: =$E$4*I25 -> 240 | L25: =$E$5*I25 -> 160 | M25: =$E$6*I25 -> 120 | N25: =$E$7*I25 -> 96 | O25: =$E$8*I25 -> 80 | P25: =$E$9*I25 -> 68.571429 | Q25: =$E$10*I25 -> 60 | R25: =$E$11*I25 -> 53.333333 | S25: =$E$12*I25 -> 48 | T25: =$E$13*I25 -> 43.636364 | U25: =$E$14*I25 -> 40 | V25: =$E$15*I25 -> 36.923077 | W25: =$E$16*I25 -> 34.285714 | X25: =$E$17*I25 -> 32 | Y25: =$E$18*I25 -> 30 | AB25: =K25/$AB$2 -> 120 | AC25: =L25/$AB$2 -> 80 | AD25: =M25/$AB$2 -> 60 | AE25: =N25/$AB$2 -> 48 | AF25: =O25/$AB$2 -> 40 | AG25: =P25/$AB$2 -> 34.285714 | AH25: =Q25/$AB$2 -> 30 | AI25: =R25/$AB$2 -> 26.666667 | ... AP25: =Y25/$AB$2 -> 15 | AQ25: =J25/$AR$2 -> 120 | AR25: =K25/$AR$2 -> 60 | AS25: =L25/$AR$2 -> 40 | AT25: =M25/$AR$2 -> 30 | AU25: =N25/$AR$2 -> 24 | AV25: =O25/$AR$2 -> 20 | AW25: =P25/$AR$2 -> 17.142857 | AX25: =Q25/$AR$2 -> 15 | ... BF25: =Y25/$AR$2 -> 7.5 | BG25: =J25/$BH$2 -> 80 | BH25: =K25/$BH$2 -> 40 | BI25: =L25/$BH$2 -> 26.666667 | BJ25: =M25/$BH$2 -> 20 | BK25: =N25/$BH$2 -> 16 | BL25: =O25/$BH$2 -> 13.333333 | BM25: =P25/$BH$2 -> 11.428571 | BN25: =Q25/$BH$2 -> 10 | ... BV25: =Y25/$BH$2 -> 5 | BW25: =J25/$BX$2 -> 60 | BX25: =K25/$BX$2 -> 30 | BY25: =L25/$BX$2 -> 20 | BZ25: =M25/$BX$2 -> 15 | CA25: =N25/$BX$2 -> 12 | CB25: =O25/$BX$2 -> 10 | CC25: =P25/$BX$2 -> 8.5714286 | CD25: =Q25/$BX$2 -> 7.5 | ... CL25: =Y25/$BX$2 -> 3.75
