Workbook

Sheet spi_protocol
B2: spi protocol | C2: data format (16-bit command+16-bit data) | U2: single write : size = 1 | DH2: reset
U3: nSCS
B4: command | D4: bit15 | E4: bit14 | F4: bit13 | G4: bit12 | H4: bit11 | I4: bit10 | J4: bit9 | K4: bit8 | L4: bit7 | M4: bit6 | N4: bit5 | O4: bit4 | P4: bit3 | Q4: bit2 | R4: bit1 | S4: bit0 | Z4: 16 | AB4: 15 | AD4: 14 | AH4: 3 | AJ4: 2 | AL4: 1 | AN4: 16 | AP4: 15 | AR4: 14 | AV4: 3 | AX4: 2 | AZ4: 1 | BB4: 16 | BD4: 15 | BF4: 14 | BJ4: 3 | BL4: 2 | BN4: 1 | BP4: 16 | BR4: 15 | BT4: 14 | BX4: 3 | BZ4: 2 | CB4: 1 | CD4: 16 | CF4: 15 | CH4: 14 | CL4: 3 | CN4: 2 | CP4: 1 | CR4: 16 | CT4: 15 | CV4: 14 | CZ4: 3 | DB4: 2 | DD4: 1
D5: command code [1:0] | F5: addr [7:0] | N5: size [5:0] | U5: SCLK
B6: register read | D6: 0 | E6: 1 | F6: start address | N6: burst size
B7: register write | D7: 1 | E7: 0 | F7: start address | N7: burst size | U7: MOSI | Z7: dev#1 command | AN7: dev#1 data | BB7: dev#2 command | BP7: dev#2 data | CD7: dev#3 command | CR7: dev#3 data
B8: ld transfer | D8: 1 | E8: 1 | F8: 8'hxx | N8: line size (max 63) | BB8: 16 | BD8: 15 | BF8: 14 | BJ8: 3 | BL8: 2 | BN8: 1 | BP8: 16 | BR8: 15 | BT8: 14 | BX8: 3 | BZ8: 2 | CB8: 1 | CD8: 16 | CF8: 15 | CH8: 14 | CL8: 3 | CN8: 2 | CP8: 1 | CR8: 16 | CT8: 15 | CV8: 14 | CZ8: 3 | DB8: 2 | DD8: 1
U9: SCLKO1
B11: register data | D11: bit15 | E11: bit14 | F11: bit13 | G11: bit12 | H11: bit11 | I11: bit10 | J11: bit9 | K11: bit8 | L11: bit7 | M11: bit6 | N11: bit5 | O11: bit4 | P11: bit3 | Q11: bit2 | R11: bit1 | S11: bit0 | U11: SDO1 | BB11: dev#2 command | BP11: dev#2 data | CD11: dev#3 command | CR11: dev#3 data
D12: register data [15:0] | CD12: 16 | CF12: 15 | CH12: 14 | CL12: 3 | CN12: 2 | CP12: 1 | CR12: 16 | CT12: 15 | CV12: 14 | CZ12: 3 | DB12: 2 | DD12: 1
B13: ld data | D13: ld_width = '00' 24-bit (pam 12-bit + pwm 12-bit) | U13: SCLKO2
D14: ld_width = '01' 24-bit (pam 12-bit + pwm 12-bit)
D15: ld_width = '00' 24-bit (pam 12-bit + pwm 12-bit) | U15: SDO2 | CD15: dev#3 command | CR15: dev#3 data
D16: ld_width = '00' 16-bit
U18: burst write : size dev#1/2/3 = 1/4/2
U19: nSCS
Z20: 16 | AB20: 15 | AF20: 1 | AH20: 16 | AJ20: 15 | AN20: 1 | AP20: 16 | AR20: 15 | AV20: 1 | AX20: 16 | AZ20: 15 | BD20: 1 | BF20: 16 | BH20: 15 | BL20: 1 | BN20: 16 | BP20: 15 | BT20: 1 | BV20: 16 | BX20: 15 | CB20: 1 | CD20: 16 | CF20: 15 | CJ20: 1 | CL20: 16 | CN20: 15 | CR20: 1 | CT20: 16 | CV20: 15 | CZ20: 1
U21: SCLK
AH22: addr=0x2
U23: MOSI | Z23: dev#1 cmd | AH23: dev#1 data1 | AP23: dev#2 cmd | AX23: dev#2 data1 | BF23: dev#2 data2 | BN23: dev#2 data3 | BV23: dev#2 data4 | CD23: dev#3 cmd | CL23: dev#3 data1 | CT23: dev#3 data2
AP24: 16 | AR24: 15 | AV24: 1 | AX24: 16 | AZ24: 15 | BD24: 1 | BF24: 16 | BH24: 15 | BL24: 1 | BN24: 16 | BP24: 15 | BT24: 1 | BV24: 16 | BX24: 15 | CB24: 1 | CD24: 16 | CF24: 15 | CJ24: 1 | CL24: 16 | CN24: 15 | CR24: 1 | CT24: 16 | CV24: 15 | CZ24: 1
U25: SCLKO1
AX26: addr=0x7 | BF26: addr=0x8 | BN26: addr=0x9 | BV26: addr=0x0A
U27: SDO1 | AP27: dev#2 cmd | AX27: dev#2 data1 | BF27: dev#2 data2 | BN27: dev#2 data3 | BV27: dev#2 data4 | CD27: dev#3 cmd | CL27: dev#3 data1 | CT27: dev#3 data2
CD28: 16 | CF28: 15 | CJ28: 1 | CL28: 16 | CN28: 15 | CR28: 1 | CT28: 16 | CV28: 15 | CZ28: 1
U29: SCLKO2
CL30: addr=0x05 | CT30: addr=0x06
U31: SDO2 | CD31: dev#3 cmd | CL31: dev#3 data1 | CT31: dev#3 data2
U34: single read : size = 1
U35: nSCS
Z36: 16 | AB36: 15 | AD36: 14 | AH36: 3 | AJ36: 2 | AL36: 1 | AN36: 16 | AP36: 15 | AR36: 14 | AV36: 3 | AX36: 2 | AZ36: 1 | BB36: 16 | BD36: 15 | BF36: 14 | BJ36: 3 | BL36: 2 | BN36: 1 | BP36: 16 | BR36: 15 | BT36: 14 | BX36: 3 | BZ36: 2 | CB36: 1 | CD36: 16 | CF36: 15 | CH36: 14 | CL36: 3 | CN36: 2 | CP36: 1 | CR36: 16 | CT36: 15 | CV36: 14 | CZ36: 3 | DB36: 2 | DD36: 1
U37: SCLK
U39: MOSI | Z39: dev#1 command | AN39: don’t care | BB39: dev#2 command | BP39: don’t care | CD39: dev#3 command | CR39: don’t care
BB40: 16 | BD40: 15 | BF40: 14 | BJ40: 3 | BL40: 2 | BN40: 1 | BP40: 16 | BR40: 15 | BT40: 14 | BX40: 3 | BZ40: 2 | CB40: 1 | CD40: 16 | CF40: 15 | CH40: 14 | CL40: 3 | CN40: 2 | CP40: 1 | CR40: 16 | CT40: 15 | CV40: 14 | CZ40: 3 | DB40: 2 | DD40: 1
U41: SCLKO1
U43: SDO1 | BB43: dev#2 command | BP43: don’t care | CD43: dev#3 command | CR43: don’t care
CD44: 16 | CF44: 15 | CH44: 14 | CL44: 3 | CN44: 2 | CP44: 1 | CR44: 16 | CT44: 15 | CV44: 14 | CZ44: 3 | DB44: 2 | DD44: 1
U45: SCLKO2
U47: SDO2 | CD47: dev#3 command | CR47: don’t care
U49: MISO1 | AN49: dev#1 data
...

Sheet serial_protocol
B2: serializer/de-serializer | C2: data format
B3: protocol
D4: bit21 | E4: bit20 | F4: bit19 | G4: bit18 | H4: bit17 | I4: bit16 | J4: bit15 | K4: bit14 | L4: bit13 | M4: bit12 | N4: bit11 | O4: bit10 | P4: bit9 | Q4: bit8 | R4: bit7 | S4: bit6 | T4: bit5 | U4: bit4 | V4: bit3 | W4: bit2 | X4: bit1 | Y4: bit0
B5: (serializer) | D5: start | E5: command code [2:0] | H5: addr [5:0] | N5: data [11:0]
B6: write command | D6: 1 | E6: 1 | F6: 0 | G6: 1
D7: bit9 | E7: bit8 | F7: bit7 | G7: bit6 | H7: bit5 | I7: bit4 | J7: bit3 | K7: bit2 | L7: bit1 | M7: bit0
B8: (serializer) | D8: start | E8: command code [2:0] | H8: addr [5:0]
B9: read command | D9: 1 | E9: 1 | F9: 1 | G9: 0 | AW9: (ld_width=00,01,10)
D10: bit20 | E10: bit19 | F10: bit18 | G10: bit17 | H10: bit16 | I10: bit15 | J10: bit14 | K10: bit13 | L10: bit12 | M10: bit11 | N10: bit10 | O10: bit9 | P10: bit8 | Q10: bit7 | R10: bit6 | S10: bit5 | T10: bit4 | U10: bit3 | V10: bit2 | W10: bit1 | X10: bit0 | AD10: DIO #1 | AF10: write cmd #1 | AG10: addr #1 | AH10: data #1 | AI10: write cmd #2 | AM10: addr #2 | AN10: data #2 | AR10: write cmd #n | AS10: addr #n | AT10: data #n | AW10: DIO #1 | AY10: ld cmd #1 | AZ10: pam1 #1 | BA10: pwm1 #1 | BB10: pam2 #1 | BF10: pwm8 #1 | BG10: ld cmd #2 | BH10: pam1 #2 | BI10: pwm1 #2 | BJ10: pam2 #2 | BN10: pwm8 #n | BQ10: DIO #1 | BS10: sync gen cmd #1 | BT10: sync gen cmd #2 | BX10: sync gen cmd #n | CA10: DIO #1 | CC10: fault read cmd #1 | CD10: fault read cmd #2 | CH10: fault read cmd #n | CQ10: fault read cmd | CR10: d2 | d1
B11: (de-serializer) | D11: start | E11: command code [2:0] | H11: ld [4:0] | M11: data [11:0]
B12: read receive format | D12: 1 | E12: 1 | F12: 1 | G12: 0 | AD12: DIO #2 | AI12: write cmd #2 | AM12: addr #2 | AN12: data #2 | AR12: write cmd #n | AS12: addr #n | AT12: data #n | AW12: DIO #2 | BG12: ld cmd #2 | BH12: pam1 #2 | BI12: pwm1 #2 | BJ12: pam2 #2 | BN12: pwm8 #n | BQ12: DIO #2 | BT12: sync gen cmd #2 | BX12: sync gen cmd #n | CA12: DIO #2 | CD12: fault read cmd#2 | CH12: fault read cmd #n | CP12: fault read cmd | CQ12: d3 | d2
D13: bit23 | E13: bit22 | F13: bit21 | G13: bit20 | H13: bit19 | I13: bit18 | J13: bit17 | K13: bit16 | L13: bit15 | M13: bit14 | N13: bit13 | O13: bit12 | P13: bit11 | Q13: bit10 | R13: bit9 | S13: bit8 | T13: bit7 | U13: bit6 | V13: bit5 | W13: bit4 | X13: bit3 | Y13: bit2 | Z13: bit1 | AA13: bit0
B14: (serializer) | D14: start | E14: command code [2:0] | H14: pam [9:0] | R14: pwm [9:0] | AD14: DDO #2 | AR14: write cmd #n | AS14: addr #n | AT14: data #n | AW14: DDO #2 | BN14: pwm8 #n | BQ14: DDO #2 | BX14: sync gen cmd #n | CA14: DDO #2 | CH14: fault read cmd #n | CO14: fault read cmd | CP14: d4 | d3
B15: ld transfer @ld_width='00' | D15: 1 | E15: 1 | F15: 1 | G15: 1
D16: bit24 | E16: bit23 | F16: bit22 | G16: bit21 | H16: bit20 | I16: bit19 | J16: bit18 | K16: bit17 | L16: bit16 | M16: bit15 | N16: bit14 | O16: bit13 | P16: bit12 | Q16: bit11 | R16: bit10 | S16: bit9 | T16: bit8 | U16: bit7 | V16: bit6 | W16: bit5 | X16: bit4 | Y16: bit3 | Z16: bit2 | AA16: bit1 | AB16: bit0 | AD16: DIO #n | AR16: write cmd #n | AS16: addr #n | AT16: data #n | AW16: DIO #n | BN16: pwm8 #n | BQ16: DIO #n | BX16: sync gen cmd #n | CA16: DIO #n | CH16: fault read cmd #n | CL16: fault read cmd | CM16: 4'bxxxx
B17: (serializer) | D17: start | E17: command code [2:0] | H17: pam [9:0] | R17: pwm [10:0]
B18: ld transfer @ld_width='01' | D18: 1 | E18: 1 | F18: 1 | G18: 1 | AD18: DDO #n | AW18: DDO #n | BQ18: DDO #n | CA18: DDO #n
D19: bit25 | E19: bit24 | F19: bit23 | G19: bit22 | H19: bit21 | I19: bit20 | J19: bit19 | K19: bit18 | L19: bit17 | M19: bit16 | N19: bit15 | O19: bit14 | P19: bit13 | Q19: bit12 | R19: bit11 | S19: bit10 | T19: bit9 | U19: bit8 | V19: bit7 | W19: bit6 | X19: bit5 | Y19: bit4 | Z19: bit3 | AA19: bit2 | AB19: bit1 | AC19: bit0
B20: (serializer) | D20: start | E20: command code [2:0] | H20: pam [9:0] | R20: pwm [11:0]
B21: ld transfer @ld_width='10' | D21: 1 | E21: 1 | F21: 1 | G21: 1
D22: bit19 | E22: bit18 | F22: bit17 | G22: bit16 | H22: bit15 | I22: bit14 | J22: bit13 | K22: bit12 | L22: bit11 | M22: bit10 | N22: bit9 | O22: bit8 | P22: bit7 | Q22: bit6 | R22: bit5 | S22: bit4 | T22: bit3 | U22: bit2 | V22: bit1 | W22: bit0
B23: (serializer) | D23: start | E23: command code [2:0] | H23: ld [15:0] | AW23: (ld_width=11)
B24: ld transfer @ld_width='11' | D24: 1 | E24: 1 | F24: 1 | G24: 1 | AD24: DIO #1 | AF24: read_in cmd #1 | AH24: addr #1 | AI24: read_in cmd #2 | AM24: addr #2 | AR24: read_in cmd #n | AS24: addr #n | AW24: DIO #1 | AY24: ld cmd #1 | AZ24: ld1(16-b)#1 | BA24: ld2(16-b)#1 | BB24: ld3(16-b)#1 | BF24: ld3(16-b)#1 | BG24: ld cmd #2 | BH24: ld1(16-b)#1 | BI24: ld2(16-b)#1 | BJ24: ld3(16-b)#1 | BN24: ld8(16-b)#1
D25: bit8 | E25: bit7 | F25: bit6 | G25: bit5
B26: (serializer) | D26: start | E26: command code [2:0] | AD26: DIO #2 | AI26: read_in cmd #2 | AM26: addr #2 | AR26: read_in cmd #n | AS26: addr #n | AW26: DIO #2 | BG26: ld cmd #2 | BH26: ld1(16-b)#1 | BI26: ld2(16-b)#1 | BJ26: ld3(16-b)#1 | BN26: ld8(16-b)#1
B27: fault (auto) read command | D27: 1 | E27: 0 | F27: 1 | G27: 0
D28: bit7 | E28: bit6 | F28: bit5 | G28: bit4 | H28: bit3 | I28: bit2 | J28: bit1 | K28: bit0 | AD28: DDO #2 | AR28: read_in cmd #n | AS28: addr #n | AW28: DDO #2 | BN28: ld8(16-b)#1
B29: (de-serializer) | D29: start | E29: command code [2:0] | H29: thermal | I29: short | J29: open | K29: fb
B30: fault (auto) receive format | D30: 1 | E30: 0 | F30: 1 | G30: 0 | AD30: DIO #n | AR30: read_in cmd #n | AS30: addr #n | AW30: DIO #n | BN30: ld8(16-b)#1
D31: bit4 | E31: bit3 | F31: bit2 | G31: bit1
B32: (serializer) | D32: start | E32: command code [2:0] | AD32: DDO #n | AW32: DDO #n
B33: sync (auto) gen | D33: 1 | E33: 0 | F33: 0 | G33: 1
D34: bit4 | E34: bit3 | F34: bit2 | G34: bit1
B35: (serializer) | D35: start | E35: command code [2:0]
B36: id gen | D36: 1 | E36: 0 | F36: 0 | G36: 0
AD38: DDO #n
B39: PROTOCOL | D39: frame format
AD40: DIO #n | AF40: read_out cmd #n | AG40: id #n | AH40: data #n
B41: write command | D41: bit21 | E41: bit20 | F41: bit19 | G41: bit18 | H41: bit17 | I41: bit16 | J41: bit15 | K41: bit14 | L41: bit13 | M41: bit12 | N41: bit11 | O41: bit10 | P41: bit9 | Q41: bit8 | R41: bit7 | S41: bit6 | T41: bit5 | U41: bit4 | V41: bit3 | W41: bit2 | X41: bit1 | Y41: bit0
B42: 1101 | D42: start | E42: cmd code [2:0] | H42: addr [5:0] | N42: data [11:0] | AD42: DIO #n-1 | AF42: read_out cmd #n | AG42: id #n | AH42: data #n
...

Sheet ld_transfer_thruput
G2: total line | H2: # | I2: 1 | J2: 2 | K2: 3 | L2: 4 | M2: 5 | N2: 6 | O2: 7 | P2: 8 | Q2: 9 | R2: 10 | S2: 11 | T2: 12 | U2: 13 | V2: 14 | W2: 15 | X2: 16 | Y2: 17 | Z2: 18 | AA2: 19 | AB2: 20 | AC2: 21 | AD2: 22 | AE2: 23 | AF2: 24 | AG2: 25 | AH2: 26 | AI2: 27 | AJ2: 28 | AK2: 29 | AL2: 30 | AM2: 31 | AN2: 32 | AO2: 33 | AP2: 34 | AQ2: 35 | AR2: 36 | AS2: 37 | AT2: 38 | AU2: 39 | AV2: 40 | AW2: 41 | AX2: 42 | AY2: 43 | AZ2: 44 | BA2: 45 | BB2: 46 | BC2: 47 | BD2: 48 | BE2: 49 | BF2: 50 | BG2: 51 | BH2: 52 | BI2: 53 | BJ2: 54 | BK2: 55 | BL2: 56 | BM2: 57 | BN2: 58 | BO2: 59 | BP2: 60 | BQ2: 61 | BR2: 62 | BS2: 63 | BT2: 64 | BU2: 65 | BV2: 66 | BW2: 67 | BX2: 68 | BY2: 69 | BZ2: 70 | CA2: 71 | CB2: 72 | CC2: 73 | CD2: 74 | CE2: 75 | CF2: 76 | CG2: 77 | CH2: 78 | CI2: 79 | CJ2: 80 | CK2: 81 | CL2: 82 | CM2: 83 | CN2: 84 | CO2: 85 | CP2: 86 | CQ2: 87 | CR2: 88 | CS2: 89 | CT2: 90 | CU2: 91 | CV2: 92 | CW2: 93 | CX2: 94 | CY2: 95 | CZ2: 96 | DA2: 97 | DB2: 98 | DC2: 99 | DD2: 100 | DE2: 101 | DF2: 102 | DG2: 103 | DH2: 104 | DI2: 105 | DJ2: 106 | DK2: 107 | DL2: 108 | DM2: 109 | DN2: 110 | DO2: 111 | DP2: 112 | DQ2: 113 | DR2: 114 | DS2: 115 | DT2: 116 | DU2: 117 | DV2: 118 | DW2: 119 | DX2: 120 | DY2: 121 | DZ2: 122 | EA2: 123 | EB2: 124 | EC2: 125 | ED2: 126 | EE2: 127 | EF2: 128 | EG2: 129 | EH2: 130 | EI2: 131 | EJ2: 132 | EK2: 133 | EL2: 134 | EM2: 135 | EN2: 136 | EO2: 137 | EP2: 138 | EQ2: 139 | ER2: 140 | ES2: 141 | ET2: 142 | EU2: 143 | EV2: 144 | EW2: 145 | EX2: 146 | EY2: 147 | EZ2: 148 | FA2: 149 | FB2: 150 | FC2: 151 | FD2: 152 | FE2: 153 | FF2: 154 | FG2: 155 | FH2: 156 | FI2: 157 | FJ2: 158 | FK2: 159 | FL2: 160 | FM2: 161 | FN2: 162 | FO2: 163 | FP2: 164 | FQ2: 165 | FR2: 166 | FS2: 167 | FT2: 168 | FU2: 169 | FV2: 170 | FW2: 171 | FX2: 172 | FY2: 173 | FZ2: 174 | GA2: 175 | GB2: 176 | GC2: 177 | GD2: 178 | GE2: 179 | GF2: 180 | GG2: 181 | GH2: 182 | GI2: 183 | GJ2: 184 | GK2: 185 | GL2: 186 | GM2: 187 | GN2: 188 | GO2: 189 | GP2: 190 | GQ2: 191 | GR2: 192 | GS2: 193 | GT2: 194 | GU2: 195 | GV2: 196 | GW2: 197 | GX2: 198 | GY2: 199 | GZ2: 200 | HA2: 201 | HB2: 202 | HC2: 203 | HD2: 204 | HE2: 205 | HF2: 206 | HG2: 207 | HH2: 208 | HI2: 209 | HJ2: 210 | HK2: 211 | HL2: 212 | HM2: 213 | HN2: 214 | HO2: 215 | HP2: 216 | HQ2: 217 | HR2: 218 | HS2: 219 | HT2: 220 | HU2: 221 | HV2: 222 | HW2: 223 | HX2: 224 | HY2: 225 | HZ2: 226 | IA2: 227 | IB2: 228 | IC2: 229 | ID2: 230 | IE2: 231 | IF2: 232 | IG2: 233 | IH2: 234 | II2: 235 | IJ2: 236 | IK2: 237 | IL2: 238 | IM2: 239 | IN2: 240 | IO2: 241 | IP2: 242 | IQ2: 243 | IR2: 244 | IS2: 245 | IT2: 246 | IU2: 247 | IV2: 248
B3: spi frequency | C3: 18 | D3: mhz | F3: spi thruput | G3: line | H3: # | I3: 1 | J3: 2 | K3: 3 | L3: 4 | M3: 5 | N3: 6 | O3: 7 | P3: 8 | Q3: 9 | R3: 10 | S3: 11 | T3: 12 | U3: 13 | V3: 14 | W3: 15 | X3: 16 | AQ3: 11 | AR3: 12 | AS3: 13 | AT3: 14 | AU3: 15 | AV3: 16 | AW3: 17 | AX3: 18 | AY3: 19 | AZ3: 20 | BA3: 21 | BB3: 22 | BC3: 23 | BD3: 24 | BE3: 1 | BF3: 2 | BG3: 3 | BH3: 4 | BI3: 5 | BJ3: 6 | BK3: 7 | BL3: 8 | BM3: 9 | BN3: 10 | BO3: 11 | BP3: 12 | BQ3: 13 | BR3: 14 | BS3: 15 | BT3: 16 | BU3: 17 | BV3: 18 | BW3: 19 | BX3: 20 | BY3: 21 | BZ3: 22 | CA3: 23 | CB3: 24 | CC3: 25 | CD3: 26 | CE3: 27 | CF3: 28 | CG3: 29 | CH3: 30 | CI3: 31 | CJ3: 32 | CK3: 33 | CL3: 34 | CM3: 35 | CN3: 36 | CO3: 37 | CP3: 38 | CQ3: 39 | CR3: 40 | CS3: 41 | CT3: 42 | CU3: 43 | CV3: 44 | CW3: 45 | CX3: 46 | CY3: 47 | CZ3: 48 | DA3: 49 | DB3: 50 | DC3: 51 | DD3: 52 | DE3: 53 | DF3: 54 | DG3: 55 | DH3: 56 | DI3: 57 | DJ3: 58 | DK3: 59 | DL3: 60 | DM3: 61 | DN3: 62 | DO3: 63 | DP3: 64 | DQ3: 65 | DR3: 66 | DS3: 67 | DT3: 68 | DU3: 69 | DV3: 70 | DW3: 71 | DX3: 72 | DY3: 73 | DZ3: 74 | EA3: 75 | EB3: 76 | EC3: 77 | ED3: 78 | EE3: 79 | EF3: 80 | EG3: 81 | EH3: 82 | EI3: 83 | EJ3: 84 | EK3: 85 | EL3: 86 | EM3: 87 | EN3: 88 | EO3: 89 | EP3: 90 | EQ3: 91 | ER3: 92 | ES3: 93 | ET3: 94 | EU3: 95 | EV3: 96 | EW3: 97 | EX3: 98 | EY3: 99 | EZ3: 100 | FA3: 101 | FB3: 102 | FC3: 103 | FD3: 104 | FE3: 105 | FF3: 106 | FG3: 107 | FH3: 108 | FI3: 109 | FJ3: 110 | FK3: 111 | FL3: 112 | FM3: 113 | FN3: 114 | FO3: 115 | FP3: 116 | FQ3: 117 | FR3: 118 | FS3: 119 | FT3: 120 | FU3: 121 | FV3: 122 | FW3: 123 | FX3: 124 | FY3: 125 | FZ3: 126 | GA3: 127 | GB3: 128 | GC3: 129 | GD3: 130 | GE3: 131 | GF3: 132 | GG3: 133 | GH3: 134 | GI3: 135 | GJ3: 136 | GK3: 137 | GL3: 138 | GM3: 139 | GN3: 140 | GO3: 141 | GP3: 142 | GQ3: 143 | GR3: 144 | GS3: 145 | GT3: 146 | GU3: 147 | GV3: 148 | GW3: 149 | GX3: 150 | GY3: 151 | GZ3: 152 | HA3: 153 | HB3: 154 | HC3: 155 | HD3: 156 | HE3: 157 | HF3: 158 | HG3: 159 | HH3: 160 | HI3: 161 | HJ3: 162 | HK3: 163 | HL3: 164 | HM3: 165 | HN3: 166 | HO3: 167 | HP3: 168 | HQ3: 169 | HR3: 170 | HS3: 171 | HT3: 172 | HU3: 173 | HV3: 174 | HW3: 175 | HX3: 176 | HY3: 177 | HZ3: 178 | IA3: 179 | IB3: 180 | IC3: 181 | ID3: 182 | IE3: 183 | IF3: 184 | IG3: 185 | IH3: 186 | II3: 187 | IJ3: 188 | IK3: 189 | IL3: 190 | IM3: 191 | IN3: 192 | IO3: 193 | IP3: 194 | IQ3: 195 | IR3: 196 | IS3: 197 | IT3: 198 | IU3: 199 | IV3: 200 | IW3: 201 | IX3: 202 | IY3: 203 | IZ3: 204 | JA3: 205 | JB3: 206 | JC3: 207 | JD3: 208 | JE3: 209 | JF3: 210 | JG3: 211 | JH3: 212 | JI3: 213 | JJ3: 214 | JK3: 215 | JL3: 216 | JM3: 217 | JN3: 218 | JO3: 219 | JP3: 220 | JQ3: 221 | JR3: 222 | JS3: 223 | JT3: 224 | JU3: 225
B4: spi ld/blk | C4: 16 | D4: bit | F4: (burst size=24) | G4: transmit | H4: us | I4: =$C$5 + (16+$C$4*$C$7*(I3)) * (1/$C$3) -> 3.0777778 | J4: =I4 + ($C$4*$C$7*(J3-I3))*(1/$C$3) -> 3.9666667 | K4: =J4 + ($C$4*$C$7*(K3-J3))*(1/$C$3) -> 4.8555556 | L4: =K4 + ($C$4*$C$7*(L3-K3))*(1/$C$3) -> 5.7444444 | M4: =L4 + ($C$4*$C$7*(M3-L3))*(1/$C$3) -> 6.6333333 | N4: =M4 + ($C$4*$C$7*(N3-M3))*(1/$C$3) -> 7.5222222 | O4: =N4 + ($C$4*$C$7*(O3-N3))*(1/$C$3) -> 8.4111111 | P4: =O4 + ($C$4*$C$7*(P3-O3))*(1/$C$3) -> 9.3 | Q4: =P4 + ($C$4*$C$7*(Q3-P3))*(1/$C$3) -> 10.188889 | ... X4: =W4 + ($C$4*$C$7*(X3-W3))*(1/$C$3) -> 16.411111 | AQ4: =AP4 + ($C$4*$C$7*(AQ3-AP3))*(1/$C$3) -> 9.7777778 | AR4: =AQ4 + ($C$4*$C$7*(AR3-AQ3))*(1/$C$3) -> 10.666667 | AS4: =AR4 + ($C$4*$C$7*(AS3-AR3))*(1/$C$3) -> 11.555556 | AT4: =AS4 + ($C$4*$C$7*(AT3-AS3))*(1/$C$3) -> 12.444444 | AU4: =AT4 + ($C$4*$C$7*(AU3-AT3))*(1/$C$3) -> 13.333333 | AV4: =AU4 + ($C$4*$C$7*(AV3-AU3))*(1/$C$3) -> 14.222222 | AW4: =AV4 + ($C$4*$C$7*(AW3-AV3))*(1/$C$3) -> 15.111111 | AX4: =AW4 + ($C$4*$C$7*(AX3-AW3))*(1/$C$3) -> 16 | ... BD4: =BC4 + ($C$4*$C$7*(BD3-BC3))*(1/$C$3) -> 21.333333 | BE4: =BD4 + (C5+C6) + (16+$C$4*$C$7*(BE3))*(1/$C$3) -> 107.41111 | BF4: =BE4 + ($C$4*$C$7*(BF3-BE3))*(1/$C$3) -> 108.3 | BG4: =BF4 + ($C$4*$C$7*(BG3-BF3))*(1/$C$3) -> 109.18889 | BH4: =BG4 + ($C$4*$C$7*(BH3-BG3))*(1/$C$3) -> 110.07778 | BI4: =BH4 + ($C$4*$C$7*(BI3-BH3))*(1/$C$3) -> 110.96667 | BJ4: =BI4 + ($C$4*$C$7*(BJ3-BI3))*(1/$C$3) -> 111.85556 | BK4: =BJ4 + ($C$4*$C$7*(BK3-BJ3))*(1/$C$3) -> 112.74444 | BL4: =BK4 + ($C$4*$C$7*(BL3-BK3))*(1/$C$3) -> 113.63333 | BM4: =BL4 + ($C$4*$C$7*(BM3-BL3))*(1/$C$3) -> 114.52222 | ... JU4: =JT4 + ($C$4*$C$7*(JU3-JT3))*(1/$C$3) -> 306.52222
B5: spi latency1 | C5: =1.3 -> 1.3 | D5: us | F5: ld serializing thruput | G5: block | H5: # | J5: 1 | K5: 2 | L5: 3 | M5: 4 | N5: 5 | O5: 6 | P5: 7 | Q5: 8 | R5: 9 | S5: 10 | T5: 11 | U5: 12 | V5: 13 | W5: 14 | X5: 15 | Y5: 16 | AW5: 33 | AX5: 34 | AY5: 35 | AZ5: 36 | BA5: 37 | BB5: 38 | BC5: 39 | BD5: 40 | BE5: 41 | BF5: 42 | BG5: 43 | BH5: 44 | BI5: 45 | BJ5: 46 | BK5: 47 | BL5: 48 | BM5: 49 | BN5: 50 | BO5: 51 | BP5: 52 | BQ5: 53 | BR5: 54 | BS5: 55 | BT5: 56 | BU5: 57 | BV5: 58 | BW5: 59 | BX5: 60 | BY5: 61 | BZ5: 62 | CA5: 63 | CB5: 64 | CC5: 65 | CD5: 66 | CE5: 67 | CF5: 68 | CG5: 69 | CH5: 70 | CI5: 71 | CJ5: 72 | CK5: 73 | CL5: 74 | CM5: 75 | CN5: 76 | CO5: 77 | CP5: 78 | CQ5: 79 | CR5: 80 | CS5: 81 | CT5: 82 | CU5: 83 | CV5: 84 | CW5: 85 | CX5: 86 | CY5: 87 | CZ5: 88 | DA5: 89 | DB5: 90 | DC5: 91 | DD5: 92 | DE5: 93 | DF5: 94 | DG5: 95 | DH5: 96 | DI5: 97 | DJ5: 98 | DK5: 99 | DL5: 100 | DM5: 101 | DN5: 102 | DO5: 103 | DP5: 104 | DQ5: 105 | DR5: 106 | DS5: 107 | DT5: 108 | DU5: 109 | DV5: 110 | DW5: 111 | DX5: 112 | DY5: 113 | DZ5: 114 | EA5: 115 | EB5: 116 | EC5: 117 | ED5: 118 | EE5: 119 | EF5: 120 | EG5: 121 | EH5: 122 | EI5: 123 | EJ5: 124 | EK5: 125 | EL5: 126 | EM5: 127 | EN5: 128 | EO5: 129 | EP5: 130 | EQ5: 131 | ER5: 132 | ES5: 133 | ET5: 134 | EU5: 135 | EV5: 136 | EW5: 137 | EX5: 138 | EY5: 139 | EZ5: 140 | FA5: 141 | FB5: 142 | FC5: 143 | FD5: 144 | FE5: 145 | FF5: 146 | FG5: 147 | FH5: 148 | FI5: 149 | FJ5: 150 | FK5: 151 | FL5: 152 | FM5: 153 | FN5: 154 | FO5: 155 | FP5: 156 | FQ5: 157 | FR5: 158 | FS5: 159 | FT5: 160 | FU5: 161 | FV5: 162 | FW5: 163 | FX5: 164 | FY5: 165 | FZ5: 166 | GA5: 167 | GB5: 168 | GC5: 169 | GD5: 170 | GE5: 171 | GF5: 172 | GG5: 173 | GH5: 174 | GI5: 175 | GJ5: 176 | GK5: 177 | GL5: 178 | GM5: 179 | GN5: 180 | GO5: 181 | GP5: 182 | GQ5: 183 | GR5: 184 | GS5: 185 | GT5: 186 | GU5: 187 | GV5: 188 | GW5: 189 | GX5: 190 | GY5: 191 | GZ5: 192 | HA5: 193 | HB5: 194 | HC5: 195 | HD5: 196 | HE5: 197 | HF5: 198 | HG5: 199 | HH5: 200 | HI5: 201 | HJ5: 202 | HK5: 203 | HL5: 204 | HM5: 205 | HN5: 206 | HO5: 207 | HP5: 208 | HQ5: 209 | HR5: 210 | HS5: 211 | HT5: 212 | HU5: 213 | HV5: 214 | HW5: 215 | HX5: 216 | HY5: 217 | HZ5: 218 | IA5: 219 | IB5: 220 | IC5: 221 | ID5: 222 | IE5: 223 | IF5: 224 | IG5: 225 | IH5: 226 | II5: 227 | IJ5: 228 | IK5: 229 | IL5: 230 | IM5: 231 | IN5: 232 | IO5: 233 | IP5: 234 | IQ5: 235 | IR5: 236 | IS5: 237 | IT5: 238 | IU5: 239 | IV5: 240 | IW5: 241 | IX5: 242 | IY5: 243 | IZ5: 244 | JA5: 245 | JB5: 246 | JC5: 247 | JD5: 248 | JE5: 249 | JF5: 250 | JG5: 251 | JH5: 252 | JI5: 253 | JJ5: 254 | JK5: 255 | JL5: 256 | JM5: 257 | JN5: 258 | JO5: 259 | JP5: 260 | JQ5: 261 | JR5: 262 | JS5: 263 | JT5: 264 | JU5: 265
B6: spi latency2 | C6: =1.7+80+C5 -> 83 | D6: us | G6: transmit | H6: us | J6: =$L$4 + (4*ROUNDUP(J5/$C$8,0)+($C$4)*J5) /$C$9 -> 15.744444 | K6: =$L$4 + (4*ROUNDUP(K5/$C$8,0)+($C$4)*K5) /$C$9 -> 23.744444 | L6: =$L$4 + (4*ROUNDUP(L5/$C$8,0)+($C$4)*L5) /$C$9 -> 31.744444 | M6: =$L$4 + (4*ROUNDUP(M5/$C$8,0)+($C$4)*M5) /$C$9 -> 39.744444 | N6: =$L$4 + (4*ROUNDUP(N5/$C$8,0)+($C$4)*N5) /$C$9 -> 47.744444 | O6: =$L$4 + (4*ROUNDUP(O5/$C$8,0)+($C$4)*O5) /$C$9 -> 55.744444 | P6: =$L$4 + (4*ROUNDUP(P5/$C$8,0)+($C$4)*P5) /$C$9 -> 63.744444 | Q6: =$L$4 + (4*ROUNDUP(Q5/$C$8,0)+($C$4)*Q5) /$C$9 -> 71.744444 | ... Y6: =$L$4 + (4*ROUNDUP(Y5/$C$8,0)+($C$4)*Y5) /$C$9 -> 137.74444 | AW6: =$P$4 + (4*ROUNDUP(AW5/$C$8,0)+($C$4)*AW5) /$C$9 -> 283.3 | AX6: =$P$4 + (4*ROUNDUP(AX5/$C$8,0)+($C$4)*AX5) /$C$9 -> 291.3 | AY6: =$P$4 + (4*ROUNDUP(AY5/$C$8,0)+($C$4)*AY5) /$C$9 -> 299.3 | AZ6: =$P$4 + (4*ROUNDUP(AZ5/$C$8,0)+($C$4)*AZ5) /$C$9 -> 307.3 | BA6: =$P$4 + (4*ROUNDUP(BA5/$C$8,0)+($C$4)*BA5) /$C$9 -> 315.3 | BB6: =$P$4 + (4*ROUNDUP(BB5/$C$8,0)+($C$4)*BB5) /$C$9 -> 323.3 | BC6: =$P$4 + (4*ROUNDUP(BC5/$C$8,0)+($C$4)*BC5) /$C$9 -> 331.3 | BD6: =$P$4 + (4*ROUNDUP(BD5/$C$8,0)+($C$4)*BD5) /$C$9 -> 339.3 | ... JU6: =$P$4 + (4*ROUNDUP(JU5/$C$8,0)+($C$4)*JU5) /$C$9 -> 2197.3
B7: xc_ld_size | C7: 1 | D7: ea | F7: ld_transfer_start_point | G7: 1 | H7: ea
B8: xc_dev_ch_size | C8: 8 | D8: ea | F8: margin | G8: room t | H8: us | J8: =J6-I4 -> 12.666667 | K8: =K6-J4 -> 19.777778 | L8: =L6-K4 -> 26.888889 | M8: =M6-L4 -> 34 | N8: =N6-M4 -> 41.111111 | O8: =O6-N4 -> 48.222222 | P8: =P6-O4 -> 55.333333 | Q8: =Q6-P4 -> 62.444444 | ... Y8: =Y6-X4 -> 121.33333 | Z8: =#REF!-Y4 -> #REF! | AA8: =#REF!-Z4 -> #REF! | AB8: =#REF!-AA4 -> #REF! | AC8: =#REF!-AB4 -> #REF! | AD8: =#REF!-AC4 -> #REF! | AE8: =#REF!-AD4 -> #REF! | AF8: =#REF!-AE4 -> #REF! | AG8: =#REF!-AF4 -> #REF! | AH8: =AK6-AG4 -> 0 | AI8: =AL6-AH4 -> 0 | AJ8: =AM6-AI4 -> 0 | AK8: =AN6-AJ4 -> 0 | AL8: =AO6-AK4 -> 0 | AM8: =AP6-AL4 -> 0 | AN8: =AQ6-AM4 -> 0 | AO8: =AR6-AN4 -> 0 | AW8: =AW6-AO4 -> 283.3 | AX8: =AX6-AP4 -> 291.3 | AY8: =AY6-AQ4 -> 289.52222 | AZ8: =AZ6-AR4 -> 296.63333 | BA8: =BA6-AS4 -> 303.74444 | BB8: =BB6-AT4 -> 310.85556 | BC8: =BC6-AU4 -> 317.96667 | BD8: =BD6-AV4 -> 325.07778 | ... JU8: =JU6-JM4 -> 1897.8889
B9: xc baudrate | C9: 2 | D9: mbps | G9: room blk# | H9: ea | J9: =J8 / ( (16+$C$4*$C$7)*(1/$C$3) + $C$5 ) -> 4.1155235 | K9: =K8 / ( (16+$C$4*$C$7)*(1/$C$3) + $C$5 ) -> 6.4259928 | L9: =L8 / ( (16+$C$4*$C$7)*(1/$C$3) + $C$5 ) -> 8.7364621 | M9: =M8 / ( (16+$C$4*$C$7)*(1/$C$3) + $C$5 ) -> 11.046931 | N9: =N8 / ( (16+$C$4*$C$7)*(1/$C$3) + $C$5 ) -> 13.357401 | O9: =O8 / ( (16+$C$4*$C$7)*(1/$C$3) + $C$5 ) -> 15.66787 | P9: =P8 / ( (16+$C$4*$C$7)*(1/$C$3) + $C$5 ) -> 17.978339 | Q9: =Q8 / ( (16+$C$4*$C$7)*(1/$C$3) + $C$5 ) -> 20.288809 | ... AO9: =AO8 / ( (16+$C$4*$C$7)*(1/$C$3) + $C$5 ) -> 0 | AW9: =AW8 / ( (16+$C$4*$C$7)*(1/$C$3) + $C$5 ) -> 92.046931 | AX9: =AX8 / ( (16+$C$4*$C$7)*(1/$C$3) + $C$5 ) -> 94.646209 | AY9: =AY8 / ( (16+$C$4*$C$7)*(1/$C$3) + $C$5 ) -> 94.068592 | AZ9: =AZ8 / ( (16+$C$4*$C$7)*(1/$C$3) + $C$5 ) -> 96.379061 | BA9: =BA8 / ( (16+$C$4*$C$7)*(1/$C$3) + $C$5 ) -> 98.689531 | BB9: =BB8 / ( (16+$C$4*$C$7)*(1/$C$3) + $C$5 ) -> 101 | BC9: =BC8 / ( (16+$C$4*$C$7)*(1/$C$3) + $C$5 ) -> 103.31047 | BD9: =BD8 / ( (16+$C$4*$C$7)*(1/$C$3) + $C$5 ) -> 105.62094 | ... JU9: =JU8 / ( (16+$C$4*$C$7)*(1/$C$3) + $C$5 ) -> 616.6426
G12: total line | H12: # | I12: 1 | J12: 2 | K12: 3 | L12: 4 | M12: 5 | N12: 6 | O12: 7 | P12: 8 | Q12: 9 | R12: 10 | S12: 11 | T12: 12 | U12: 13 | V12: 14 | W12: 15 | X12: 16 | Y12: 17 | Z12: 18 | AA12: 19 | AB12: 20 | AC12: 21 | AD12: 22 | AE12: 23 | AF12: 24 | AG12: 25 | AH12: 26 | AI12: 27 | AJ12: 28 | AK12: 29 | AL12: 30 | AM12: 31 | AN12: 32 | AO12: 33 | AP12: 34 | AQ12: 35 | AR12: 36 | AS12: 37 | AT12: 38 | AU12: 39 | AV12: 40 | AW12: 41 | AX12: 42 | AY12: 43 | AZ12: 44 | BA12: 45 | BB12: 46 | BC12: 47 | BD12: 48 | BE12: 49 | BF12: 50 | BG12: 51 | BH12: 52 | BI12: 53 | BJ12: 54 | BK12: 55 | BL12: 56 | BM12: 57 | BN12: 58 | BO12: 59 | BP12: 60 | BQ12: 61 | BR12: 62 | BS12: 63 | BT12: 64 | BU12: 65 | BV12: 66 | BW12: 67 | BX12: 68 | BY12: 69 | BZ12: 70 | CA12: 71 | CB12: 72
B13: spi frequency | C13: 15 | D13: mhz | F13: spi thruput | G13: line | H13: # | I13: 1 | J13: 2 | K13: 3 | L13: 4 | M13: 5 | N13: 6 | O13: 7 | P13: 8 | Q13: 9 | R13: 10 | S13: 11 | T13: 12 | U13: 13 | V13: 14 | W13: 15 | X13: 16 | Y13: 17 | Z13: 18 | AA13: 19 | AB13: 20 | AC13: 21 | AD13: 22 | AE13: 23 | AF13: 24 | AG13: 1 | AH13: 2 | AI13: 3 | AJ13: 4 | AK13: 5 | AL13: 6 | AM13: 7 | AN13: 8 | AO13: 9 | AP13: 10 | AQ13: 11 | AR13: 12 | AS13: 13 | AT13: 14 | AU13: 15 | AV13: 16 | AW13: 17 | AX13: 18 | AY13: 19 | AZ13: 20 | BA13: 21 | BB13: 22 | BC13: 23 | BD13: 24 | BE13: 1 | BF13: 2 | BG13: 3 | BH13: 4 | BI13: 5 | BJ13: 6 | BK13: 7 | BL13: 8 | BM13: 9 | BN13: 10 | BO13: 11 | BP13: 12 | BQ13: 13 | BR13: 14 | BS13: 15 | BT13: 16 | BU13: 17 | BV13: 18 | BW13: 19 | BX13: 20 | BY13: 21 | BZ13: 22 | CA13: 23 | CB13: 24
B14: spi ld/blk | C14: 16 | D14: bit | F14: (burst size=24) | G14: transmit | H14: us | I14: =$C$15 + (16+$C$14*$C$17*(I13)) * (1/$C$13) -> 27.966667 | J14: =I14 + ($C$14*$C$17*(J13-I13))*(1/$C$13) -> 53.566667 | K14: =J14 + ($C$14*$C$17*(K13-J13))*(1/$C$13) -> 79.166667 | L14: =K14 + ($C$14*$C$17*(L13-K13))*(1/$C$13) -> 104.76667 | M14: =L14 + ($C$14*$C$17*(M13-L13))*(1/$C$13) -> 130.36667 | N14: =M14 + ($C$14*$C$17*(N13-M13))*(1/$C$13) -> 155.96667 | O14: =N14 + ($C$14*$C$17*(O13-N13))*(1/$C$13) -> 181.56667 | P14: =O14 + ($C$14*$C$17*(P13-O13))*(1/$C$13) -> 207.16667 | Q14: =P14 + ($C$14*$C$17*(Q13-P13))*(1/$C$13) -> 232.76667 | ... AF14: =AE14 + ($C$14*$C$17*(AF13-AE13))*(1/$C$13) -> 616.76667 | AG14: =AF14 + (C15+C16) + (16+$C$14*$C$17*(AG13))*(1/$C$13) -> 727.73333 | AH14: =AG14 + ($C$4*$C$7*(AH13-AG13))*(1/$C$3) -> 728.62222 | AI14: =AH14 + ($C$14*$C$17*(AI13-AH13))*(1/$C$13) -> 754.22222 | AJ14: =AI14 + ($C$14*$C$17*(AJ13-AI13))*(1/$C$13) -> 779.82222 | AK14: =AJ14 + ($C$14*$C$17*(AK13-AJ13))*(1/$C$13) -> 805.42222 | AL14: =AK14 + ($C$14*$C$17*(AL13-AK13))*(1/$C$13) -> 831.02222 | AM14: =AL14 + ($C$14*$C$17*(AM13-AL13))*(1/$C$13) -> 856.62222 | AN14: =AM14 + ($C$14*$C$17*(AN13-AM13))*(1/$C$13) -> 882.22222 | AO14: =AN14 + ($C$14*$C$17*(AO13-AN13))*(1/$C$13) -> 907.82222 | AP14: =AO14 + ($C$14*$C$17*(AP13-AO13))*(1/$C$13) -> 933.42222 | ... BD14: =BC14 + ($C$14*$C$17*(BD13-BC13))*(1/$C$13) -> 1291.8222 | BE14: =BD14 + (C15+C16) + (16+$C$14*$C$17*(BE13))*(1/$C$13) -> 1402.7889 | BF14: =BE14 + ($C$14*$C$17*(BF13-BE13))*(1/$C$13) -> 1428.3889 | BG14: =BF14 + ($C$14*$C$17*(BG13-BF13))*(1/$C$13) -> 1453.9889 | BH14: =BG14 + ($C$14*$C$17*(BH13-BG13))*(1/$C$13) -> 1479.5889 | BI14: =BH14 + ($C$14*$C$17*(BI13-BH13))*(1/$C$13) -> 1505.1889 | BJ14: =BI14 + ($C$14*$C$17*(BJ13-BI13))*(1/$C$13) -> 1530.7889 | BK14: =BJ14 + ($C$14*$C$17*(BK13-BJ13))*(1/$C$13) -> 1556.3889 | BL14: =BK14 + ($C$14*$C$17*(BL13-BK13))*(1/$C$13) -> 1581.9889 | BM14: =BL14 + ($C$14*$C$17*(BM13-BL13))*(1/$C$13) -> 1607.5889 | ... CB14: =CA14 + ($C$14*$C$17*(CB13-CA13))*(1/$C$13) -> 1991.5889
B15: spi latency1 | C15: 1.3 | D15: us | F15: ld serializing thruput | G15: block | H15: # | U15: 1 | V15: 2 | W15: 3 | X15: 4 | Y15: 5 | Z15: 6 | AA15: 7 | AB15: 8 | AC15: 9 | AD15: 10 | AE15: 11 | AF15: 12 | AG15: 13 | AH15: 14 | AI15: 15 | AJ15: 16 | AK15: 17 | AL15: 18 | AM15: 19 | AN15: 20 | AO15: 21 | AP15: 22 | AQ15: 23 | AR15: 24 | AS15: 25 | AT15: 26 | AU15: 27 | AV15: 28 | AW15: 29 | AX15: 30 | AY15: 31 | AZ15: 32 | BA15: 33 | BB15: 34 | BC15: 35 | BD15: 36 | BE15: 37 | BF15: 38 | BG15: 39 | BH15: 40 | BI15: 41 | BJ15: 42 | BK15: 43 | BL15: 44 | BM15: 45 | BN15: 46 | BO15: 47 | BP15: 48 | BQ15: 49 | BR15: 50 | BS15: 51 | BT15: 52 | BU15: 53 | BV15: 54 | BW15: 55 | BX15: 56 | BY15: 57 | BZ15: 58 | CA15: 59 | CB15: 60 | CC15: 61 | CD15: 62 | CE15: 63 | CF15: 64 | CG15: 65 | CH15: 66 | CI15: 67 | CJ15: 68 | CK15: 69 | CL15: 70 | CM15: 71 | CN15: 72
B16: spi latency2 | C16: =1.7+80+C15 -> 83 | D16: us | G16: transmit | H16: us | U16: =$T$14 + (4*ROUNDUP(U15/$C$18,0)+($C$14)*U15) /$C$19 -> 351.56667 | V16: =$T$14 + (4*ROUNDUP(V15/$C$18,0)+($C$14)*V15) /$C$19 -> 385.16667 | W16: =$T$14 + (4*ROUNDUP(W15/$C$18,0)+($C$14)*W15) /$C$19 -> 418.76667 | X16: =$T$14 + (4*ROUNDUP(X15/$C$18,0)+($C$14)*X15) /$C$19 -> 452.36667 | Y16: =$T$14 + (4*ROUNDUP(Y15/$C$18,0)+($C$14)*Y15) /$C$19 -> 485.96667 | Z16: =$T$14 + (4*ROUNDUP(Z15/$C$18,0)+($C$14)*Z15) /$C$19 -> 519.56667 | AA16: =$T$14 + (4*ROUNDUP(AA15/$C$18,0)+($C$14)*AA15) /$C$19 -> 553.16667 | AB16: =$T$14 + (4*ROUNDUP(AB15/$C$18,0)+($C$14)*AB15) /$C$19 -> 586.76667 | ... CN16: =$T$14 + (4*ROUNDUP(CN15/$C$18,0)+($C$14)*CN15) /$C$19 -> 2779.1667
B17: xc_ld_size | C17: 24 | D17: ea | F17: ld_transfer_start_point | G17: 12 | H17: ea
B18: xc_dev_ch_size | C18: 12 | D18: ea | F18: margin | G18: room t | H18: us | U18: =U16-I14 -> 323.6 | V18: =V16-J14 -> 331.6 | W18: =W16-K14 -> 339.6 | X18: =X16-L14 -> 347.6 | Y18: =Y16-M14 -> 355.6 | Z18: =Z16-N14 -> 363.6 | AA18: =AA16-O14 -> 371.6 | AB18: =AB16-P14 -> 379.6 | ... CN18: =CN16-CB14 -> 787.57778
B19: xc baudrate | C19: =1/2.1 -> 0.47619048 | D19: mbps | G19: room blk# | H19: ea | U19: =U18 / ( (16+$C$14*$C$17)*(1/$C$13) + $C$15 ) -> 11.570918 | V19: =V18 / ( (16+$C$14*$C$17)*(1/$C$13) + $C$15 ) -> 11.856973 | W19: =W18 / ( (16+$C$14*$C$17)*(1/$C$13) + $C$15 ) -> 12.143027 | X19: =X18 / ( (16+$C$14*$C$17)*(1/$C$13) + $C$15 ) -> 12.429082 | Y19: =Y18 / ( (16+$C$14*$C$17)*(1/$C$13) + $C$15 ) -> 12.715137 | Z19: =Z18 / ( (16+$C$14*$C$17)*(1/$C$13) + $C$15 ) -> 13.001192 | AA19: =AA18 / ( (16+$C$14*$C$17)*(1/$C$13) + $C$15 ) -> 13.287247 | AB19: =AB18 / ( (16+$C$14*$C$17)*(1/$C$13) + $C$15 ) -> 13.573302 | ... CN19: =CN18 / ( (16+$C$14*$C$17)*(1/$C$13) + $C$15 ) -> 28.161303
B23: main spi | C23: 2 | D23: mhz
C24: =1/C23 -> 0.5 | D24: us
B25: total blk# | C25: 720 | D25: ea
B26: data# | C26: 1 | D26: line | G26: =(C25/C26+1)*14*C24+2 -> 5049
B27: xc spi | C27: 15 | D27: mhz | G27: 72 | H27: ea
C28: =1/C27 -> 0.066666667 | D28: us | G28: =((16+16*24*24)*$C$28 + 2)*3 + 100*2 -> 2052.4 | H28: us | Q28: =16/2 -> 8
B29: xc mclk | C29: 10 | D29: mhz | G29: =G31-G28 -> 64.4 | Q29: =Q28*0.333333333333 -> 2.6666667 | R29: =Q28*0.666666666666 -> 5.3333333
C30: =1/C29 -> 0.1 | D30: us | Q30: 2 | R30: 6
B31: xc baudrate | C31: =1/(C30*(C32+D32)) -> 0.55555556 | D31: mbps | G31: =((4+16*12)*6)*(1/C31) -> 2116.8 | H31: us
B32: low/high | C32: 6 | D32: =C32*2 -> 12 | F32: =C40*C42/C30 -> 6.100126 | G32: =C40*D42/C30 -> 12.200252
B33: us | C33: =$C$30*C32 -> 0.6 | D33: =$C$30*D32 -> 1.2 | F33: =C33+D33 -> 1.8
B34: max frame
B36: target | C36: 120 | D36: hz
B39: xd mclk | C39: 39.34345 | D39: mhz
C40: =1/C39 -> 0.025417192 | D40: us
B41: xc baudrate | C41: =1/(C40*(C42+D42)) -> 0.5464368 | D41: mbps
B42: low/high | C42: 24 | D42: =C42*2 -> 48 | F42: =C30*C32/C40 -> 23.60607 | G42: =C30*D32/C40 -> 47.21214
B43: us | C43: =$C$40*C42 -> 0.6100126 | D43: =$C$40*D42 -> 1.2200252 | F43: =C43+D43 -> 1.8300378

Sheet ld_transfer_thruput (2)
G2: total line | H2: # | I2: 1 | J2: 2 | K2: 3 | L2: 4 | M2: 5 | N2: 6 | O2: 7 | P2: 8 | Q2: 9 | R2: 10 | S2: 11 | T2: 12 | U2: 13 | V2: 14 | W2: 15 | X2: 16 | Y2: 17 | Z2: 18 | AA2: 19 | AB2: 20 | AC2: 21 | AD2: 22 | AE2: 23 | AF2: 24 | AG2: 25 | AH2: 26 | AI2: 27 | AJ2: 28 | AK2: 29 | AL2: 30 | AM2: 31 | AN2: 32 | AO2: 33 | AP2: 34 | AQ2: 35 | AR2: 36 | AS2: 37 | AT2: 38 | AU2: 39 | AV2: 40 | AW2: 41 | AX2: 42 | AY2: 43 | AZ2: 44 | BA2: 45 | BB2: 46 | BC2: 47 | BD2: 48 | BE2: 49 | BF2: 50 | BG2: 51 | BH2: 52 | BI2: 53 | BJ2: 54 | BK2: 55 | BL2: 56 | BM2: 57 | BN2: 58 | BO2: 59 | BP2: 60 | BQ2: 61 | BR2: 62 | BS2: 63 | BT2: 64 | BU2: 65 | BV2: 66 | BW2: 67 | BX2: 68 | BY2: 69 | BZ2: 70 | CA2: 71 | CB2: 72
B3: spi frequency | C3: 15 | D3: mhz | F3: spi thruput | G3: line | H3: # | I3: 1 | J3: 2 | K3: 3 | L3: 4 | M3: 5 | N3: 6 | O3: 7 | P3: 8 | Q3: 9 | R3: 10 | S3: 11 | T3: 12 | U3: 13 | V3: 14 | W3: 15 | X3: 16 | Y3: 17 | Z3: 18 | AA3: 19 | AB3: 20 | AC3: 21 | AD3: 22 | AE3: 23 | AF3: 24 | AG3: 1 | AH3: 2 | AI3: 3 | AJ3: 4 | AK3: 5 | AL3: 6 | AM3: 7 | AN3: 8 | AO3: 9 | AP3: 10 | AQ3: 11 | AR3: 12 | AS3: 13 | AT3: 14 | AU3: 15 | AV3: 16 | AW3: 17 | AX3: 18 | AY3: 19 | AZ3: 20 | BA3: 21 | BB3: 22 | BC3: 23 | BD3: 24 | BE3: 1 | BF3: 2 | BG3: 3 | BH3: 4 | BI3: 5 | BJ3: 6 | BK3: 7 | BL3: 8 | BM3: 9 | BN3: 10 | BO3: 11 | BP3: 12 | BQ3: 13 | BR3: 14 | BS3: 15 | BT3: 16 | BU3: 17 | BV3: 18 | BW3: 19 | BX3: 20 | BY3: 21 | BZ3: 22 | CA3: 23 | CB3: 24
B4: spi ld/blk | C4: 16 | D4: bit | F4: (burst size=24) | G4: transmit | H4: us | I4: =$C$5 + (16+$C$4*$C$7*(I3)) * (1/$C$3) -> 27.966667 | J4: =I4 + ($C$4*$C$7*(J3-I3))*(1/$C$3) -> 53.566667 | K4: =J4 + ($C$4*$C$7*(K3-J3))*(1/$C$3) -> 79.166667 | L4: =K4 + ($C$4*$C$7*(L3-K3))*(1/$C$3) -> 104.76667 | M4: =L4 + ($C$4*$C$7*(M3-L3))*(1/$C$3) -> 130.36667 | N4: =M4 + ($C$4*$C$7*(N3-M3))*(1/$C$3) -> 155.96667 | O4: =N4 + ($C$4*$C$7*(O3-N3))*(1/$C$3) -> 181.56667 | P4: =O4 + ($C$4*$C$7*(P3-O3))*(1/$C$3) -> 207.16667 | Q4: =P4 + ($C$4*$C$7*(Q3-P3))*(1/$C$3) -> 232.76667 | ... AF4: =AE4 + ($C$4*$C$7*(AF3-AE3))*(1/$C$3) -> 616.76667 | AG4: =AF4 + (C5+C6) + (16+$C$4*$C$7*(AG3))*(1/$C$3) -> 727.73333 | AH4: =AG4 + ($C$4*$C$7*(AH3-AG3))*(1/$C$3) -> 753.33333 | AI4: =AH4 + ($C$4*$C$7*(AI3-AH3))*(1/$C$3) -> 778.93333 | AJ4: =AI4 + ($C$4*$C$7*(AJ3-AI3))*(1/$C$3) -> 804.53333 | AK4: =AJ4 + ($C$4*$C$7*(AK3-AJ3))*(1/$C$3) -> 830.13333 | AL4: =AK4 + ($C$4*$C$7*(AL3-AK3))*(1/$C$3) -> 855.73333 | AM4: =AL4 + ($C$4*$C$7*(AM3-AL3))*(1/$C$3) -> 881.33333 | AN4: =AM4 + ($C$4*$C$7*(AN3-AM3))*(1/$C$3) -> 906.93333 | AO4: =AN4 + ($C$4*$C$7*(AO3-AN3))*(1/$C$3) -> 932.53333 | ... BD4: =BC4 + ($C$4*$C$7*(BD3-BC3))*(1/$C$3) -> 1316.5333 | BE4: =BD4 + (C5+C6) + (16+$C$4*$C$7*(BE3))*(1/$C$3) -> 1427.5 | BF4: =BE4 + ($C$4*$C$7*(BF3-BE3))*(1/$C$3) -> 1453.1 | BG4: =BF4 + ($C$4*$C$7*(BG3-BF3))*(1/$C$3) -> 1478.7 | BH4: =BG4 + ($C$4*$C$7*(BH3-BG3))*(1/$C$3) -> 1504.3 | BI4: =BH4 + ($C$4*$C$7*(BI3-BH3))*(1/$C$3) -> 1529.9 | BJ4: =BI4 + ($C$4*$C$7*(BJ3-BI3))*(1/$C$3) -> 1555.5 | BK4: =BJ4 + ($C$4*$C$7*(BK3-BJ3))*(1/$C$3) -> 1581.1 | BL4: =BK4 + ($C$4*$C$7*(BL3-BK3))*(1/$C$3) -> 1606.7 | BM4: =BL4 + ($C$4*$C$7*(BM3-BL3))*(1/$C$3) -> 1632.3 | ... CB4: =CA4 + ($C$4*$C$7*(CB3-CA3))*(1/$C$3) -> 2016.3
B5: spi latency1 | C5: =1.3 -> 1.3 | D5: us | F5: ld serializing thruput | G5: block | H5: # | U5: 1 | V5: 2 | W5: 3 | X5: 4 | Y5: 5 | Z5: 6 | AA5: 7 | AB5: 8 | AC5: 9 | AD5: 10 | AE5: 11 | AF5: 12 | AG5: 13 | AH5: 14 | AI5: 15 | AJ5: 16 | AK5: 17 | AL5: 18 | AM5: 19 | AN5: 20 | AO5: 21 | AP5: 22 | AQ5: 23 | AR5: 24 | AS5: 25 | AT5: 26 | AU5: 27 | AV5: 28 | AW5: 29 | AX5: 30 | AY5: 31 | AZ5: 32 | BA5: 33 | BB5: 34 | BC5: 35 | BD5: 36 | BE5: 37 | BF5: 38 | BG5: 39 | BH5: 40 | BI5: 41 | BJ5: 42 | BK5: 43 | BL5: 44 | BM5: 45 | BN5: 46 | BO5: 47 | BP5: 48 | BQ5: 49 | BR5: 50 | BS5: 51 | BT5: 52 | BU5: 53 | BV5: 54 | BW5: 55 | BX5: 56 | BY5: 57 | BZ5: 58 | CA5: 59 | CB5: 60 | CC5: 61 | CD5: 62 | CE5: 63 | CF5: 64 | CG5: 65 | CH5: 66 | CI5: 67 | CJ5: 68 | CK5: 69 | CL5: 70 | CM5: 71 | CN5: 72
B6: spi latency2 | C6: =1.7+80+C5 -> 83 | D6: us | G6: transmit | H6: us | U6: =$T$4 + (4*ROUNDUP(U5/$C$8,0)+($C$4)*U5) /$C$9 -> 351.56667 | V6: =$T$4 + (4*ROUNDUP(V5/$C$8,0)+($C$4)*V5) /$C$9 -> 385.16667 | W6: =$T$4 + (4*ROUNDUP(W5/$C$8,0)+($C$4)*W5) /$C$9 -> 418.76667 | X6: =$T$4 + (4*ROUNDUP(X5/$C$8,0)+($C$4)*X5) /$C$9 -> 452.36667 | Y6: =$T$4 + (4*ROUNDUP(Y5/$C$8,0)+($C$4)*Y5) /$C$9 -> 485.96667 | Z6: =$T$4 + (4*ROUNDUP(Z5/$C$8,0)+($C$4)*Z5) /$C$9 -> 519.56667 | AA6: =$T$4 + (4*ROUNDUP(AA5/$C$8,0)+($C$4)*AA5) /$C$9 -> 553.16667 | AB6: =$T$4 + (4*ROUNDUP(AB5/$C$8,0)+($C$4)*AB5) /$C$9 -> 586.76667 | ... CN6: =$T$4 + (4*ROUNDUP(CN5/$C$8,0)+($C$4)*CN5) /$C$9 -> 2779.1667
B7: xc_ld_size | C7: 24 | D7: ea | F7: ld_transfer_start_point | G7: 12 | H7: ea
B8: xc_dev_ch_size | C8: 12 | D8: ea
B9: xc baudrate | C9: =1/2.1 -> 0.47619048 | D9: mbps | F9: margin | G9: room blk# | H9: ea | BQ9: =CA2-BQ5 -> 22 | BR9: =$CB$2-BR5 -> 22 | BS9: =$CB$2-BS5 -> 21 | BT9: =$CB$2-BT5 -> 20 | BU9: =$CB$2-BU5 -> 19 | BV9: =$CB$2-BV5 -> 18 | BW9: =$CB$2-BW5 -> 17 | BX9: =$CB$2-BX5 -> 16 | BY9: =$CB$2-BY5 -> 15 | ... CN9: =$CB$2-CN5 -> 0
G12: total line | H12: # | I12: 1 | J12: 2 | K12: 3 | L12: 4 | M12: 5 | N12: 6 | O12: 7 | P12: 8 | Q12: 9 | R12: 10 | S12: 11 | T12: 12 | U12: 13 | V12: 14 | W12: 15 | X12: 16 | Y12: 17 | Z12: 18 | AA12: 19 | AB12: 20 | AC12: 21 | AD12: 22 | AE12: 23 | AF12: 24 | AG12: 25 | AH12: 26 | AI12: 27 | AJ12: 28 | AK12: 29 | AL12: 30 | AM12: 31 | AN12: 32 | AO12: 33 | AP12: 34 | AQ12: 35 | AR12: 36 | AS12: 37 | AT12: 38 | AU12: 39 | AV12: 40 | AW12: 41 | AX12: 42 | AY12: 43 | AZ12: 44 | BA12: 45 | BB12: 46 | BC12: 47 | BD12: 48 | BE12: 49 | BF12: 50 | BG12: 51 | BH12: 52 | BI12: 53 | BJ12: 54 | BK12: 55 | BL12: 56 | BM12: 57 | BN12: 58 | BO12: 59 | BP12: 60 | BQ12: 61 | BR12: 62 | BS12: 63 | BT12: 64 | BU12: 65 | BV12: 66 | BW12: 67 | BX12: 68 | BY12: 69 | BZ12: 70 | CA12: 71 | CB12: 72
B13: spi frequency | C13: 15 | D13: mhz | F13: spi thruput | G13: line | H13: # | I13: 1 | J13: 2 | K13: 3 | L13: 4 | M13: 5 | N13: 6 | O13: 7 | P13: 8 | Q13: 9 | R13: 10 | S13: 11 | T13: 12 | U13: 13 | V13: 14 | W13: 15 | X13: 16 | Y13: 17 | Z13: 18 | AA13: 19 | AB13: 20 | AC13: 21 | AD13: 22 | AE13: 23 | AF13: 24 | AG13: 1 | AH13: 2 | AI13: 3 | AJ13: 4 | AK13: 5 | AL13: 6 | AM13: 7 | AN13: 8 | AO13: 9 | AP13: 10 | AQ13: 11 | AR13: 12 | AS13: 13 | AT13: 14 | AU13: 15 | AV13: 16 | AW13: 17 | AX13: 18 | AY13: 19 | AZ13: 20 | BA13: 21 | BB13: 22 | BC13: 23 | BD13: 24 | BE13: 1 | BF13: 2 | BG13: 3 | BH13: 4 | BI13: 5 | BJ13: 6 | BK13: 7 | BL13: 8 | BM13: 9 | BN13: 10 | BO13: 11 | BP13: 12 | BQ13: 13 | BR13: 14 | BS13: 15 | BT13: 16 | BU13: 17 | BV13: 18 | BW13: 19 | BX13: 20 | BY13: 21 | BZ13: 22 | CA13: 23 | CB13: 24
B14: spi ld/blk | C14: 16 | D14: bit | F14: (burst size=24) | G14: transmit | H14: us | I14: =$C$15 + (16+$C$14*$C$17*(I13)) * (1/$C$13) -> 27.966667 | J14: =I14 + ($C$14*$C$17*(J13-I13))*(1/$C$13) -> 53.566667 | K14: =J14 + ($C$14*$C$17*(K13-J13))*(1/$C$13) -> 79.166667 | L14: =K14 + ($C$14*$C$17*(L13-K13))*(1/$C$13) -> 104.76667 | M14: =L14 + ($C$14*$C$17*(M13-L13))*(1/$C$13) -> 130.36667 | N14: =M14 + ($C$14*$C$17*(N13-M13))*(1/$C$13) -> 155.96667 | O14: =N14 + ($C$14*$C$17*(O13-N13))*(1/$C$13) -> 181.56667 | P14: =O14 + ($C$14*$C$17*(P13-O13))*(1/$C$13) -> 207.16667 | Q14: =P14 + ($C$14*$C$17*(Q13-P13))*(1/$C$13) -> 232.76667 | ... AF14: =AE14 + ($C$14*$C$17*(AF13-AE13))*(1/$C$13) -> 616.76667 | AG14: =AF14 + (C15+C16) + (16+$C$14*$C$17*(AG13))*(1/$C$13) -> 727.73333 | AH14: =AG14 + ($C$4*$C$7*(AH13-AG13))*(1/$C$3) -> 753.33333 | AI14: =AH14 + ($C$14*$C$17*(AI13-AH13))*(1/$C$13) -> 778.93333 | AJ14: =AI14 + ($C$14*$C$17*(AJ13-AI13))*(1/$C$13) -> 804.53333 | AK14: =AJ14 + ($C$14*$C$17*(AK13-AJ13))*(1/$C$13) -> 830.13333 | AL14: =AK14 + ($C$14*$C$17*(AL13-AK13))*(1/$C$13) -> 855.73333 | AM14: =AL14 + ($C$14*$C$17*(AM13-AL13))*(1/$C$13) -> 881.33333 | AN14: =AM14 + ($C$14*$C$17*(AN13-AM13))*(1/$C$13) -> 906.93333 | AO14: =AN14 + ($C$14*$C$17*(AO13-AN13))*(1/$C$13) -> 932.53333 | AP14: =AO14 + ($C$14*$C$17*(AP13-AO13))*(1/$C$13) -> 958.13333 | ... BD14: =BC14 + ($C$14*$C$17*(BD13-BC13))*(1/$C$13) -> 1316.5333 | BE14: =BD14 + (C15+C16) + (16+$C$14*$C$17*(BE13))*(1/$C$13) -> 1427.5 | BF14: =BE14 + ($C$14*$C$17*(BF13-BE13))*(1/$C$13) -> 1453.1 | BG14: =BF14 + ($C$14*$C$17*(BG13-BF13))*(1/$C$13) -> 1478.7 | BH14: =BG14 + ($C$14*$C$17*(BH13-BG13))*(1/$C$13) -> 1504.3 | BI14: =BH14 + ($C$14*$C$17*(BI13-BH13))*(1/$C$13) -> 1529.9 | BJ14: =BI14 + ($C$14*$C$17*(BJ13-BI13))*(1/$C$13) -> 1555.5 | BK14: =BJ14 + ($C$14*$C$17*(BK13-BJ13))*(1/$C$13) -> 1581.1 | BL14: =BK14 + ($C$14*$C$17*(BL13-BK13))*(1/$C$13) -> 1606.7 | BM14: =BL14 + ($C$14*$C$17*(BM13-BL13))*(1/$C$13) -> 1632.3 | ... CB14: =CA14 + ($C$14*$C$17*(CB13-CA13))*(1/$C$13) -> 2016.3
B15: spi latency1 | C15: 1.3 | D15: us | F15: ld serializing thruput | G15: block | H15: # | U15: 1 | V15: 2 | W15: 3 | X15: 4 | Y15: 5 | Z15: 6 | AA15: 7 | AB15: 8 | AC15: 9 | AD15: 10 | AE15: 11 | AF15: 12 | AG15: 13 | AH15: 14 | AI15: 15 | AJ15: 16 | AK15: 17 | AL15: 18 | AM15: 19 | AN15: 20 | AO15: 21 | AP15: 22 | AQ15: 23 | AR15: 24 | AS15: 25 | AT15: 26 | AU15: 27 | AV15: 28 | AW15: 29 | AX15: 30 | AY15: 31 | AZ15: 32 | BA15: 33 | BB15: 34 | BC15: 35 | BD15: 36 | BE15: 37 | BF15: 38 | BG15: 39 | BH15: 40 | BI15: 41 | BJ15: 42 | BK15: 43 | BL15: 44 | BM15: 45 | BN15: 46 | BO15: 47 | BP15: 48 | BQ15: 49 | BR15: 50 | BS15: 51 | BT15: 52 | BU15: 53 | BV15: 54 | BW15: 55 | BX15: 56 | BY15: 57 | BZ15: 58 | CA15: 59 | CB15: 60 | CC15: 61 | CD15: 62 | CE15: 63 | CF15: 64 | CG15: 65 | CH15: 66 | CI15: 67 | CJ15: 68 | CK15: 69 | CL15: 70 | CM15: 71 | CN15: 72
B16: spi latency2 | C16: =1.7+80+C15 -> 83 | D16: us | G16: transmit | H16: us | U16: =$T$14 + (4*ROUNDUP(U15/$C$18,0)+($C$14)*U15) /$C$19 -> 345.56667 | V16: =$T$14 + (4*ROUNDUP(V15/$C$18,0)+($C$14)*V15) /$C$19 -> 374.36667 | W16: =$T$14 + (4*ROUNDUP(W15/$C$18,0)+($C$14)*W15) /$C$19 -> 403.16667 | X16: =$T$14 + (4*ROUNDUP(X15/$C$18,0)+($C$14)*X15) /$C$19 -> 431.96667 | Y16: =$T$14 + (4*ROUNDUP(Y15/$C$18,0)+($C$14)*Y15) /$C$19 -> 460.76667 | Z16: =$T$14 + (4*ROUNDUP(Z15/$C$18,0)+($C$14)*Z15) /$C$19 -> 489.56667 | AA16: =$T$14 + (4*ROUNDUP(AA15/$C$18,0)+($C$14)*AA15) /$C$19 -> 518.36667 | AB16: =$T$14 + (4*ROUNDUP(AB15/$C$18,0)+($C$14)*AB15) /$C$19 -> 547.16667 | ... CN16: =$T$14 + (4*ROUNDUP(CN15/$C$18,0)+($C$14)*CN15) /$C$19 -> 2426.3667
B17: xc_ld_size | C17: 24 | D17: ea | F17: ld_transfer_start_point | G17: 12 | H17: ea
B18: xc_dev_ch_size | C18: 12 | D18: ea
B19: xc baudrate | C19: =1/1.8 -> 0.55555556 | D19: mbps | F19: margin | G19: room blk# | H19: ea | BZ19: =$CB$12-BZ15 -> 14 | CA19: =$CB$12-CA15 -> 13 | CB19: =$CB$12-CB15 -> 12 | CC19: =$CB$12-CC15 -> 11 | CD19: =$CB$12-CD15 -> 10 | CE19: =$CB$12-CE15 -> 9 | CF19: =$CB$12-CF15 -> 8 | CG19: =$CB$12-CG15 -> 7 | ... CN19: =$CB$12-CN15 -> 0
B23: main spi | C23: 2 | D23: mhz
C24: =1/C23 -> 0.5 | D24: us
B25: total blk# | C25: 720 | D25: ea
B26: data# | C26: 1 | D26: line | G26: =(C25/C26+1)*14*C24+2 -> 5049
B27: xc spi | C27: 15 | D27: mhz | G27: 72 | H27: ea
C28: =1/C27 -> 0.066666667 | D28: us | G28: =((16+16*24*24)*$C$28 + 2)*3 + 100*2 -> 2052.4 | H28: us
B29: xc mclk | C29: 10 | D29: mhz | G29: =G31-G28 -> 64.4
C30: =1/C29 -> 0.1 | D30: us
B31: xc baudrate | C31: =1/(C30*(C32+D32)) -> 0.55555556 | D31: mbps | G31: =((4+16*12)*6)*(1/C31) -> 2116.8 | H31: us
B32: low/high | C32: 6 | D32: =C32*2 -> 12 | F32: =C40*C42/C30 -> 6.100126 | G32: =C40*D42/C30 -> 12.200252
B33: us | C33: =$C$30*C32 -> 0.6 | D33: =$C$30*D32 -> 1.2 | F33: =C33+D33 -> 1.8
B34: max frame
B36: target | C36: 120 | D36: hz
B39: xd mclk | C39: 39.34345 | D39: mhz
C40: =1/C39 -> 0.025417192 | D40: us
B41: xc baudrate | C41: =1/(C40*(C42+D42)) -> 0.5464368 | D41: mbps
B42: low/high | C42: 24 | D42: =C42*2 -> 48 | F42: =C30*C32/C40 -> 23.60607 | G42: =C30*D32/C40 -> 47.21214
B43: us | C43: =$C$40*C42 -> 0.6100126 | D43: =$C$40*D42 -> 1.2200252 | F43: =C43+D43 -> 1.8300378

Sheet qn90f_spec_summary (2)
B2: model | C2: total block | F2: led# | G2: blu# | H2: blk# | I2: blu layout | K2: blk layout/blu | N2: xd#/blu | P2: d# | R2: xd#/d | T2: jumper | U2: curr | V2: curr | W2: curr | X2: watt
C3: hor | D3: ver | E3: total | F3: led#/blk | G3: /set | H3: /blu | I3: hor | J3: ver | K3: hor | L3: ver | M3: total | N3: xd ch# | O3: 8 | P3: /blu | Q3: total | T3: /blu | U3: /blu | V3: /finger | W3: total | X3: /xd
B4: 55" | G4: 6 | H4: =E4/G4 -> 0 | I4: 3 | J4: =$G$4/I4 -> 2 | K4: =$C$4/I4 -> 0 | L4: =$D$4/J4 -> 0 | M4: =K4*L4 -> 0 | N4: =M4/$O$3 -> 0 | O4: =ROUNDUP(N4,0) -> 0 | Q4: =G4*P4 -> 0 | R4: =O4/P4 -> #DIV/0! | S4: =ROUNDUP(R4,0) -> #DIV/0! | U4: =E11*M4 -> 0 | V4: =U4/L4 -> #DIV/0! | W4: =U4*G4 -> 0 | X4: =G11*$O$3 -> 207.52
B5: 65" | C5: 40 | D5: 18 | E5: =C5*D5 -> 720 | G5: 8 | H5: =E5/G5 -> 90 | I5: 4 | J5: =$G$5/I5 -> 2 | K5: =$C$5/I5 -> 10 | L5: =$D$5/J5 -> 9 | M5: =K5*L5 -> 90 | N5: =M5/$O$3 -> 11.25 | O5: =ROUNDUP(N5,0) -> 12 | P5: 2 | Q5: =G5*P5 -> 16 | R5: =O5/P5 -> 6 | S5: =ROUNDUP(R5,0) -> 6 | U5: =E12*M5 -> 2364.3 | V5: =U5/L5 -> 262.7 | W5: =U5*G5 -> 18914.4 | X5: =G12*$O$3 -> 210.16
B6: 75" | G6: 10 | H6: =E6/G6 -> 0 | I6: 5 | J6: =$G$6/I6 -> 2 | K6: =$C$6/I6 -> 0 | L6: =$D$6/J6 -> 0 | M6: =K6*L6 -> 0 | N6: =M6/$O$3 -> 0 | O6: =ROUNDUP(N6,0) -> 0 | Q6: =G6*P6 -> 0 | R6: =O6/P6 -> #DIV/0! | S6: =ROUNDUP(R6,0) -> #DIV/0! | U6: =E13*M6 -> 0 | V6: =U6/L6 -> #DIV/0! | W6: =U6*G6 -> 0 | X6: =G13*$O$3 -> 214.72
B7: 85" | G7: 12 | H7: =E7/G7 -> 0 | I7: 6 | J7: =$G$7/I7 -> 2 | K7: =$C$7/I7 -> 0 | L7: =$D$7/J7 -> 0 | M7: =K7*L7 -> 0 | N7: =M7/$O$3 -> 0 | O7: =ROUNDUP(N7,0) -> 0 | Q7: =G7*P7 -> 0 | R7: =O7/P7 -> #DIV/0! | S7: =ROUNDUP(R7,0) -> #DIV/0! | U7: =E14*M7 -> 0 | V7: =U7/L7 -> #DIV/0! | W7: =U7*G7 -> 0 | X7: =G14*$O$3 -> 222.08
B9: model | C9: current [mA] | F9: ana | H9: curr/ana | I9: curr/vref | K9: ana | L9: vref | M9: ana | N9: vref | O9: gap_vref
C10: normal | D10: peak | E10: swing | F10: 0 | G10: 1023 | J10: 4095 | K10: 0 | M10: 1023 | Q10: vref/ana
B11: 55" | C11: 6.83 | D11: 18.58 | E11: 25.94 | F11: =C11*0.7 -> 4.781 | G11: =E11 -> 25.94 | H11: =(G11-F11)/1023 -> 0.020683284 | I11: 32 | J11: =I11/$J$10 -> 0.0078144078 | K11: =( (G11-F11)/1023 )*$K$10 + F11 -> 4.781 | L11: =K11/J11 -> 611.81859 | M11: =( (G11-F11)/1023 )*$M$10 + F11 -> 25.94 | N11: =M11/J11 -> 3319.5094 | O11: =N11-L11 -> 2707.6908 | P11: =MROUND(N11,1)-MROUND(L11,1) -> 2708 | Q11: =O11/$G$10 -> 2.6468141
B12: 65" | C12: 6.91 | D12: 18.81 | E12: 26.27 | F12: =C12*0.7 -> 4.837 | G12: =E12 -> 26.27 | H12: =(G12-F12)/1023 -> 0.020951124 | I12: 32 | J12: =I12/$J$10 -> 0.0078144078 | K12: =( (G12-F12)/1023 )*$K$10 + F12 -> 4.837 | L12: =K12/J12 -> 618.98484 | M12: =( (G12-F12)/1023 )*$M$10 + F12 -> 26.27 | N12: =M12/J12 -> 3361.7391 | O12: =N12-L12 -> 2742.7542 | P12: =MROUND(N12,1)-MROUND(L12,1) -> 2743 | Q12: =O12/$G$10 -> 2.6810892
B13: 75" | C13: 7.04 | D13: 19.21 | E13: 26.84 | F13: =C13*0.7 -> 4.928 | G13: =E13 -> 26.84 | H13: =(G13-F13)/1023 -> 0.021419355 | I13: 32 | J13: =I13/$J$10 -> 0.0078144078 | K13: =( (G13-F13)/1023 )*$K$10 + F13 -> 4.928 | L13: =K13/J13 -> 630.63 | M13: =( (G13-F13)/1023 )*$M$10 + F13 -> 26.84 | N13: =M13/J13 -> 3434.6813 | O13: =N13-L13 -> 2804.0512 | P13: =MROUND(N13,1)-MROUND(L13,1) -> 2804 | Q13: =O13/$G$10 -> 2.7410081
B14: 85" | C14: 7.26 | D14: 19.84 | E14: 27.76 | F14: =C14*0.7 -> 5.082 | G14: =E14 -> 27.76 | H14: =(G14-F14)/1023 -> 0.022168133 | I14: 32 | J14: =I14/$J$10 -> 0.0078144078 | K14: =( (G14-F14)/1023 )*$K$10 + F14 -> 5.082 | L14: =K14/J14 -> 650.33719 | M14: =( (G14-F14)/1023 )*$M$10 + F14 -> 27.76 | N14: =M14/J14 -> 3552.4125 | O14: =N14-L14 -> 2902.0753 | P14: =MROUND(N14,1)-MROUND(L14,1) -> 2902 | Q14: =O14/$G$10 -> 2.8368283
B18: main spi | C18: 2 | D18: mhz
C19: =1/C18 -> 0.5 | D19: us
B20: total blk# | C20: =720 -> 720 | D20: ea
B21: data# | C21: 1 | D21: line | F21: =(E4/$C$21+1)*14*$C$19+2 -> 9 | G21: =(C20/$C$21+1)*14*$C$19+2 -> 5049 | H21: =(E6/$C$21+1)*14*$C$19+2 -> 9 | I21: =(E7/$C$21+1)*14*$C$19+2 -> 9
B22: xc spi | C22: 15 | D22: mhz | G22: 72 | H22: 12
C23: =1/C22 -> 0.066666667 | D23: us | G23: =((16+16*24*24)*$C$23 + 2)*3 + 100*2 -> 2052.4 | H23: =(16+16*16*H22)*$C$23 + 2 -> 207.86667
B24: xc mclk | C24: 10 | D24: mhz | H24: =G23-G26 -> -64.4 | I24: =G26+H23 -> 2324.6667
C25: =1/C24 -> 0.1 | D25: us
B26: xc baudrate | C26: =1/(C25*(C27+D27)) -> 0.55555556 | D26: mbps | G26: =((4+16*12)*6)*(1/$C$26) -> 2116.8
B27: low/high | C27: 6 | D27: =C27*2 -> 12 | F27: =C35*C37/C25 -> 6.100126 | G27: =C35*D37/C25 -> 12.200252
B28: us | C28: =$C$25*C27 -> 0.6 | D28: =$C$25*D27 -> 1.2 | E28: =C28+D28 -> 1.8
B29: max frame | G29: =(G21+G23+G26)/1000 -> 9.2182
G30: =1/G29*1000 -> 108.48105
B31: target | C31: 120 | D31: hz | E31: margin | G31: =G30-$C$31 -> -11.518952
B34: xd mclk | C34: 39.34345 | D34: mhz
C35: =1/C34 -> 0.025417192 | D35: us
B36: xc baudrate | C36: =1/(C35*(C37+D37)) -> 0.5464368 | D36: mbps
B37: low/high | C37: 24 | D37: =C37*2 -> 48 | F37: =C25*C27/C35 -> 23.60607 | G37: =C25*D27/C35 -> 47.21214
B38: us | C38: =$C$35*C37 -> 0.6100126 | D38: =$C$35*D37 -> 1.2200252 | E38: =C38+D38 -> 1.8300378

Sheet mclk_variable
E1: pwm(max) | L1: pwm(typ)
B2: XD | C2: BDIO to BDDIO delay | D2: ns | E2: 8.881 | L2: 4.776 | M2: =L2/E2 -> 0.53777728
C3: BDDIO to BDIO delay | D3: ns | E3: 9.316 | L3: 5.011 | M3: =L3/E3 -> 0.5378918
C5: BDIO to BDDIO skew | E5: high | F5: low | H5: high | I5: low | L5: high | M5: low | O5: high | P5: low
C6: #1 dio | D6: ns | E6: 406.8 | F6: 203.4 | G6: =SUM(E6:F6) -> 610.2 | H6: 203.4 | I6: 406.8 | J6: =SUM(H6:I6) -> 610.2 | L6: 406.8 | M6: 203.4 | N6: =SUM(L6:M6) -> 610.2 | O6: 203.4 | P6: 406.8 | Q6: =SUM(O6:P6) -> 610.2 | T6: proper baudrate according daisy # and mclk
C7: #1 ddio | D7: ns | E7: 404.275 | F7: 205.925 | G7: =SUM(E7:F7) -> 610.2 | H7: 200.875 | I7: 409.325 | J7: =SUM(H7:I7) -> 610.2 | L7: 405.353 | M7: 204.847 | N7: =SUM(L7:M7) -> 610.2 | O7: 201.953 | P7: 408.247 | Q7: =SUM(O7:P7) -> 610.2 | W7: downstream | AC7: upstream
C8: #1 skew | D8: ns | E8: =E7-E6 -> -2.525 | F8: =F7-F6 -> 2.525 | G8: =G7-G6 -> 0 | H8: =H7-H6 -> -2.525 | I8: =I7-I6 -> 2.525 | J8: =J7-J6 -> 0 | L8: =L7-L6 -> -1.447 | M8: =M7-M6 -> 1.447 | N8: =N7-N6 -> 0 | O8: =O7-O6 -> -1.447 | P8: =P7-P6 -> 1.447 | Q8: =Q7-Q6 -> 0 | T8: xc mclk | U8: 16 | V8: mhz | W8: daisy | X8: # | Y8: 31 | Z8: ea | AC8: daisy | AD8: # | AE8: 31 | AF8: ea
U9: 0 | V9: dev | W9: skew/dev | X9: s high | Y9: -2.525 | Z9: ns | AC9: skew/dev | AD9: s high | AE9: -2.248 | AF9: ns
C10: #31 total delay | D10: ns | E10: =E2*(31-1) -> 266.43 | L10: =L2*(31-1) -> 143.28 | U10: =U8+U8*U9 -> 16 | V10: mhz | X10: s low | Y10: =-Y9 -> 2.525 | Z10: ns | AD10: s low | AE10: =-AE9 -> 2.248 | AF10: ns
C11: #31 dio | D11: ns | E11: 331.05 | F11: 279.15 | G11: =SUM(E11:F11) -> 610.2 | H11: 127.65 | I11: 482.55 | J11: =SUM(H11:I11) -> 610.2 | L11: 363.39 | M11: 246.81 | N11: =SUM(L11:M11) -> 610.2 | O11: 159.99 | P11: 450.21 | Q11: =SUM(O11:P11) -> 610.2 | U11: =1/U10*1000 -> 62.5 | V11: ns | W11: total skew | X11: s high | Y11: =Y9*(W16-1) -> -75.75 | Z11: ns | AC11: total skew | AD11: s high | AE11: =AE9*(AC16-1) -> -67.44 | AF11: ns
C12: #31 skew | D12: ns | E12: =E8*(31-1) -> -75.75 | F12: =F8*(31-1) -> 75.75 | G12: =G8*(31-1) -> 0 | H12: =H8*(31-1) -> -75.75 | I12: =I8*(31-1) -> 75.75 | J12: =J8*(31-1) -> 0 | L12: =L8*(31-1) -> -43.41 | M12: =M8*(31-1) -> 43.41 | N12: =N8*(31-1) -> 0 | O12: =O8*(31-1) -> -43.41 | P12: =P8*(31-1) -> 43.41 | Q12: =Q8*(31-1) -> 0 | T12: high# | U12: 3 | V12: ea | X12: s low | Y12: =Y10*(W16-1) -> 75.75 | Z12: ns | AD12: s low | AE12: =AE10*(AC16-1) -> 67.44 | AF12: ns
T13: low# | U13: 6 | V13: ea | X13: logic 1 | Z13: logic 0 | AD13: logic 1 | AF13: logic 0
C14: BDDIO to BDIO skew | D14: ns | E14: high | F14: low | H14: high | I14: low | L14: high | M14: low | O14: high | P14: low | T14: baudrate | U14: =U11*(U12+U13) -> 562.5 | V14: ns | W14: 1 | X14: s high | Y14: =U11*U12 -> 187.5 | Z14: ns | AA14: =Y15 -> 375 | AB14: ns | AC14: 1 | AD14: s high | AE14: =U20*U21 -> 508.65735 | AF14: ns | AG14: =AE15 -> 254.32867 | AH14: ns
C15: #30 ddio | D15: ns | E15: 361.052 | F15: 184.468 | G15: =SUM(E15:F15) -> 545.52 | H15: 179.212 | I15: 366.308 | J15: =SUM(H15:I15) -> 545.52 | L15: 362.124 | M15: 183.396 | N15: =SUM(L15:M15) -> 545.52 | O15: 180.284 | P15: 365.236 | Q15: =SUM(O15:P15) -> 545.52 | U15: =1/U14*1000 -> 1.7777778 | V15: mbps | X15: s low | Y15: =U11*U13 -> 375 | Z15: ns | AA15: =Y14 -> 187.5 | AB15: ns | AD15: s low | AE15: =U20*U22 -> 254.32867 | AF15: ns | AG15: =AE14 -> 508.65735 | AH15: ns
C16: #30 dio | D16: ns | E16: 358.804 | F16: 186.716 | G16: =SUM(E16:F16) -> 545.52 | H16: 176.964 | I16: 368.556 | J16: =SUM(H16:I16) -> 545.52 | L16: 360.791 | M16: 184.729 | N16: =SUM(L16:M16) -> 545.52 | O16: 178.951 | P16: 366.569 | Q16: =SUM(O16:P16) -> 545.52 | W16: =Y8 -> 31 | X16: s high | Y16: =Y14+Y11 -> 111.75 | Z16: ns | AA16: =AA14+Y11 -> 299.25 | AB16: ns | AC16: =AE8 -> 31 | AD16: s high | AE16: =AE14+AE11 -> 441.21735 | AF16: ns | AG16: =AG14+AE11 -> 186.88867 | AH16: ns
C17: #30 skew | D17: ns | E17: =E16-E15 -> -2.248 | F17: =F16-F15 -> 2.248 | G17: =G16-G15 -> 0 | H17: =H16-H15 -> -2.248 | I17: =I16-I15 -> 2.248 | J17: =J16-J15 -> 0 | L17: =L16-L15 -> -1.333 | M17: =M16-M15 -> 1.333 | N17: =N16-N15 -> 0 | O17: =O16-O15 -> -1.333 | P17: =P16-P15 -> 1.333 | Q17: =Q16-Q15 -> 0 | T17: xd mclk | U17: 39.3192 | V17: mhz | X17: s low | Y17: =Y15+Y12 -> 450.75 | Z17: ns | AA17: =AA15+Y12 -> 263.25 | AB17: ns | AD17: s low | AE17: =AE15+AE12 -> 321.76867 | AF17: ns | AG17: =AG15+AE12 -> 576.09735 | AH17: ns
U18: 0 | V18: dev | W18: spl#@last dev | X18: logic 1 | Z18: logic 0 | AC18: spl#@last dev | AD18: logic 1 | AF18: logic 0
C19: #1 delay | D19: ns | E19: =E3*(31-1) -> 279.48 | L19: =L3*(31-1) -> 150.33 | U19: =U17+U17*U18 -> 39.3192 | V19: mhz | X19: high# | Y19: =Y16/$U$20 -> 4.3939206 | Z19: ea | AA19: =AA16/$U$20 -> 11.766271 | AB19: ea | AD19: high# | AE19: =AE16/$U$11 -> 7.0594776 | AF19: ea | AG19: =AG16/$U$11 -> 2.9902188 | AH19: ea
C20: #1 dio | D20: ns | E20: 293.612 | F20: 251.908 | G20: =SUM(E20:F20) -> 545.52 | H20: 111.772 | I20: 433.748 | J20: =SUM(H20:I20) -> 545.52 | L20: 322.134 | M20: 223.386 | N20: =SUM(L20:M20) -> 545.52 | O20: 140.294 | P20: 405.226 | Q20: =SUM(O20:P20) -> 545.52 | U20: =1/U19*1000 -> 25.432867 | V20: ns | X20: low# | Y20: =Y17/$U$20 -> 17.723129 | Z20: ea | AA20: =AA17/$U$20 -> 10.350779 | AB20: ea | AD20: low# | AE20: =AE17/$U$11 -> 5.1482988 | AF20: ea | AG20: =AG17/$U$11 -> 9.2175576 | AH20: ea
C21: #1 skew | D21: ns | E21: =E17*(31-1) -> -67.44 | F21: =F17*(31-1) -> 67.44 | G21: =G17*(31-1) -> 0 | H21: =H17*(31-1) -> -67.44 | I21: =I17*(31-1) -> 67.44 | J21: =J17*(31-1) -> 0 | L21: =L17*(31-1) -> -39.99 | M21: =M17*(31-1) -> 39.99 | N21: =N17*(31-1) -> 0 | O21: =O17*(31-1) -> -39.99 | P21: =P17*(31-1) -> 39.99 | Q21: =Q17*(31-1) -> 0 | T21: high# | U21: 20 | V21: ea
T22: low# | U22: 10 | V22: ea | W22: worst case | Y22: =ROUNDDOWN(Y19,0) -> 4 | Z22: ea | AA22: =ROUNDUP(AA19,0) -> 12 | AB22: ea | AC22: worst case | AE22: =ROUNDDOWN(AE19,0) -> 7 | AF22: ea | AG22: =ROUNDUP(AG19,0) -> 3 | AH22: ea
C23: VSYNCI to VSYNCO delay(max) | D23: ns | E23: 8.656 | T23: baudrate | U23: =U20*(U21+U22) -> 762.98602 | V23: ns | W23: @last xd | Y23: =ROUNDUP(Y20,0) -> 18 | Z23: ea | AA23: =ROUNDDOWN(AA20,0) -> 10 | AB23: ea | AC23: @xc | AE23: =ROUNDUP(AE20,0) -> 6 | AF23: ea | AG23: =ROUNDDOWN(AG20,0) -> 9 | AH23: ea
C24: VSYNCI to VSYNCO delay(typ) | D24: ns | L24: =E23*M2 -> 4.6550001 | U24: =1/U23*1000 -> 1.31064 | V24: mbps | W24: validation | X24: ①min # ≥ 2ea ② min gap# ≥ 2ea
E26: max | H26: 30 | I26: mhz | L26: typ | O26: 30 | P26: mhz | T26: serial latency according to mclk variation
B27: XC | E27: es2 | H27: =1/H26*1000 -> 33.333333 | I27: ns | L27: es2 | O27: =1/O26*1000 -> 33.333333 | P27: ns | T27: 39.312 | U27: mhz | V27: 0.091 | W27: variation
E28: high | F28: low | H28: =H27/2 -> 16.666667 | I28: ns | L28: high | M28: low | O28: =O27/2 -> 16.666667 | P28: ns | T28: =T27+T27*V27 -> 42.889392 | U28: mhz | V28: =1/T28*1000 -> 23.315789 | W28: ns
C29: SCLK | D29: ns | E29: 16.67 | F29: =E29 -> 16.67 | L29: 16.67 | M29: =L29 -> 16.67 | T29: =T27-T27*V27 -> 35.734608 | U29: mhz | V29: =1/T29*1000 -> 27.984076 | W29: ns
C30: SCLKO | D30: ns | E30: 13.972 | F30: 19.368 | L30: 15.158 | M30: 18.182 | T30: 60 | U30: ea | V30: =(T30+12)*V28/1000 -> 1.6787368 | W30: us
C31: SCLK to SCLKO skew | D31: ns | E31: =E30-E29 -> -2.698 | F31: =F30-F29 -> 2.698 | L31: =L30-L29 -> -1.512 | M31: =M30-M29 -> 1.512 | V31: =T30*V29/1000 -> 1.6790446 | W31: us
C32: SCLK to SCLKO delay | D32: ns | E32: 10.218 | L32: 5.387 | M32: =L32/E32 -> 0.52720689 | T32: gap | U32: us | V32: =V30-V31 -> -0.00030779919 | W32: us
E33: high | F33: low | L33: high | M33: low
C34: MOSI to SDO delay | D34: ns | E34: 9.761 | F34: 6.975 | L34: 5.164 | M34: 3.619 | T34: POR Initialize
C35: SCLKO to SDO skew | D35: ns | E35: =E34-E32 -> -0.457 | L35: =L34-L32 -> -0.223 | U35: Vdd ramp-up | W35: digital por after mclk activation | AC35: wait for 1st cmd
U36: analog por | W36: digital [ea] | X36: mclk | Y36: release | AA36: otp down | AC36: total wait
C37: SCLK to MISO delay | D37: ns | E37: 11.964 | L37: 6.261 | M37: =L37/E37 -> 0.52331996 | U37: max [ms] | W37: 16 | X37: [mhz] | Y37: [ms] | AA37: [ms] | AC37: [ms]
C38: SCLK to #2 MISO delay | D38: ns | E38: =E32+E37 -> 22.182 | L38: =L32+L37 -> 11.648 | T38: XC | U38: 3~5 | W38: =2^W37 -> 65536 | X38: 10 | Y38: =W38*(1/X38)/1000 -> 6.5536 | AA38: 1 | AC38: =Y38+AA38 -> 7.5536
C39: SCLK to #3 MISO delay | D39: ns | E39: =E32*2+E37 -> 32.4 | L39: =L32*2+L37 -> 17.035 | T39: XD_BFI | U39: 2~5 | W39: =2^W37 -> 65536 | X39: =14.75 -> 14.75 | Y39: =W39*(1/X39)/1000 -> 4.4431186 | AA39: 1 | AC39: =Y39+AA39 -> 5.4431186
T40: XD_PWM | U40: 2~5 | W40: =2^W37 -> 65536 | X40: 39.312 | Y40: =W40*(1/X40)/1000 -> 1.6670737 | AA40: 1 | AC40: =Y40+AA40 -> 2.6670737
C41: #1 max write access | D41: ns | H41: na | I41: up to 30mhz | O41: na | P41: up to 30mhz
C42: #1 read margin | D42: ns | H42: =H28-E37 -> 4.7026667 | I42: min setup time | O42: =O28-L37 -> 10.405667 | P42: min setup time
...

Sheet mclk_pwm
B2: frame | C2: hz | D2: 100 | E2: 120 | F2: 144 | G2: 165 | H2: 240 | I2: =D2*2^(D4-I4) -> 800 | J2: =E2*2^(E4-J4) -> 960 | K2: =G2*2^(F4-K4) -> 1320 | L2: =H2*2^(G4-L4) -> 1920 | O2: frame | P2: hz | Q2: 100 | R2: 120 | S2: 144 | T2: 165 | U2: 240 | V2: =Q2*2^(Q4-V4) -> 800 | W2: =R2*2^(R4-W4) -> 960 | X2: =T2*2^(S4-X4) -> 1320 | Y2: =U2*2^(T4-Y4) -> 1920 | AB2: frame | AC2: hz | AD2: 100 | AE2: 120 | AF2: =AD2*2^(AD4-AF4) -> 200 | AG2: =AE2*2^(AE4-AG4) -> 240 | AH2: =AD2*2^(AD4-AH4) -> 400 | AI2: =AE2*2^(AE4-AI4) -> 480 | AJ2: =AD2*2^(AD4-AJ4) -> 800 | AK2: =AE2*2^(AE4-AK4) -> 960 | AL2: =AJ2*2^(AJ4-AL4) -> 1600 | AM2: =AK2*2^(AK4-AM4) -> 1920 | AN2: =AL2*2^(AL4-AN4) -> 3200 | AO2: =AM2*2^(AM4-AO4) -> 3840
C3: us | D3: =1/D2*1000000 -> 10000 | E3: =1/E2*1000000 -> 8333.3333 | F3: =1/F2*1000000 -> 6944.4444 | G3: =1/G2*1000000 -> 6060.6061 | H3: =1/H2*1000000 -> 4166.6667 | I3: =1/I2*1000000 -> 1250 | J3: =1/J2*1000000 -> 1041.6667 | K3: =1/K2*1000000 -> 757.57576 | L3: =1/L2*1000000 -> 520.83333 | P3: us | Q3: =1/Q2*1000000 -> 10000 | R3: =1/R2*1000000 -> 8333.3333 | S3: =1/S2*1000000 -> 6944.4444 | T3: =1/T2*1000000 -> 6060.6061 | U3: =1/U2*1000000 -> 4166.6667 | V3: =1/V2*1000000 -> 1250 | W3: =1/W2*1000000 -> 1041.6667 | X3: =1/X2*1000000 -> 757.57576 | Y3: =1/Y2*1000000 -> 520.83333 | AC3: us | AD3: =1/AD2*1000000 -> 10000 | AE3: =1/AE2*1000000 -> 8333.3333 | AF3: =1/AF2*1000000 -> 5000 | AG3: =1/AG2*1000000 -> 4166.6667 | AH3: =1/AH2*1000000 -> 2500 | AI3: =1/AI2*1000000 -> 2083.3333 | AJ3: =1/AJ2*1000000 -> 1250 | AK3: =1/AK2*1000000 -> 1041.6667 | ... AO3: =1/AO2*1000000 -> 260.41667
