Workbook
Name OLE_LINK288: Command!#REF!

Sheet History
B2: Date (YYYY-MM-DD) | C2: Version | D2: Editor | E2: Chapter | F2: Contents
B3: 45854 | C3: 0.1 | D3: YS.KIM | E3: All | F3: Initial version released
B4: 45855 | C4: 0.1.1 | D4: K.LEE | E4: GPIOx CFG | F4: Modified GPIO configuration bits
B5: 45856 | C5: 0.1.2 | D5: BC.CHO | E5: BCUK_SOFT_START[1:0] TIMEOUT SIO1 SSC_TRI SPRD_EN SETUP1 | F5: removed BCUK_SOFT_START[1:0] register add (TBD) in TIMEOUT command & register SIO1[1:0] register modified to SIO[1:0] SSC_TRI register modified to SSC_MODE SPRD_EN register modified to SSC_EN[1:0] SETUP1 register bit position changed
B6: 45860 | C6: 0.1.3 | D6: BC.CHO | E6: VIO_MON VIO_MON_EN READ_VIO_MON All | F6: add VIO_MON[9:0] register add VIO_MON_EN register add READ_VIO_MON command modified command encoding bit & register address bit
B7: 45924 | C7: 0.2 | D7: YS.KIM BC.CHO WS.KANG | E7: SETUP3 STATUS2 SETUP4 Testmode Reg | F7: CLK_INV_EN bit and VB_IN_OV_FLT_EN bit added on SETUP3 VB_IN_OV bit added on STATUS2 add SETUP4 register, SET_SETUP4 & READ_SETUP4 command add first contents testmode register (Control & E-fuse)
B8: 45957 | C8: 0.3 | D8: YS.KIM YJ.LEE | E8: CMD_SET1 ~ CMD_SET16 SETUP3 | F8: New Registers and commnads are added. CMD_SET1 ~ CMD_SET16 modified VB_IN_OV_FLT_EN as VB_IN_OV2_FLT_EN
B9: 45973 | C9: 0.3.1 | D9: SM.LEE | E9: SETUP4 | F9: Merged SETUP4 register changes from GT - ADC_FREQ register added to SETUP4 - SETUP4 register bit position changed - Updated SETUP4 register description
B10: 45975 | C10: 0.3.2 | D10: BC.CHO | E10: Testmode Reg | F10: add TEST_E in 0xE1 add OTP_CRC[7:0] in 0xFD changed Register category name in Testmode Reg
B11: 45980 | C11: 0.3.3 | D11: BC.CHO | E11: Testmode Reg DTB_Table | F11: add TM_F_SS_RESET_SEL, TM_F_SS_RESET_EN in 0xE1 changed from TM_F_LP_SEL to TM_GO_STBY in 0xE5 changed from TM_F_LP_ENABLE to TM_GO_LOWPOWER in 0xE5 removed CP_CLK_8MHz, DTB_OSC_TOP_CLK, DTB_MCLK in DTB_Table add I_SIO_SING_DIN_N in DTB_Table (DIN_N in DTB1 & DTB2 both)
B12: 45980 | C12: 0.3.4 | D12: BC.CHO | E12: CMD_SET1 ~ CMD_SET16 | F12: modified command encoding 8bit - 8'hD0 ~ 8'hDF → 8'h70 ~ 8'h7F
B13: 45981 | C13: 0.3.5 | D13: JK.CHOI | E13: Normal Reg Testmode Reg | F13: add ADC_CLK_POL in 0x0A.SETUP4 moved 0x0A to 0xE8(ADC related 3-register) add CHIP_ID_1~4 in 0xEE to 0xF1
B14: 45982 | C14: 0.3.6 | D14: BC.CHO | E14: SETUP3 SETUP4 | F14: modified access type in SETUP3 register from R to RW - CAN_CFG_EN, CAN_TX_POL, CAN_RX_POL, CAN_LPRX_POL - VB_IN_OV2_FLT_EN modified access type in SETUP4 register from R to RW - LP_WFLT_SEL, CAN_LPRX_EN, CAN_RX_EN, CAN_TX_EN modified default value in SETUP4 register from 0 to 1 - LP_WFLT_SEL, CAN_LPRX_EN, CAN_RX_EN, CAN_TX_EN
... B20: 46003 | C20: 0.4.2 | D20: CH.YE | E20: Testmode Reg | F20: Modify i2c address 0xFA,0xE8

Sheet Command
B2: Command | C2: Command | D2: Data bits | J2: 7 | K2: 6 | L2: 5 | M2: 4 | N2: 3 | O2: 2 | P2: 1 | Q2: 0 | S2: 7 | T2: 6 | U2: 5 | V2: 4 | W2: 3 | X2: 2 | Y2: 1 | Z2: 0
C3: Encoding | G3: * Command Encoding description
B4: RESET | C4: =_xlfn.CONCAT("0x",BIN2HEX(_xlfn.CONCAT(J4,K4,L4,M4,N4,O4,P4,Q4,),2)) -> 0xF0 | D4: 0 | G4: [7:5] | H4: 3'b111 | I4: Write command | J4: 1 | K4: 1 | L4: 1 | M4: 1 | N4: 0 | O4: 0 | P4: 0 | Q4: 0 | R4: =BIN2HEX(_xlfn.CONCAT(L4,M4,N4,O4,P4,Q4),2) -> 30 | S4: 1 | T4: 1 | U4: 1 | V4: 1 | W4: 0 | X4: 0 | Y4: 1 | Z4: 1 | AA4: =BIN2HEX(_xlfn.CONCAT(U4,V4,W4,X4,Y4,Z4),2) -> 33
B5: GOLOWPOWER | C5: =_xlfn.CONCAT("0x",BIN2HEX(_xlfn.CONCAT(J5,K5,L5,M5,N5,O5,P5,Q5,),2)) -> 0xF2 | D5: 0 | H5: 3'b001 | I5: Read command | J5: 1 | K5: 1 | L5: 1 | M5: 1 | N5: 0 | O5: 0 | P5: 1 | Q5: 0 | R5: =BIN2HEX(_xlfn.CONCAT(L5,M5,N5,O5,P5,Q5),2) -> 32 | S5: 1 | T5: 1 | U5: 1 | V5: 1 | W5: 0 | X5: 1 | Y5: 0 | Z5: 0 | AA5: =BIN2HEX(_xlfn.CONCAT(U5,V5,W5,X5,Y5,Z5),2) -> 34
B6: CLRERROR | C6: =_xlfn.CONCAT("0x",BIN2HEX(_xlfn.CONCAT(J6,K6,L6,M6,N6,O6,P6,Q6,),2)) -> 0xF7 | D6: 0 | J6: 1 | K6: 1 | L6: 1 | M6: 1 | N6: 0 | O6: 1 | P6: 1 | Q6: 1 | R6: =BIN2HEX(_xlfn.CONCAT(L6,M6,N6,O6,P6,Q6),2) -> 37 | S6: 1 | T6: 1 | U6: 1 | V6: 1 | W6: 1 | X6: 0 | Y6: 0 | Z6: 0 | AA6: =BIN2HEX(_xlfn.CONCAT(U6,V6,W6,X6,Y6,Z6),2) -> 38
B7: SET_SETUP1 | C7: =_xlfn.CONCAT("0x",BIN2HEX(_xlfn.CONCAT(J7,K7,L7,M7,N7,O7,P7,Q7,),2)) -> 0xE7 | D7: 12 | G7: [5:0] | H7: Register Address | J7: 1 | K7: 1 | L7: 1 | M7: 0 | N7: 0 | O7: 1 | P7: 1 | Q7: 1 | R7: =BIN2HEX(_xlfn.CONCAT(L7,M7,N7,O7,P7,Q7),2) -> 27 | S7: 1 | T7: 1 | U7: 1 | V7: 1 | W7: 1 | X7: 1 | Y7: 0 | Z7: 0 | AA7: =BIN2HEX(_xlfn.CONCAT(U7,V7,W7,X7,Y7,Z7),2) -> 3C
B8: SET_SETUP2 | C8: =_xlfn.CONCAT("0x",BIN2HEX(_xlfn.CONCAT(J8,K8,L8,M8,N8,O8,P8,Q8,),2)) -> 0xE8 | D8: 12 | J8: 1 | K8: 1 | L8: 1 | M8: 0 | N8: 1 | O8: 0 | P8: 0 | Q8: 0 | R8: =BIN2HEX(_xlfn.CONCAT(L8,M8,N8,O8,P8,Q8),2) -> 28 | S8: 1 | T8: 1 | U8: 0 | V8: 0 | W8: 0 | X8: 1 | Y8: 1 | Z8: 0 | AA8: =BIN2HEX(_xlfn.CONCAT(U8,V8,W8,X8,Y8,Z8),2) -> 06
B9: SET_SETUP3 | C9: =_xlfn.CONCAT("0x",BIN2HEX(_xlfn.CONCAT(J9,K9,L9,M9,N9,O9,P9,Q9,),2)) -> 0xE9 | D9: 12 | J9: 1 | K9: 1 | L9: 1 | M9: 0 | N9: 1 | O9: 0 | P9: 0 | Q9: 1 | R9: =BIN2HEX(_xlfn.CONCAT(L9,M9,N9,O9,P9,Q9),2) -> 29 | S9: 1 | T9: 1 | U9: 0 | V9: 0 | W9: 0 | X9: 1 | Y9: 1 | Z9: 1 | AA9: =BIN2HEX(_xlfn.CONCAT(U9,V9,W9,X9,Y9,Z9),2) -> 07
B10: SET_SETUP4 | C10: =_xlfn.CONCAT("0x",BIN2HEX(_xlfn.CONCAT(J10,K10,L10,M10,N10,O10,P10,Q10,),2)) -> 0xEA | D10: 12 | J10: 1 | K10: 1 | L10: 1 | M10: 0 | N10: 1 | O10: 0 | P10: 1 | Q10: 0 | R10: =BIN2HEX(_xlfn.CONCAT(L10,M10,N10,O10,P10,Q10),2) -> 2A | S10: 1 | T10: 1 | U10: 0 | V10: 0 | W10: 1 | X10: 0 | Y10: 0 | Z10: 0 | AA10: =BIN2HEX(_xlfn.CONCAT(U10,V10,W10,X10,Y10,Z10),2) -> 08
B11: SET_TIMEOUT | C11: =_xlfn.CONCAT("0x",BIN2HEX(_xlfn.CONCAT(J11,K11,L11,M11,N11,O11,P11,Q11,),2)) -> 0xEB | D11: 12 | J11: 1 | K11: 1 | L11: 1 | M11: 0 | N11: 1 | O11: 0 | P11: 1 | Q11: 1 | R11: =BIN2HEX(_xlfn.CONCAT(L11,M11,N11,O11,P11,Q11),2) -> 2B | S11: 1 | T11: 1 | U11: 1 | V11: 0 | W11: 0 | X11: 0 | Y11: 0 | Z11: 0 | AA11: =BIN2HEX(_xlfn.CONCAT(U11,V11,W11,X11,Y11,Z11),2) -> 20
B12: SET_CMD_SET1 | C12: 0x70 | D12: 12
B13: SET_CMD_SET2 | C13: 0x71 | D13: 12
B14: SET_CMD_SET3 | C14: 0x72 | D14: 12
B15: SET_CMD_SET4 | C15: 0x73 | D15: 12
B16: SET_CMD_SET5 | C16: 0x74 | D16: 12
B17: SET_CMD_SET6 | C17: 0x75 | D17: 12
B18: SET_CMD_SET7 | C18: 0x76 | D18: 12
B19: SET_CMD_SET8 | C19: 0x77 | D19: 12
B20: SET_CMD_SET9 | C20: 0x78 | D20: 12
B21: SET_CMD_SET10 | C21: 0x79 | D21: 12
B22: SET_CMD_SET11 | C22: 0x7A | D22: 12
B23: SET_CMD_SET12 | C23: 0x7B | D23: 12
... B27: SET_CMD_SET16 | C27: 0x7F | D27: 12
B28: READ_STATUS1 | C28: =_xlfn.CONCAT("0x",BIN2HEX(_xlfn.CONCAT(J28,K28,L28,M28,N28,O28,P28,Q28,),2)) -> 0x20 | D28: 12 | J28: 0 | K28: 0 | L28: 1 | M28: 0 | N28: 0 | O28: 0 | P28: 0 | Q28: 0 | R28: =BIN2HEX(_xlfn.CONCAT(L28,M28,N28,O28,P28,Q28),2) -> 20 | S28: 1 | T28: 1 | U28: 0 | V28: 0 | W28: 1 | X28: 0 | Y28: 1 | Z28: 0 | AA28: =BIN2HEX(_xlfn.CONCAT(U28,V28,W28,X28,Y28,Z28),2) -> 0A
B29: READ_STATUS2 | C29: =_xlfn.CONCAT("0x",BIN2HEX(_xlfn.CONCAT(J29,K29,L29,M29,N29,O29,P29,Q29,),2)) -> 0x21 | D29: 12 | J29: 0 | K29: 0 | L29: 1 | M29: 0 | N29: 0 | O29: 0 | P29: 0 | Q29: 1 | R29: =BIN2HEX(_xlfn.CONCAT(L29,M29,N29,O29,P29,Q29),2) -> 21 | S29: 1 | T29: 1 | U29: 0 | V29: 0 | W29: 1 | X29: 0 | Y29: 1 | Z29: 1 | AA29: =BIN2HEX(_xlfn.CONCAT(U29,V29,W29,X29,Y29,Z29),2) -> 0B
B30: READ_STATUS3 | C30: =_xlfn.CONCAT("0x",BIN2HEX(_xlfn.CONCAT(J30,K30,L30,M30,N30,O30,P30,Q30,),2)) -> 0x22 | D30: 12 | J30: 0 | K30: 0 | L30: 1 | M30: 0 | N30: 0 | O30: 0 | P30: 1 | Q30: 0 | R30: =BIN2HEX(_xlfn.CONCAT(L30,M30,N30,O30,P30,Q30),2) -> 22 | S30: 1 | T30: 1 | U30: 0 | V30: 0 | W30: 1 | X30: 1 | Y30: 1 | Z30: 1 | AA30: =BIN2HEX(_xlfn.CONCAT(U30,V30,W30,X30,Y30,Z30),2) -> 0F
B31: READ_TEMP | C31: =_xlfn.CONCAT("0x",BIN2HEX(_xlfn.CONCAT(J31,K31,L31,M31,N31,O31,P31,Q31,),2)) -> 0x23 | D31: 12 | J31: 0 | K31: 0 | L31: 1 | M31: 0 | N31: 0 | O31: 0 | P31: 1 | Q31: 1 | R31: =BIN2HEX(_xlfn.CONCAT(L31,M31,N31,O31,P31,Q31),2) -> 23 | S31: 1 | T31: 1 | U31: 0 | V31: 1 | W31: 0 | X31: 0 | Y31: 0 | Z31: 0 | AA31: =BIN2HEX(_xlfn.CONCAT(U31,V31,W31,X31,Y31,Z31),2) -> 10
B32: READ_VEXT_GPIO1 | C32: =_xlfn.CONCAT("0x",BIN2HEX(_xlfn.CONCAT(J32,K32,L32,M32,N32,O32,P32,Q32,),2)) -> 0x24 | D32: 12 | J32: 0 | K32: 0 | L32: 1 | M32: 0 | N32: 0 | O32: 1 | P32: 0 | Q32: 0 | R32: =BIN2HEX(_xlfn.CONCAT(L32,M32,N32,O32,P32,Q32),2) -> 24 | S32: 1 | T32: 1 | U32: 0 | V32: 1 | W32: 0 | X32: 0 | Y32: 0 | Z32: 1 | AA32: =BIN2HEX(_xlfn.CONCAT(U32,V32,W32,X32,Y32,Z32),2) -> 11
B33: READ_VEXT_GPIO2 | C33: =_xlfn.CONCAT("0x",BIN2HEX(_xlfn.CONCAT(J33,K33,L33,M33,N33,O33,P33,Q33,),2)) -> 0x25 | D33: 12 | J33: 0 | K33: 0 | L33: 1 | M33: 0 | N33: 0 | O33: 1 | P33: 0 | Q33: 1 | R33: =BIN2HEX(_xlfn.CONCAT(L33,M33,N33,O33,P33,Q33),2) -> 25 | S33: 1 | T33: 1 | U33: 0 | V33: 1 | W33: 0 | X33: 0 | Y33: 1 | Z33: 0 | AA33: =BIN2HEX(_xlfn.CONCAT(U33,V33,W33,X33,Y33,Z33),2) -> 12
B34: READ_VIO_MON | C34: =_xlfn.CONCAT("0x",BIN2HEX(_xlfn.CONCAT(J34,K34,L34,M34,N34,O34,P34,Q34,),2)) -> 0x26 | D34: 12 | J34: 0 | K34: 0 | L34: 1 | M34: 0 | N34: 0 | O34: 1 | P34: 1 | Q34: 0 | R34: =BIN2HEX(_xlfn.CONCAT(L34,M34,N34,O34,P34,Q34),2) -> 26 | S34: 1 | T34: 1 | U34: 0 | V34: 1 | W34: 0 | X34: 0 | Y34: 1 | Z34: 1 | AA34: =BIN2HEX(_xlfn.CONCAT(U34,V34,W34,X34,Y34,Z34),2) -> 13
B35: READ_SETUP1 | C35: =_xlfn.CONCAT("0x",BIN2HEX(_xlfn.CONCAT(J35,K35,L35,M35,N35,O35,P35,Q35,),2)) -> 0x27 | D35: 12 | J35: 0 | K35: 0 | L35: 1 | M35: 0 | N35: 0 | O35: 1 | P35: 1 | Q35: 1 | R35: =BIN2HEX(_xlfn.CONCAT(L35,M35,N35,O35,P35,Q35),2) -> 27 | S35: 1 | T35: 1 | U35: 0 | V35: 1 | W35: 0 | X35: 1 | Y35: 0 | Z35: 0 | AA35: =BIN2HEX(_xlfn.CONCAT(U35,V35,W35,X35,Y35,Z35),2) -> 14
B36: READ_SETUP2 | C36: =_xlfn.CONCAT("0x",BIN2HEX(_xlfn.CONCAT(J36,K36,L36,M36,N36,O36,P36,Q36,),2)) -> 0x28 | D36: 12 | J36: 0 | K36: 0 | L36: 1 | M36: 0 | N36: 1 | O36: 0 | P36: 0 | Q36: 0 | R36: =BIN2HEX(_xlfn.CONCAT(L36,M36,N36,O36,P36,Q36),2) -> 28 | S36: 1 | T36: 1 | U36: 0 | V36: 1 | W36: 0 | X36: 1 | Y36: 0 | Z36: 1 | AA36: =BIN2HEX(_xlfn.CONCAT(U36,V36,W36,X36,Y36,Z36),2) -> 15
B37: READ_SETUP3 | C37: =_xlfn.CONCAT("0x",BIN2HEX(_xlfn.CONCAT(J37,K37,L37,M37,N37,O37,P37,Q37,),2)) -> 0x29 | D37: 12 | J37: 0 | K37: 0 | L37: 1 | M37: 0 | N37: 1 | O37: 0 | P37: 0 | Q37: 1 | R37: =BIN2HEX(_xlfn.CONCAT(L37,M37,N37,O37,P37,Q37),2) -> 29 | S37: 1 | T37: 1 | U37: 0 | V37: 1 | W37: 0 | X37: 1 | Y37: 1 | Z37: 0 | AA37: =BIN2HEX(_xlfn.CONCAT(U37,V37,W37,X37,Y37,Z37),2) -> 16
B38: READ_SETUP4 | C38: =_xlfn.CONCAT("0x",BIN2HEX(_xlfn.CONCAT(J38,K38,L38,M38,N38,O38,P38,Q38,),2)) -> 0x2A | D38: 12 | J38: 0 | K38: 0 | L38: 1 | M38: 0 | N38: 1 | O38: 0 | P38: 1 | Q38: 0 | R38: =BIN2HEX(_xlfn.CONCAT(L38,M38,N38,O38,P38,Q38),2) -> 2A | S38: 1 | T38: 1 | U38: 0 | V38: 1 | W38: 0 | X38: 1 | Y38: 1 | Z38: 1 | AA38: =BIN2HEX(_xlfn.CONCAT(U38,V38,W38,X38,Y38,Z38),2) -> 17
B39: READ_TIMEOUT | C39: =_xlfn.CONCAT("0x",BIN2HEX(_xlfn.CONCAT(J39,K39,L39,M39,N39,O39,P39,Q39,),2)) -> 0x2B | D39: 12 | J39: 0 | K39: 0 | L39: 1 | M39: 0 | N39: 1 | O39: 0 | P39: 1 | Q39: 1 | R39: =BIN2HEX(_xlfn.CONCAT(L39,M39,N39,O39,P39,Q39),2) -> 2B | S39: 1 | T39: 1 | U39: 0 | V39: 1 | W39: 1 | X39: 0 | Y39: 0 | Z39: 0 | AA39: =BIN2HEX(_xlfn.CONCAT(U39,V39,W39,X39,Y39,Z39),2) -> 18
B40: READ_CMD_SET1 | C40: 0x30 | D40: 12 | J40: 0 | K40: 0 | L40: 0 | M40: 0 | N40: 0 | O40: 0 | P40: 0 | Q40: 0 | R40: =BIN2HEX(_xlfn.CONCAT(L40,M40,N40,O40,P40,Q40),2) -> 00 | S40: 1 | T40: 1 | U40: 0 | V40: 1 | W40: 1 | X40: 0 | Y40: 0 | Z40: 1 | AA40: =BIN2HEX(_xlfn.CONCAT(U40,V40,W40,X40,Y40,Z40),2) -> 19
B41: READ_CMD_SET2 | C41: 0x31 | D41: 12 | J41: 0 | K41: 0 | L41: 0 | M41: 0 | N41: 0 | O41: 0 | P41: 0 | Q41: 0 | R41: =BIN2HEX(_xlfn.CONCAT(L41,M41,N41,O41,P41,Q41),2) -> 00 | S41: 1 | T41: 1 | U41: 0 | V41: 1 | W41: 1 | X41: 0 | Y41: 1 | Z41: 0 | AA41: =BIN2HEX(_xlfn.CONCAT(U41,V41,W41,X41,Y41,Z41),2) -> 1A
B42: READ_CMD_SET3 | C42: 0x32 | D42: 12 | J42: 0 | K42: 0 | L42: 0 | M42: 0 | N42: 0 | O42: 0 | P42: 0 | Q42: 0 | R42: =BIN2HEX(_xlfn.CONCAT(L42,M42,N42,O42,P42,Q42),2) -> 00
B43: READ_CMD_SET4 | C43: 0x33 | D43: 12 | J43: 0 | K43: 0 | L43: 0 | M43: 0 | N43: 0 | O43: 0 | P43: 0 | Q43: 0 | R43: =BIN2HEX(_xlfn.CONCAT(L43,M43,N43,O43,P43,Q43),2) -> 00
B44: READ_CMD_SET5 | C44: 0x34 | D44: 12 | J44: 0 | K44: 0 | L44: 0 | M44: 0 | N44: 0 | O44: 0 | P44: 0 | Q44: 0 | R44: =BIN2HEX(_xlfn.CONCAT(L44,M44,N44,O44,P44,Q44),2) -> 00
...

Sheet Register Table
B2: Address | C2: Name | D2: Bit 11 | E2: Bit 10 | F2: Bit 9 | G2: Bit 8 | H2: Bit 7 | I2: Bit 6 | J2: Bit 5 | K2: Bit 4 | L2: Bit 3 | M2: Bit 2 | N2: Bit 1 | O2: Bit 0 | P2: Default Value (bin) | Q2: Default Value (hex)
B3: 0x00 | C3: =VLOOKUP(B3,'Register Description'!$B$1:$C$220,2,FALSE) -> STATUS1 | D3: IC_STATE[3:0] (TBD) | H3: NA | I3: RFREQ_STATUS | J3: MASTER_MODE | K3: DEV_ADDR[2:0] | N3: SIO[1:0] | P3: =_xlfn.CONCAT('Register Description'!F22,'Register Description'!G22,'Register Description'!H22,'Register Description'!I22,"_",'Register Description'!J22,'Register Description'!K22,'Register Description'!L22,'Register Description'!M22,"_",'Register Description'!N22,'Register Description'!O22,'Register Description'!P22,'Register Description'!Q22) -> 0000_0000_0000 | Q3: =_xlfn.CONCAT("0x",BIN2HEX(_xlfn.CONCAT('Register Description'!F22,'Register Description'!G22,'Register Description'!H22,'Register Description'!I22),1),BIN2HEX(_xlfn.CONCAT('Register Description'!J22,'Register Description'!K22,'Register Description'!L22,'Register Description'!M22),1),BIN2HEX(_xlfn.CONCAT('Register Description'!N22,'Register Description'!O22,'Register Description'!P22,'Register Description'!Q22),1)) -> 0x000
B4: 0x01 | C4: =VLOOKUP(B4,'Register Description'!$B$1:$C$220,2,FALSE) -> STATUS2 | D4: 필요시, CAN_STATUS | E4: VB_IN_OV | F4: POR | G4: OTPCRC_FLT | H4: BUCK_OV | I4: BUCK_UV | J4: BUCK_UV_CRIT | K4: BUCK_OC | L4: BOOT_UV | M4: TW | N4: VC_OV | O4: VDD5_UV | P4: =_xlfn.CONCAT('Register Description'!F33,'Register Description'!G33,'Register Description'!H33,'Register Description'!I33,"_",'Register Description'!J33,'Register Description'!K33,'Register Description'!L33,'Register Description'!M33,"_",'Register Description'!N33,'Register Description'!O33,'Register Description'!P33,'Register Description'!Q33) -> 0010_0000_0000 | Q4: =_xlfn.CONCAT("0x",BIN2HEX(_xlfn.CONCAT('Register Description'!F33,'Register Description'!G33,'Register Description'!H33,'Register Description'!I33),1),BIN2HEX(_xlfn.CONCAT('Register Description'!J33,'Register Description'!K33,'Register Description'!L33,'Register Description'!M33),1),BIN2HEX(_xlfn.CONCAT('Register Description'!N33,'Register Description'!O33,'Register Description'!P33,'Register Description'!Q33),1)) -> 0x200
B5: 0x02 | C5: =VLOOKUP(B5,'Register Description'!$B$1:$C$220,2,FALSE) -> STATUS3 | D5: GPIO2_FALLING_DET | E5: GPIO2_RISING_DET | F5: GPIO2_STATUS | G5: GPIO1_FALLING_DET | H5: GPIO1_RISING_DET | I5: GPIO1_STATUS | J5: GPIO0_FALLING_DET | K5: GPIO0_RISING_DET | L5: GPIO0_STATUS | M5: T_OUT (TBD) | N5: CRC_FLT | O5: COM_FLT | P5: =_xlfn.CONCAT('Register Description'!F50,'Register Description'!G50,'Register Description'!H50,'Register Description'!I50,"_",'Register Description'!J50,'Register Description'!K50,'Register Description'!L50,'Register Description'!M50,"_",'Register Description'!N50,'Register Description'!O50,'Register Description'!P50,'Register Description'!Q50) -> 0000_0000_0000 | Q5: =_xlfn.CONCAT("0x",BIN2HEX(_xlfn.CONCAT('Register Description'!F50,'Register Description'!G50,'Register Description'!H50,'Register Description'!I50),1),BIN2HEX(_xlfn.CONCAT('Register Description'!J50,'Register Description'!K50,'Register Description'!L50,'Register Description'!M50),1),BIN2HEX(_xlfn.CONCAT('Register Description'!N50,'Register Description'!O50,'Register Description'!P50,'Register Description'!Q50),1)) -> 0x000
B6: 0x03 | C6: =VLOOKUP(B6,'Register Description'!$B$1:$C$220,2,FALSE) -> TEMP | D6: NA | E6: NA | F6: TEMPERATURE[9:0] | P6: =_xlfn.CONCAT('Register Description'!F68,'Register Description'!G68,'Register Description'!H68,'Register Description'!I68,"_",'Register Description'!J68,'Register Description'!K68,'Register Description'!L68,'Register Description'!M68,"_",'Register Description'!N68,'Register Description'!O68,'Register Description'!P68,'Register Description'!Q68) -> 0000_0000_0000 | Q6: =_xlfn.CONCAT("0x",BIN2HEX(_xlfn.CONCAT('Register Description'!F68,'Register Description'!G68,'Register Description'!H68,'Register Description'!I68),1),BIN2HEX(_xlfn.CONCAT('Register Description'!J68,'Register Description'!K68,'Register Description'!L68,'Register Description'!M68),1),BIN2HEX(_xlfn.CONCAT('Register Description'!N68,'Register Description'!O68,'Register Description'!P68,'Register Description'!Q68),1)) -> 0x000
B7: 0x04 | C7: =VLOOKUP(B7,'Register Description'!$B$1:$C$220,2,FALSE) -> VEXT_GPIO1 | D7: NA | E7: NA | F7: VEXT_GPIO1[9:0] | P7: =_xlfn.CONCAT('Register Description'!F75,'Register Description'!G75,'Register Description'!H75,'Register Description'!I75,"_",'Register Description'!J75,'Register Description'!K75,'Register Description'!L75,'Register Description'!M75,"_",'Register Description'!N75,'Register Description'!O75,'Register Description'!P75,'Register Description'!Q75) -> 0000_0000_0000 | Q7: =_xlfn.CONCAT("0x",BIN2HEX(_xlfn.CONCAT('Register Description'!F75,'Register Description'!G75,'Register Description'!H75,'Register Description'!I75),1),BIN2HEX(_xlfn.CONCAT('Register Description'!J75,'Register Description'!K75,'Register Description'!L75,'Register Description'!M75),1),BIN2HEX(_xlfn.CONCAT('Register Description'!N75,'Register Description'!O75,'Register Description'!P75,'Register Description'!Q75),1)) -> 0x000
B8: 0x05 | C8: =VLOOKUP(B8,'Register Description'!$B$1:$C$220,2,FALSE) -> VEXT_GPIO2 | D8: NA | E8: NA | F8: VEXT_GPIO2[9:0] | P8: =_xlfn.CONCAT('Register Description'!F82,'Register Description'!G82,'Register Description'!H82,'Register Description'!I82,"_",'Register Description'!J82,'Register Description'!K82,'Register Description'!L82,'Register Description'!M82,"_",'Register Description'!N82,'Register Description'!O82,'Register Description'!P82,'Register Description'!Q82) -> 0000_0000_0000 | Q8: =_xlfn.CONCAT("0x",BIN2HEX(_xlfn.CONCAT('Register Description'!F75,'Register Description'!G75,'Register Description'!H75,'Register Description'!I75),1),BIN2HEX(_xlfn.CONCAT('Register Description'!J75,'Register Description'!K75,'Register Description'!L75,'Register Description'!M75),1),BIN2HEX(_xlfn.CONCAT('Register Description'!N75,'Register Description'!O75,'Register Description'!P75,'Register Description'!Q75),1)) -> 0x000
B9: 0x06 | C9: VIO_MON | D9: NA | E9: NA | F9: VIO_MON[9:0] | P9: =_xlfn.CONCAT('Register Description'!F89,'Register Description'!G89,'Register Description'!H89,'Register Description'!I89,"_",'Register Description'!J89,'Register Description'!K89,'Register Description'!L89,'Register Description'!M89,"_",'Register Description'!N89,'Register Description'!O89,'Register Description'!P89,'Register Description'!Q89) -> 0000_0000_0000 | Q9: =_xlfn.CONCAT("0x",BIN2HEX(_xlfn.CONCAT('Register Description'!F89,'Register Description'!G89,'Register Description'!H89,'Register Description'!I89),1),BIN2HEX(_xlfn.CONCAT('Register Description'!J89,'Register Description'!K89,'Register Description'!L89,'Register Description'!M89),1),BIN2HEX(_xlfn.CONCAT('Register Description'!N89,'Register Description'!O89,'Register Description'!P89,'Register Description'!Q89),1)) -> 0x000
B10: 0x07 | C10: =VLOOKUP(B10,'Register Description'!$B$1:$C$220,2,FALSE) -> SETUP1 | D10: NA | E10: SSC _MODE | F10: SSC_EN[1:0] | H10: BUCK_OC_FLT_EN | I10: FM_FREQ[2:0] | L10: BUCK_OC _FILTER_TIME[1:0] | N10: BUCK_DISCHARGE | O10: BUCK_EN | P10: =_xlfn.CONCAT('Register Description'!F97,'Register Description'!G97,'Register Description'!H97,'Register Description'!I97,"_",'Register Description'!J97,'Register Description'!K97,'Register Description'!L97,'Register Description'!M97,"_",'Register Description'!N97,'Register Description'!O97,'Register Description'!P97,'Register Description'!Q97) -> 0001_1011_1101 | Q10: =_xlfn.CONCAT("0x",BIN2HEX(_xlfn.CONCAT('Register Description'!F97,'Register Description'!G97,'Register Description'!H97,'Register Description'!I97),1),BIN2HEX(_xlfn.CONCAT('Register Description'!J97,'Register Description'!K97,'Register Description'!L97,'Register Description'!M97),1),BIN2HEX(_xlfn.CONCAT('Register Description'!N97,'Register Description'!O97,'Register Description'!P97,'Register Description'!Q97),1)) -> 0x1BD
B11: 0x08 | C11: =VLOOKUP(B11,'Register Description'!$B$1:$C$220,2,FALSE) -> SETUP2 | D11: GPIO2 _OUT | E11: GPIO2_OUT_TYPE | F11: GPIO2_VEXT_EN | G11: GPIO2_MODE | H11: GPIO1 _OUT | I11: GPIO1_OUT_TYPE | J11: GPIO1_VEXT_EN | K11: GPIO1_MODE | L11: GPIO0 _OUT | M11: GPIO0_OUT_TYPE | N11: GPIO0_BUCK_CTRL_EN | O11: GPIO0_MODE | P11: =_xlfn.CONCAT('Register Description'!F111,'Register Description'!G111,'Register Description'!H111,'Register Description'!I111,"_",'Register Description'!J111,'Register Description'!K111,'Register Description'!L111,'Register Description'!M111,"_",'Register Description'!N111,'Register Description'!O111,'Register Description'!P111,'Register Description'!Q111) -> 0000_0000_0011 | Q11: =_xlfn.CONCAT("0x",BIN2HEX(_xlfn.CONCAT('Register Description'!F111,'Register Description'!G111,'Register Description'!H111,'Register Description'!I111),1),BIN2HEX(_xlfn.CONCAT('Register Description'!J111,'Register Description'!K111,'Register Description'!L111,'Register Description'!M111),1),BIN2HEX(_xlfn.CONCAT('Register Description'!N111,'Register Description'!O111,'Register Description'!P111,'Register Description'!Q111),1)) -> 0x003
B12: 0x09 | C12: =VLOOKUP(B12,'Register Description'!$B$1:$C$220,2,FALSE) -> SETUP3 | D12: CAN_CFG_EN | E12: CAN_TX_POL | F12: CAN_RX_POL | G12: CAN_LPRX_POL | H12: VB_IN_OV2_FLT_EN | I12: CLK_INV_EN | J12: VIO_MON_EN | K12: CAN_BYPASS_TX_EN | L12: CAN_BYPASS_RX_EN | M12: GPIO2_PD_EN | N12: GPIO1_PD_EN | O12: GPIO0_PD_EN | P12: =_xlfn.CONCAT('Register Description'!F130,'Register Description'!G130,'Register Description'!H130,'Register Description'!I130,"_",'Register Description'!J130,'Register Description'!K130,'Register Description'!L130,'Register Description'!M130,"_",'Register Description'!N130,'Register Description'!O130,'Register Description'!P130,'Register Description'!Q130) -> 0111_1000_0000 | Q12: =_xlfn.CONCAT("0x",BIN2HEX(_xlfn.CONCAT('Register Description'!F130,'Register Description'!G130,'Register Description'!H130,'Register Description'!I130),1),BIN2HEX(_xlfn.CONCAT('Register Description'!J130,'Register Description'!K130,'Register Description'!L130,'Register Description'!M130),1),BIN2HEX(_xlfn.CONCAT('Register Description'!N130,'Register Description'!O130,'Register Description'!P130,'Register Description'!Q130),1)) -> 0x780
B13: 0x0A | C13: =VLOOKUP(B13,'Register Description'!$B$1:$C$220,2,FALSE) -> SETUP4 | D13: RSVD | E13: RSVD | F13: RSVD | G13: ADC_CLK_POL | H13: ADC_FREQ[1:0] | J13: CAN_PUP_EN | K13: CAN_PDN_EN | L13: LP_WFLT_SEL | M13: CAN_LPRX_EN | N13: CAN_RX_EN | O13: CAN_TX_EN | P13: =_xlfn.CONCAT('Register Description'!F149,'Register Description'!G149,'Register Description'!H149,'Register Description'!I149,"_",'Register Description'!J149,'Register Description'!K149,'Register Description'!L149,'Register Description'!M149,"_",'Register Description'!N149,'Register Description'!O149,'Register Description'!P149,'Register Description'!Q149) -> 0000_0111_1111 | Q13: =_xlfn.CONCAT("0x",BIN2HEX(_xlfn.CONCAT('Register Description'!F149,'Register Description'!G149,'Register Description'!H149,'Register Description'!I149),1),BIN2HEX(_xlfn.CONCAT('Register Description'!J149,'Register Description'!K149,'Register Description'!L149,'Register Description'!M149),1),BIN2HEX(_xlfn.CONCAT('Register Description'!N149,'Register Description'!O149,'Register Description'!P149,'Register Description'!Q149),1)) -> 0x07F
B14: 0x0B | C14: =VLOOKUP(B14,'Register Description'!$B$1:$C$220,2,FALSE) -> TIMEOUT | D14: TIMEOUT[11:0](TBD) | P14: =_xlfn.CONCAT('Register Description'!F163,'Register Description'!G163,'Register Description'!H163,'Register Description'!I163,"_",'Register Description'!J163,'Register Description'!K163,'Register Description'!L163,'Register Description'!M163,"_",'Register Description'!N163,'Register Description'!O163,'Register Description'!P163,'Register Description'!Q163) -> 1000_0000_0000 | Q14: =_xlfn.CONCAT("0x",BIN2HEX(_xlfn.CONCAT('Register Description'!F163,'Register Description'!G163,'Register Description'!H163,'Register Description'!I163),1),BIN2HEX(_xlfn.CONCAT('Register Description'!J163,'Register Description'!K163,'Register Description'!L163,'Register Description'!M163),1),BIN2HEX(_xlfn.CONCAT('Register Description'!N163,'Register Description'!O163,'Register Description'!P163,'Register Description'!Q163),1)) -> 0x800
B15: 0x0C | C15: =VLOOKUP(B15,'Register Description'!$B$1:$C$220,2,FALSE) -> CMD_SET1 | D15: COM_DIR1 | E15: DATA_LENGTH1[2:0] | H15: CMD1[7:0] | P15: =_xlfn.CONCAT('Register Description'!F170,'Register Description'!G170,'Register Description'!H170,'Register Description'!I170,"_",'Register Description'!J170,'Register Description'!K170,'Register Description'!L170,'Register Description'!M170,"_",'Register Description'!N170,'Register Description'!O170,'Register Description'!P170,'Register Description'!Q170) -> 0000_0000_0000 | Q15: =_xlfn.CONCAT("0x",BIN2HEX(_xlfn.CONCAT('Register Description'!F170,'Register Description'!G170,'Register Description'!H170,'Register Description'!I170),1),BIN2HEX(_xlfn.CONCAT('Register Description'!J170,'Register Description'!K170,'Register Description'!L170,'Register Description'!M170),1),BIN2HEX(_xlfn.CONCAT('Register Description'!N170,'Register Description'!O170,'Register Description'!P170,'Register Description'!Q170),1)) -> 0x000
B16: 0x0D | C16: =VLOOKUP(B16,'Register Description'!$B$1:$C$220,2,FALSE) -> CMD_SET2 | D16: COM_DIR2 | E16: DATA_LENGTH2[2:0] | H16: CMD2[7:0] | P16: =_xlfn.CONCAT('Register Description'!F179,'Register Description'!G179,'Register Description'!H179,'Register Description'!I179,"_",'Register Description'!J179,'Register Description'!K179,'Register Description'!L179,'Register Description'!M179,"_",'Register Description'!N179,'Register Description'!O179,'Register Description'!P179,'Register Description'!Q179) -> 0000_0000_0000 | Q16: =_xlfn.CONCAT("0x",BIN2HEX(_xlfn.CONCAT('Register Description'!F179,'Register Description'!G179,'Register Description'!H179,'Register Description'!I179),1),BIN2HEX(_xlfn.CONCAT('Register Description'!J179,'Register Description'!K179,'Register Description'!L179,'Register Description'!M179),1),BIN2HEX(_xlfn.CONCAT('Register Description'!N179,'Register Description'!O179,'Register Description'!P179,'Register Description'!Q179),1)) -> 0x000
B17: 0x0E | C17: =VLOOKUP(B17,'Register Description'!$B$1:$C$220,2,FALSE) -> CMD_SET3 | D17: COM_DIR3 | E17: DATA_LENGTH3[2:0] | H17: CMD3[7:0] | P17: =_xlfn.CONCAT('Register Description'!F188,'Register Description'!G188,'Register Description'!H188,'Register Description'!I188,"_",'Register Description'!J188,'Register Description'!K188,'Register Description'!L188,'Register Description'!M188,"_",'Register Description'!N188,'Register Description'!O188,'Register Description'!P188,'Register Description'!Q188) -> 0000_0000_0000 | Q17: =_xlfn.CONCAT("0x",BIN2HEX(_xlfn.CONCAT('Register Description'!F188,'Register Description'!G188,'Register Description'!H188,'Register Description'!I188),1),BIN2HEX(_xlfn.CONCAT('Register Description'!J188,'Register Description'!K188,'Register Description'!L188,'Register Description'!M188),1),BIN2HEX(_xlfn.CONCAT('Register Description'!N188,'Register Description'!O188,'Register Description'!P188,'Register Description'!Q188),1)) -> 0x000
B18: 0x0F | C18: =VLOOKUP(B18,'Register Description'!$B$1:$C$220,2,FALSE) -> CMD_SET4 | D18: COM_DIR4 | E18: DATA_LENGTH4[2:0] | H18: CMD4[7:0] | P18: =_xlfn.CONCAT('Register Description'!F197,'Register Description'!G197,'Register Description'!H197,'Register Description'!I197,"_",'Register Description'!J197,'Register Description'!K197,'Register Description'!L197,'Register Description'!M197,"_",'Register Description'!N197,'Register Description'!O197,'Register Description'!P197,'Register Description'!Q197) -> 0000_0000_0000 | Q18: =_xlfn.CONCAT("0x",BIN2HEX(_xlfn.CONCAT('Register Description'!F197,'Register Description'!G197,'Register Description'!H197,'Register Description'!I197),1),BIN2HEX(_xlfn.CONCAT('Register Description'!J197,'Register Description'!K197,'Register Description'!L197,'Register Description'!M197),1),BIN2HEX(_xlfn.CONCAT('Register Description'!N197,'Register Description'!O197,'Register Description'!P197,'Register Description'!Q197),1)) -> 0x000
B19: 0x10 | C19: =VLOOKUP(B19,'Register Description'!$B$1:$C$220,2,FALSE) -> CMD_SET5 | D19: COM_DIR5 | E19: DATA_LENGTH5[2:0] | H19: CMD5[7:0] | P19: =_xlfn.CONCAT('Register Description'!F206,'Register Description'!G206,'Register Description'!H206,'Register Description'!I206,"_",'Register Description'!J206,'Register Description'!K206,'Register Description'!L206,'Register Description'!M206,"_",'Register Description'!N206,'Register Description'!O206,'Register Description'!P206,'Register Description'!Q206) -> 0000_0000_0000 | Q19: =_xlfn.CONCAT("0x",BIN2HEX(_xlfn.CONCAT('Register Description'!F206,'Register Description'!G206,'Register Description'!H206,'Register Description'!I206),1),BIN2HEX(_xlfn.CONCAT('Register Description'!J206,'Register Description'!K206,'Register Description'!L206,'Register Description'!M206),1),BIN2HEX(_xlfn.CONCAT('Register Description'!N206,'Register Description'!O206,'Register Description'!P206,'Register Description'!Q206),1)) -> 0x000
B20: 0x11 | C20: =VLOOKUP(B20,'Register Description'!$B$1:$C$522,2,FALSE) -> CMD_SET6 | D20: COM_DIR6 | E20: DATA_LENGTH6[2:0] | H20: CMD6[7:0] | P20: =_xlfn.CONCAT('Register Description'!F215,'Register Description'!G215,'Register Description'!H215,'Register Description'!I215,"_",'Register Description'!J215,'Register Description'!K215,'Register Description'!L215,'Register Description'!M215,"_",'Register Description'!N215,'Register Description'!O215,'Register Description'!P215,'Register Description'!Q215) -> 0000_0000_0000 | Q20: =_xlfn.CONCAT("0x",BIN2HEX(_xlfn.CONCAT('Register Description'!F215,'Register Description'!G215,'Register Description'!H215,'Register Description'!I215),1),BIN2HEX(_xlfn.CONCAT('Register Description'!J215,'Register Description'!K215,'Register Description'!L215,'Register Description'!M215),1),BIN2HEX(_xlfn.CONCAT('Register Description'!N215,'Register Description'!O215,'Register Description'!P215,'Register Description'!Q215),1)) -> 0x000
B21: 0x12 | C21: =VLOOKUP(B21,'Register Description'!$B$1:$C$522,2,FALSE) -> CMD_SET7 | D21: COM_DIR7 | E21: DATA_LENGTH7[2:0] | H21: CMD7[7:0] | P21: =_xlfn.CONCAT('Register Description'!F224,'Register Description'!G224,'Register Description'!H224,'Register Description'!I224,"_",'Register Description'!J224,'Register Description'!K224,'Register Description'!L224,'Register Description'!M224,"_",'Register Description'!N224,'Register Description'!O224,'Register Description'!P224,'Register Description'!Q224) -> 0000_0000_0000 | Q21: =_xlfn.CONCAT("0x",BIN2HEX(_xlfn.CONCAT('Register Description'!F224,'Register Description'!G224,'Register Description'!H224,'Register Description'!I224),1),BIN2HEX(_xlfn.CONCAT('Register Description'!J224,'Register Description'!K224,'Register Description'!L224,'Register Description'!M224),1),BIN2HEX(_xlfn.CONCAT('Register Description'!N224,'Register Description'!O224,'Register Description'!P224,'Register Description'!Q224),1)) -> 0x000
B22: 0x13 | C22: =VLOOKUP(B22,'Register Description'!$B$1:$C$522,2,FALSE) -> CMD_SET8 | D22: COM_DIR8 | E22: DATA_LENGTH8[2:0] | H22: CMD8[7:0] | P22: =_xlfn.CONCAT('Register Description'!F233,'Register Description'!G233,'Register Description'!H233,'Register Description'!I233,"_",'Register Description'!J233,'Register Description'!K233,'Register Description'!L233,'Register Description'!M233,"_",'Register Description'!N233,'Register Description'!O233,'Register Description'!P233,'Register Description'!Q233) -> 0000_0000_0000 | Q22: =_xlfn.CONCAT("0x",BIN2HEX(_xlfn.CONCAT('Register Description'!F233,'Register Description'!G233,'Register Description'!H233,'Register Description'!I233),1),BIN2HEX(_xlfn.CONCAT('Register Description'!J233,'Register Description'!K233,'Register Description'!L233,'Register Description'!M233),1),BIN2HEX(_xlfn.CONCAT('Register Description'!N233,'Register Description'!O233,'Register Description'!P233,'Register Description'!Q233),1)) -> 0x000
B23: 0x14 | C23: =VLOOKUP(B23,'Register Description'!$B$1:$C$522,2,FALSE) -> CMD_SET9 | D23: COM_DIR9 | E23: DATA_LENGTH9[2:0] | H23: CMD9[7:0] | P23: =_xlfn.CONCAT('Register Description'!F242,'Register Description'!G242,'Register Description'!H242,'Register Description'!I242,"_",'Register Description'!J242,'Register Description'!K242,'Register Description'!L242,'Register Description'!M242,"_",'Register Description'!N242,'Register Description'!O242,'Register Description'!P242,'Register Description'!Q242) -> 0000_0000_0000 | Q23: =_xlfn.CONCAT("0x",BIN2HEX(_xlfn.CONCAT('Register Description'!F242,'Register Description'!G242,'Register Description'!H242,'Register Description'!I242),1),BIN2HEX(_xlfn.CONCAT('Register Description'!J242,'Register Description'!K242,'Register Description'!L242,'Register Description'!M242),1),BIN2HEX(_xlfn.CONCAT('Register Description'!N242,'Register Description'!O242,'Register Description'!P242,'Register Description'!Q242),1)) -> 0x000
B24: 0x15 | C24: =VLOOKUP(B24,'Register Description'!$B$1:$C$522,2,FALSE) -> CMD_SET10 | D24: COM_DIR10 | E24: DATA_LENGTH10[2:0] | H24: CMD10[7:0] | P24: =_xlfn.CONCAT('Register Description'!F251,'Register Description'!G251,'Register Description'!H251,'Register Description'!I251,"_",'Register Description'!J251,'Register Description'!K251,'Register Description'!L251,'Register Description'!M251,"_",'Register Description'!N251,'Register Description'!O251,'Register Description'!P251,'Register Description'!Q251) -> 0000_0000_0000 | Q24: =_xlfn.CONCAT("0x",BIN2HEX(_xlfn.CONCAT('Register Description'!F251,'Register Description'!G251,'Register Description'!H251,'Register Description'!I251),1),BIN2HEX(_xlfn.CONCAT('Register Description'!J251,'Register Description'!K251,'Register Description'!L251,'Register Description'!M251),1),BIN2HEX(_xlfn.CONCAT('Register Description'!N251,'Register Description'!O251,'Register Description'!P251,'Register Description'!Q251),1)) -> 0x000
B25: 0x16 | C25: =VLOOKUP(B25,'Register Description'!$B$1:$C$522,2,FALSE) -> CMD_SET11 | D25: COM_DIR11 | E25: DATA_LENGTH11[2:0] | H25: CMD11[7:0] | P25: =_xlfn.CONCAT('Register Description'!F260,'Register Description'!G260,'Register Description'!H260,'Register Description'!I260,"_",'Register Description'!J260,'Register Description'!K260,'Register Description'!L260,'Register Description'!M260,"_",'Register Description'!N260,'Register Description'!O260,'Register Description'!P260,'Register Description'!Q260) -> 0000_0000_0000 | Q25: =_xlfn.CONCAT("0x",BIN2HEX(_xlfn.CONCAT('Register Description'!F260,'Register Description'!G260,'Register Description'!H260,'Register Description'!I260),1),BIN2HEX(_xlfn.CONCAT('Register Description'!J260,'Register Description'!K260,'Register Description'!L260,'Register Description'!M260),1),BIN2HEX(_xlfn.CONCAT('Register Description'!N260,'Register Description'!O260,'Register Description'!P260,'Register Description'!Q260),1)) -> 0x000
B26: 0x17 | C26: =VLOOKUP(B26,'Register Description'!$B$1:$C$522,2,FALSE) -> CMD_SET12 | D26: COM_DIR12 | E26: DATA_LENGTH12[2:0] | H26: CMD12[7:0] | P26: =_xlfn.CONCAT('Register Description'!F269,'Register Description'!G269,'Register Description'!H269,'Register Description'!I269,"_",'Register Description'!J269,'Register Description'!K269,'Register Description'!L269,'Register Description'!M269,"_",'Register Description'!N269,'Register Description'!O269,'Register Description'!P269,'Register Description'!Q269) -> 0000_0000_0000 | Q26: =_xlfn.CONCAT("0x",BIN2HEX(_xlfn.CONCAT('Register Description'!F269,'Register Description'!G269,'Register Description'!H269,'Register Description'!I269),1),BIN2HEX(_xlfn.CONCAT('Register Description'!J269,'Register Description'!K269,'Register Description'!L269,'Register Description'!M269),1),BIN2HEX(_xlfn.CONCAT('Register Description'!N269,'Register Description'!O269,'Register Description'!P269,'Register Description'!Q269),1)) -> 0x000
B27: 0x18 | C27: =VLOOKUP(B27,'Register Description'!$B$1:$C$522,2,FALSE) -> CMD_SET13 | D27: COM_DIR13 | E27: DATA_LENGTH13[2:0] | H27: CMD13[7:0] | P27: =_xlfn.CONCAT('Register Description'!F278,'Register Description'!G278,'Register Description'!H278,'Register Description'!I278,"_",'Register Description'!J278,'Register Description'!K278,'Register Description'!L278,'Register Description'!M278,"_",'Register Description'!N278,'Register Description'!O278,'Register Description'!P278,'Register Description'!Q278) -> 0000_0000_0000 | Q27: =_xlfn.CONCAT("0x",BIN2HEX(_xlfn.CONCAT('Register Description'!F278,'Register Description'!G278,'Register Description'!H278,'Register Description'!I278),1),BIN2HEX(_xlfn.CONCAT('Register Description'!J278,'Register Description'!K278,'Register Description'!L278,'Register Description'!M278),1),BIN2HEX(_xlfn.CONCAT('Register Description'!N278,'Register Description'!O278,'Register Description'!P278,'Register Description'!Q278),1)) -> 0x000
B28: 0x19 | C28: =VLOOKUP(B28,'Register Description'!$B$1:$C$522,2,FALSE) -> CMD_SET14 | D28: COM_DIR14 | E28: DATA_LENGTH14[2:0] | H28: CMD14[7:0] | P28: =_xlfn.CONCAT('Register Description'!F287,'Register Description'!G287,'Register Description'!H287,'Register Description'!I287,"_",'Register Description'!J287,'Register Description'!K287,'Register Description'!L287,'Register Description'!M287,"_",'Register Description'!N287,'Register Description'!O287,'Register Description'!P287,'Register Description'!Q287) -> 0000_0000_0000 | Q28: =_xlfn.CONCAT("0x",BIN2HEX(_xlfn.CONCAT('Register Description'!F287,'Register Description'!G287,'Register Description'!H287,'Register Description'!I287),1),BIN2HEX(_xlfn.CONCAT('Register Description'!J287,'Register Description'!K287,'Register Description'!L287,'Register Description'!M287),1),BIN2HEX(_xlfn.CONCAT('Register Description'!N287,'Register Description'!O287,'Register Description'!P287,'Register Description'!Q287),1)) -> 0x000
B29: 0x1A | C29: =VLOOKUP(B29,'Register Description'!$B$1:$C$522,2,FALSE) -> CMD_SET15 | D29: COM_DIR15 | E29: DATA_LENGTH15[2:0] | H29: CMD15[7:0] | P29: =_xlfn.CONCAT('Register Description'!F296,'Register Description'!G296,'Register Description'!H296,'Register Description'!I296,"_",'Register Description'!J296,'Register Description'!K296,'Register Description'!L296,'Register Description'!M296,"_",'Register Description'!N296,'Register Description'!O296,'Register Description'!P296,'Register Description'!Q296) -> 0000_0000_0000 | Q29: =_xlfn.CONCAT("0x",BIN2HEX(_xlfn.CONCAT('Register Description'!F296,'Register Description'!G296,'Register Description'!H296,'Register Description'!I296),1),BIN2HEX(_xlfn.CONCAT('Register Description'!J296,'Register Description'!K296,'Register Description'!L296,'Register Description'!M296),1),BIN2HEX(_xlfn.CONCAT('Register Description'!N296,'Register Description'!O296,'Register Description'!P296,'Register Description'!Q296),1)) -> 0x000
B30: 0x1B | C30: =VLOOKUP(B30,'Register Description'!$B$1:$C$522,2,FALSE) -> CMD_SET16 | D30: COM_DIR16 | E30: DATA_LENGTH16[2:0] | H30: CMD16[7:0] | P30: =_xlfn.CONCAT('Register Description'!F305,'Register Description'!G305,'Register Description'!H305,'Register Description'!I305,"_",'Register Description'!J305,'Register Description'!K305,'Register Description'!L305,'Register Description'!M305,"_",'Register Description'!N305,'Register Description'!O305,'Register Description'!P305,'Register Description'!Q305) -> 0000_0000_0000 | Q30: =_xlfn.CONCAT("0x",BIN2HEX(_xlfn.CONCAT('Register Description'!F305,'Register Description'!G305,'Register Description'!H305,'Register Description'!I305),1),BIN2HEX(_xlfn.CONCAT('Register Description'!J305,'Register Description'!K305,'Register Description'!L305,'Register Description'!M305),1),BIN2HEX(_xlfn.CONCAT('Register Description'!N305,'Register Description'!O305,'Register Description'!P305,'Register Description'!Q305),1)) -> 0x000
C31: =VLOOKUP(B31,'Register Description'!$B$1:$C$220,2,FALSE) -> #N/A
C32: =VLOOKUP(B32,'Register Description'!$B$1:$C$220,2,FALSE) -> #N/A
C33: =VLOOKUP(B33,'Register Description'!$B$1:$C$220,2,FALSE) -> #N/A
C34: =VLOOKUP(B34,'Register Description'!$B$1:$C$220,2,FALSE) -> #N/A
C35: =VLOOKUP(B35,'Register Description'!$B$1:$C$220,2,FALSE) -> #N/A
C36: =VLOOKUP(B36,'Register Description'!$B$1:$C$220,2,FALSE) -> #N/A
C37: =VLOOKUP(B37,'Register Description'!$B$1:$C$220,2,FALSE) -> #N/A
C38: =VLOOKUP(B38,'Register Description'!$B$1:$C$220,2,FALSE) -> #N/A
C39: =VLOOKUP(B39,'Register Description'!$B$1:$C$220,2,FALSE) -> #N/A
C40: =VLOOKUP(B40,'Register Description'!$B$1:$C$220,2,FALSE) -> #N/A
C41: =VLOOKUP(B41,'Register Description'!$B$1:$C$220,2,FALSE) -> #N/A
...

Sheet Register Description
E3: Description
E9: Reset Source
E10: POR : release at VDD5 > VPOR_VDD5
E11: SWRES : RESET command by MCU
E13: Action items
E14: 1. CAN BUS 관련 Configure / Status register 검토
B20: Address | C20: Name | F20: Bit 11 | G20: Bit 10 | H20: Bit 9 | I20: Bit 8 | J20: Bit 7 | K20: Bit 6 | L20: Bit 5 | M20: Bit 4 | N20: Bit 3 | O20: Bit 2 | P20: Bit 1 | Q20: Bit 0 | S20: Comment
B21: 0x00 | C21: STATUS1 | E21: Content | F21: IC_STATE[3:0] (TBD) | J21: RSVD | K21: RFREQ_STATUS | L21: MASTER_MODE | M21: DEV_ADDR[2:0] | P21: SIO[1:0]
E22: Reset Value | F22: 0 | G22: 0 | H22: 0 | I22: 0 | J22: 0 | K22: 0 | L22: 0 | M22: 0 | N22: 0 | O22: 0 | P22: 0 | Q22: 0
E23: Reset Source | F23: POR, SWRES
E24: Access | F24: R | J24: R | K24: R | L24: R | M24: R | P24: R
E25: Bit Description | F25: IC_STATE : | H25: Represent current IC state. 0x0 : POWER_OFF (default) 0x1 : LOW_POWER 0x2 : NORMAL 0x3 : FAULT …......................
F26: RFREQ_STATUS : | H26: RFREQ pin value 0: No Open or Short (internal BUCK using) 1: Open or Short (external BUCK using)
F27: MASTER_MODE : | H27: Device Master Mode status 1: ADDR0 pin hi-z as master 0: ADDR0 pin not hi-z as slave
F28: DEV_ADDR : | H28: Device Address configured by ADDR0/ADDR1/ADDR2 pins
F29: SIO : | H29: Communication mode of SIO. 0x0 : LVDS / 0x1 : OPEN / 0x2 : MCU / 0x3 : UART Value is set automatically at startup and after reset.
B31: Address | C31: Name | F31: Bit 11 | G31: Bit 10 | H31: Bit 9 | I31: Bit 8 | J31: Bit 7 | K31: Bit 6 | L31: Bit 5 | M31: Bit 4 | N31: Bit 3 | O31: Bit 2 | P31: Bit 1 | Q31: Bit 0
B32: 0x01 | C32: STATUS2 | E32: Content | F32: 필요시, CAN_STATUS | G32: VB_IN_OV | H32: POR | I32: OTPCRC_FLT | J32: BUCK_OV | K32: BUCK_UV | L32: BUCK_UV_CRIT | M32: BUCK_OC | N32: BOOT_UV | O32: TW | P32: VC_OV | Q32: VDD5_UV
E33: Reset Value | F33: 0 | G33: 0 | H33: 1 | I33: 0 | J33: 0 | K33: 0 | L33: 0 | M33: 0 | N33: 0 | O33: 0 | P33: 0 | Q33: 0
E34: Reset Source | F34: POR, SWRES
E35: Access | F35: R | G35: RC | H35: RC | I35: RC | J35: RC | K35: RC | L35: RC | M35: RC | N35: RC | O35: RC | P35: RC | Q35: RC
E36: Bit Description | F36: VB_IN_OV : | H36: 1 : Battery input Over-Voltage flag (VB > ???)
F37: POR : | H37: 1 : POR occurred
F38: OTPCRC_FLT : | H38: 1 : This is set during startup and working when a mismatch between the OTP values and the internal CRC is detected
F39: BUCK_OV : | H39: 1 : BUCK Over-Voltage flag (VVIO > 5.6V)
F40: BUCK_UV : | H40: 1 : BUCK Under-Voltage flag (VVIO < 4.5V)
F41: BUCK_UV_CRIT : | H41: 1 : BUCK Critical Under-Voltage flag (VVIO < 4.0V)
F42: BUCK_OC : | H42: 1 : BUCK Over-Current flag (IVBCK_IO > 4.5A)
F43: BOOT_UV | H43: 1 : BOOT CAP Under-Voltage flag (VBOOT < 2.6V)
F44: TW : | H44: 1 : Over temperature warning flag is raised if the detection condition, TJ > 125°C (@Typ)
F45: VC_OV : | H45: 1 : Compensation Voltage Over-Voltage flag (IVBCK_IO > 4.5A or VBOOT < 2.6V or VBCK_IO pin open)
F46: VDD5_UV : | H46: 1 : VDD5 Under-Voltage flag (VDD5 < 3.9V)
B48: Address | C48: Name | F48: Bit 11 | G48: Bit 10 | H48: Bit 9 | I48: Bit 8 | J48: Bit 7 | K48: Bit 6 | L48: Bit 5 | M48: Bit 4 | N48: Bit 3 | O48: Bit 2 | P48: Bit 1 | Q48: Bit 0
B49: 0x02 | C49: STATUS3 | E49: Content | F49: GPIO2_FALLING_DET | G49: GPIO2_RISING_DET | H49: GPIO2_STATUS | I49: GPIO1_FALLING_DET | J49: GPIO1_RISING_DET | K49: GPIO1_STATUS | L49: GPIO0_FALLING_DET | M49: GPIO0_RISING_DET | N49: GPIO0_STATUS | O49: T_OUT | P49: CRC_FLT | Q49: COM_FLT
E50: Reset Value | F50: 0 | G50: 0 | H50: 0 | I50: 0 | J50: 0 | K50: 0 | L50: 0 | M50: 0 | N50: 0 | O50: 0 | P50: 0 | Q50: 0
E51: Reset Source | F51: POR, SWRES
E52: Access | F52: RC | G52: RC | H52: R | I52: RC | J52: RC | K52: R | L52: RC | M52: RC | N52: R | O52: RC | P52: RC | Q52: RC
E53: Bit Description | F53: GPIO2_FALLING_DET : | H53: 1 : GPIO2 input falling edge detected flag
F54: GPIO2_RISING_DET : | H54: 1 : GPIO2 input rising edge detected flag
F55: GPIO2_STATUS : | H55: GPIO2 input live status
...

Sheet Testmode Reg. Table
B2: ADDR | C2: Register | D2: Reset Type | E2: Read Write | F2: D15 | G2: D14 | H2: D13 | I2: D12 | J2: D11 | K2: D10 | L2: D9 | M2: D8 | N2: D7 | O2: D6 | P2: D5 | Q2: D4 | R2: D3 | S2: D2 | T2: D1 | U2: D0 | V2: DEFAULT bin | W2: DEFAULT
F3: I2C@TESTMODE
B4: TEST CONTROL
B5: 0xE0 | C5: TEST_CONTROL1 | D5: POR | E5: RW | F5: dumy | G5: dumy | H5: dumy | I5: dumy | J5: TM_LP_MASK | K5: TM_IDDQ_ALL | L5: TM_IDDQ_LDO_1P5V | M5: TM_IDDQ_LDO_VDD | N5: TM_FM_DAC_EN | O5: TM_FM_DAC_DATA | P5: TM_TSD_OT | Q5: TM_TSD_VCTAT | R5: TM_ATB_BIAS_EN | S5: TM_ATB1_SEL[2:0] | W5: =_xlfn.CONCAT("0x",BIN2HEX(MID(V5,1,4),1),BIN2HEX(MID(V5,6,4),1),BIN2HEX(MID(V5,11,4),1)) -> 0x000
B6: 0xE1 | C6: TEST_CONTROL2 | D6: POR | E6: RW | F6: dumy | G6: dumy | H6: dumy | I6: dumy | J6: TEST_E | K6: TM_F_SS_RESET_SEL | L6: TM_F_SS_RESET_EN | M6: TM_COMP_MSK | N6: TM_OTA_OFFSET | O6: TM_OTA_GM_DOWN_EN | P6: TM_CP_EN | Q6: TM_CP_DISABLE | R6: TM_BUCK_SS_DISABLE | S6: TM_BUCK_SS_LATCH_EN | T6: TM_GATE_FORCE_OFF | U6: TM_GATE_FORCE_ON | W6: =_xlfn.CONCAT("0x",BIN2HEX(MID(V6,1,4),1),BIN2HEX(MID(V6,6,4),1),BIN2HEX(MID(V6,11,4),1)) -> 0x000
B7: 0xE2 | C7: TEST_CONTROL3 | D7: POR | E7: RW | F7: dumy | G7: dumy | H7: dumy | I7: dumy | J7: TM_FSW_SWEEP_EN | K7: TM_BUCK_ATB1_EN | L7: TM_BUCK_ATB1_SEL[1:0] | N7: TM_ILIM_REDUCE | O7: TM_BUCK_ATB2_EN | P7: TM_BUCK_ATB2_SEL[1:0] | R7: TM_PFM_OS[1:0] | T7: TM_PFM_WEAK | U7: TM_PFM_DIS | W7: =_xlfn.CONCAT("0x",BIN2HEX(MID(V7,1,4),1),BIN2HEX(MID(V7,6,4),1),BIN2HEX(MID(V7,11,4),1)) -> 0x000
B8: 0xE3 | C8: TEST_CONTROL4 | D8: POR | E8: RW | F8: dumy | G8: dumy | H8: dumy | I8: dumy | J8: TM_LF_CLK_SEL[1:0] | L8: TM_SE_P_TX_IN_TEST | M8: TM_SE_N_TX_IN_TEST | N8: TM_LVDS_TX_IN_TEST | O8: TM_SIO_TEST_EN[2:0] | R8: TM_HIZ_RES_SW_ON | S8: TM_CLK_DIV_CON[2:0] | W8: =_xlfn.CONCAT("0x",BIN2HEX(MID(V8,1,4),1),BIN2HEX(MID(V8,6,4),1),BIN2HEX(MID(V8,11,4),1)) -> 0x000
B9: 0xE4 | C9: TEST_CONTROL5 | D9: POR | E9: RW | F9: dumy | G9: dumy | H9: dumy | I9: dumy | J9: TM_ENABLE_LOCK | K9: TM_HF_FM_FREQ[2:0] | N9: TM_HF_CLK_SEL[1:0] | P9: TM_HF_DUTY_EN | Q9: TM_HFP_EN | R9: TM_HF_EN | S9: TM_HF_MODE | T9: TM_LF_DUTY_EN | U9: TM_LFP_EN | W9: =_xlfn.CONCAT("0x",BIN2HEX(MID(V9,1,4),1),BIN2HEX(MID(V9,6,4),1),BIN2HEX(MID(V9,11,4),1)) -> 0x000
B10: 0xE5 | C10: TEST_CONTROL6 | D10: POR | E10: RW | F10: dumy | G10: dumy | H10: dumy | I10: dumy | J10: TM_F_RFREQ_SEL | K10: TM_GO_STBY | L10: TM_F_OSC_SEL | M10: TM_F_BUCK_SEL | N10: TM_F_FSW_SEL | O10: DTB1_MUX_EN | P10: DTB1_MUX_SEL | Q10: DTB1_MUX[4:0] | W10: =_xlfn.CONCAT("0x",BIN2HEX(MID(V10,1,4),1),BIN2HEX(MID(V10,6,4),1),BIN2HEX(MID(V10,11,4),1)) -> 0x000
B11: 0xE6 | C11: TEST_CONTROL7 | D11: POR | E11: RW | F11: dumy | G11: dumy | H11: dumy | I11: dumy | J11: TM_F_RFREQ_STATUS | K11: TM_GO_LOWPOWER | L11: TM_F_OSC_TOP_EN_D | M11: TM_F_BUCK_EN | N11: TM_F_FSW_450K_EN | O11: DTB2_MUX_EN | P11: DTB2_MUX_SEL | Q11: DTB2_MUX[4:0] | W11: =_xlfn.CONCAT("0x",BIN2HEX(MID(V11,1,4),1),BIN2HEX(MID(V11,6,4),1),BIN2HEX(MID(V11,11,4),1)) -> 0x000
B12: 0xE7 | C12: TEST_CONTROL8 | D12: POR | E12: RW | F12: dumy | G12: dumy | H12: dumy | I12: dumy | J12: TM_GAIN_TMON_EN | K12: DTB_BUCK_SEL[2:0] | N12: TM_IDDQ_1P5V_PWRSW_ON | O12: TM_ATB_2_SPARE_EN | P12: TM_ATB_2_SPARE_SEL[1:0] | R12: TM_ATB_1_BUF_EN | S12: TM_ATB_1_EN | T12: TM_ATB_2_BUF_EN | U12: TM_ATB_2_EN | W12: =_xlfn.CONCAT("0x",BIN2HEX(MID(V12,1,4),1),BIN2HEX(MID(V12,6,4),1),BIN2HEX(MID(V12,11,4),1)) -> 0x000
B13: 0xE8 | C13: TEST_CONTROL9 | D13: POR | E13: RW | F13: dumy | G13: dumy | H13: dumy | I13: dumy | J13: RSVD | K13: RSVD | L13: RSVD | M13: TM_ANA_TEST_EN | N13: RSVD | O13: TM_EXT_CLK_SEL | P13: TM_VIO_SEL | Q13: TM_VIO_MUX_EN | R13: TM_ADC_IN_SEL[1:0] | T13: TM_ADC_IN_CTL | U13: TM_ADC_EN | V13: 0000_0000_0000 | W13: =_xlfn.CONCAT("0x",BIN2HEX(MID(V13,1,4),1),BIN2HEX(MID(V13,6,4),1),BIN2HEX(MID(V13,11,4),1)) -> 0x000
B14: 0xE9 | C14: TEST_CONTROL10 | D14: POR | E14: RW | F14: dumy | G14: dumy | H14: dumy | I14: dumy | J14: RSVD | K14: RSVD | L14: RSVD | M14: RSVD | N14: RSVD | O14: RSVD | P14: RSVD | Q14: RSVD | R14: RSVD | S14: RSVD | T14: RSVD | U14: RSVD | V14: 0000_0000_0000 | W14: =_xlfn.CONCAT("0x",BIN2HEX(MID(V14,1,4),1),BIN2HEX(MID(V14,6,4),1),BIN2HEX(MID(V14,11,4),1)) -> 0x000
B15: 0xEA | C15: TEST_CONTROL11 | D15: POR | E15: RW | F15: dumy | G15: dumy | H15: dumy | I15: dumy | J15: RSVD | K15: RSVD | L15: RSVD | M15: RSVD | N15: RSVD | O15: RSVD | P15: RSVD | Q15: RSVD | R15: RSVD | S15: RSVD | T15: RSVD | U15: RSVD | V15: 0000_0000_0000 | W15: =_xlfn.CONCAT("0x",BIN2HEX(MID(V15,1,4),1),BIN2HEX(MID(V15,6,4),1),BIN2HEX(MID(V15,11,4),1)) -> 0x000
B17: OTP CONTRTOL
B18: 0xEB | C18: OTP_CONTROL1 | D18: POR | E18: RW | F18: dumy | G18: dumy | H18: dumy | I18: dumy | J18: OTP_WSEL [3:0] | P18: OTP_RSEL[1:0] | R18: OTP_PG | S18: OTP_CRC_START | U18: OTP_RD | V18: 0100_0000_0000 | W18: =_xlfn.CONCAT("0x",BIN2HEX(MID(V18,1,4),1),BIN2HEX(MID(V18,6,4),1),BIN2HEX(MID(V18,11,4),1)) -> 0x400
B19: 0xEC | C19: OTP_CONTROL2 | D19: POR | E19: RW | F19: dumy | G19: dumy | H19: dumy | I19: dumy | J19: OTP_PG_ACC_CYCLE [11:0] | V19: 0001_1001_0000 | W19: =_xlfn.CONCAT("0x",BIN2HEX(MID(V19,1,4),1),BIN2HEX(MID(V19,6,4),1),BIN2HEX(MID(V19,11,4),1)) -> 0x190
B20: 0xED | C20: OTP_CONTROL3 | D20: POR | E20: RW | F20: dumy | G20: dumy | H20: dumy | I20: dumy | J20: PROTECT [11:0] | V20: 0101_1010_0101 | W20: =_xlfn.CONCAT("0x",BIN2HEX(MID(V20,1,4),1),BIN2HEX(MID(V20,6,4),1),BIN2HEX(MID(V20,11,4),1)) -> 0x5A5
B22: TRIM CONTROL | X22: Total Bit | Y22: Not Use # | Z22: Spare # | AA22: Use #
B23: 0xEE | C23: OTP1_MIRROR1 | D23: POR | E23: RW | F23: dumy | G23: dumy | H23: dumy | I23: dumy | J23: CHIP_ID_1[11:0] | V23: 0000_0000_0000 | W23: =_xlfn.CONCAT("0x",BIN2HEX(MID(V23,1,4),1),BIN2HEX(MID(V23,6,4),1),BIN2HEX(MID(V23,11,4),1)) -> 0x000 | X23: 12
B24: 0xEF | C24: OTP1_MIRROR2 | D24: POR | E24: RW | F24: dumy | G24: dumy | H24: dumy | I24: dumy | J24: CHIP_ID_2[11:0] | V24: 0000_0000_0000 | W24: =_xlfn.CONCAT("0x",BIN2HEX(MID(V24,1,4),1),BIN2HEX(MID(V24,6,4),1),BIN2HEX(MID(V24,11,4),1)) -> 0x000 | X24: 12
B25: 0xF0 | C25: OTP1_MIRROR3 | D25: POR | E25: RW | F25: dumy | G25: dumy | H25: dumy | I25: dumy | J25: CHIP_ID_3[11:0] | V25: 0000_0000_0000 | W25: =_xlfn.CONCAT("0x",BIN2HEX(MID(V25,1,4),1),BIN2HEX(MID(V25,6,4),1),BIN2HEX(MID(V25,11,4),1)) -> 0x000 | X25: 12
B26: 0xF1 | C26: OTP1_MIRROR4 | D26: POR | E26: RW | F26: dumy | G26: dumy | H26: dumy | I26: dumy | J26: CHIP_ID_4[11:0] | V26: 0000_0000_0000 | W26: =_xlfn.CONCAT("0x",BIN2HEX(MID(V26,1,4),1),BIN2HEX(MID(V26,6,4),1),BIN2HEX(MID(V26,11,4),1)) -> 0x000 | X26: 12
B27: 0xF2 | C27: OTP1_MIRROR5 | D27: POR | E27: RW | F27: dumy | G27: dumy | H27: dumy | I27: dumy | J27: TRIM_BG_LVL[3:0] | N27: TRIM_VLDO_CORE[2:0] | Q27: TRIM_BG[4:0] | W27: =_xlfn.CONCAT("0x",BIN2HEX(MID(V27,1,4),1),BIN2HEX(MID(V27,6,4),1),BIN2HEX(MID(V27,11,4),1)) -> 0x000 | X27: 12
B28: 0xF3 | C28: OTP1_MIRROR6 | D28: POR | E28: RW | F28: dumy | G28: dumy | H28: dumy | I28: dumy | J28: TRIM_LP_OSC[3:0] | N28: TRIM_IREF[3:0] | R28: TRIM_IPTAT[3:0] | W28: =_xlfn.CONCAT("0x",BIN2HEX(MID(V28,1,4),1),BIN2HEX(MID(V28,6,4),1),BIN2HEX(MID(V28,11,4),1)) -> 0x000 | X28: 12
B29: 0xF4 | C29: OTP1_MIRROR7 | D29: POR | E29: RW | F29: dumy | G29: dumy | H29: dumy | I29: dumy | J29: TRIM_32M_OSC_TEMP[3:0] | N29: TRIM_32MOSC[7:0] | W29: =_xlfn.CONCAT("0x",BIN2HEX(MID(V29,1,4),1),BIN2HEX(MID(V29,6,4),1),BIN2HEX(MID(V29,11,4),1)) -> 0x000 | X29: 12
B30: 0xF5 | C30: OTP1_MIRROR8 | D30: POR | E30: RW | F30: dumy | G30: dumy | H30: dumy | I30: dumy | J30: na | K30: TRIM_GAIN_TMON[2:0] | N30: TRIM_OFST_TMON[3:0] | R30: TRIM_OSC_BIAS[3:0] | W30: =_xlfn.CONCAT("0x",BIN2HEX(MID(V30,1,4),1),BIN2HEX(MID(V30,6,4),1),BIN2HEX(MID(V30,11,4),1)) -> 0x000 | X30: 12 | Y30: 1
B31: 0xF6 | C31: OTP1_MIRROR9 | D31: POR | E31: RW | F31: dumy | G31: dumy | H31: dumy | I31: dumy | J31: TRIM_ILIM[3:0] | N31: na | O31: TRIM_BUCK_RC[2:0] | R31: na | S31: TRIM_BUCK_CC[2:0] | W31: =_xlfn.CONCAT("0x",BIN2HEX(MID(V31,1,4),1),BIN2HEX(MID(V31,6,4),1),BIN2HEX(MID(V31,11,4),1)) -> 0x000 | X31: 12 | Y31: 2
B32: 0xF7 | C32: OTP1_MIRROR10 | D32: POR | E32: RW | F32: dumy | G32: dumy | H32: dumy | I32: dumy | J32: TRIM_BUCK_SS_CLK_SEL[1:0] | L32: TRIM_CURR_SLP[1:0] | N32: TRIM_PRE_DRV[1:0] | P32: TRIM_LVDS_RX_RES[1:0] | R32: na | S32: TRIM_LVDS_TX[2:0] | W32: =_xlfn.CONCAT("0x",BIN2HEX(MID(V32,1,4),1),BIN2HEX(MID(V32,6,4),1),BIN2HEX(MID(V32,11,4),1)) -> 0x000 | X32: 12 | Y32: 1
B33: 0xF8 | C33: OTP1_MIRROR11 | D33: POR | E33: RW | F33: dumy | G33: dumy | H33: dumy | I33: dumy | J33: na | K33: na | L33: na | M33: ADC_OFFSET[8:0] | V33: 0000_0000_0000 | W33: =_xlfn.CONCAT("0x",BIN2HEX(MID(V33,1,4),1),BIN2HEX(MID(V33,6,4),1),BIN2HEX(MID(V33,11,4),1)) -> 0x000 | X33: 12 | Y33: 3
B34: 0xF9 | C34: OTP1_MIRROR12 | D34: POR | E34: RW | F34: dumy | G34: dumy | H34: dumy | I34: dumy | J34: SPARE_1[6] | K34: SPARE_1[5] | L34: SPARE_1[4] | M34: SPARE_1[3] | N34: SPARE_1[2] | O34: SPARE_1[1] | P34: SPARE_1[0] | Q34: ADC_GAIN[4:0] | V34: 0000_0001_0000 | W34: =_xlfn.CONCAT("0x",BIN2HEX(MID(V34,1,4),1),BIN2HEX(MID(V34,6,4),1),BIN2HEX(MID(V34,11,4),1)) -> 0x010 | X34: 12 | Z34: 7
B35: 0xFA | C35: OTP1_MIRROR13 | D35: POR | E35: RW | F35: dumy | G35: dumy | H35: dumy | I35: dumy | J35: DLY_OFF[3:0] | N35: DLY_ON[4:0] | S35: RXD_DUTY_CCTL[2:0] | W35: =_xlfn.CONCAT("0x",BIN2HEX(MID(V35,1,4),1),BIN2HEX(MID(V35,6,4),1),BIN2HEX(MID(V35,11,4),1)) -> 0x000 | X35: 12 | Y35: 1
B36: 0xFB | C36: OTP1_MIRROR14 | D36: POR | E36: RW | F36: dumy | G36: dumy | H36: dumy | I36: dumy | J36: VPP_CTL[3:0] | N36: na | O36: NCU_CTL[2:0] | R36: na | S36: PCU_CTL[2:0] | W36: =_xlfn.CONCAT("0x",BIN2HEX(MID(V36,1,4),1),BIN2HEX(MID(V36,6,4),1),BIN2HEX(MID(V36,11,4),1)) -> 0x000 | X36: 12 | Y36: 2
B37: 0xFC | C37: OTP1_MIRROR15 | D37: POR | E37: RW | F37: dumy | G37: dumy | H37: dumy | I37: dumy | J37: na | K37: HYS_RCON[2:0] | N37: ID_CTL | O37: HYS_DCON[2:0] | R37: na | S37: RXD_DUTY_CCTL2[2:0] | W37: =_xlfn.CONCAT("0x",BIN2HEX(MID(V37,1,4),1),BIN2HEX(MID(V37,6,4),1),BIN2HEX(MID(V37,11,4),1)) -> 0x000 | X37: 12 | Y37: 2
B38: 0xFD | C38: OTP2_MIRROR16 | D38: POR | E38: RW | F38: dumy | G38: dumy | H38: dumy | I38: dumy | J38: SPARE_2[6] | K38: SPARE_2[5] | L38: SPARE_2[4] | M38: SPARE_2[3] | N38: SPARE_2[2] | O38: SPARE_2[1] | P38: SPARE_2[0] | Q38: na | R38: HYSL_RCON[1:0] | T38: HYSL_DCON[1:0] | W38: =_xlfn.CONCAT("0x",BIN2HEX(MID(V38,1,4),1),BIN2HEX(MID(V38,6,4),1),BIN2HEX(MID(V38,11,4),1)) -> 0x000 | X38: 12 | Z38: 8
B39: 0xFE | C39: OTP2_MIRROR17 | D39: POR | E39: RW | F39: dumy | G39: dumy | H39: dumy | I39: dumy | J39: OTP_CRC[7:0] | R39: SPARE_3[3] | S39: SPARE_3[2] | T39: SPARE_3[1] | U39: SPARE_3[0] | V39: 0000_0000_0000 | W39: =_xlfn.CONCAT("0x",BIN2HEX(MID(V39,1,4),1),BIN2HEX(MID(V39,6,4),1),BIN2HEX(MID(V39,11,4),1)) -> 0x000 | X39: 12 | Z39: 4
W40: Bit # | X40: =SUM(X23:X39) -> 204 | Y40: =SUM(Y23:Y39) -> 12 | Z40: =SUM(Z23:Z39) -> 19 | AA40: =X40-Y40 -> 192
W42: efuse # | X42: =X40/$W$43 -> 3.1875 | AA42: =AA40/$W$43 -> 3
W43: 64

Sheet Testmode Reg Description
E3: Description
E9: Reset Source
E10: POR : release at VDD5 > VPOR_VDD5
E11: SWRES : RESET command by MCU
E13: Action items
E14: 1. CAN BUS 관련 Configure / Status register 검토
B20: Address | C20: Name | F20: Bit 11 | G20: Bit 10 | H20: Bit 9 | I20: Bit 8 | J20: Bit 7 | K20: Bit 6 | L20: Bit 5 | M20: Bit 4 | N20: Bit 3 | O20: Bit 2 | P20: Bit 1 | Q20: Bit 0 | S20: Comment
B21: 0xE0 | C21: TEST_CONTROL1 | E21: Content | F21: TM_LP_MASK | G21: TM_IDDQ_ALL | H21: TM_IDDQ_LDO_1P5V | I21: TM_IDDQ_LDO_VDD | J21: TM_FM_DAC_EN | K21: TM_FM_DAC_DATA | L21: TM_TSD_OT | M21: TM_TSD_VCTAT | N21: TM_ATB_BIAS_EN | O21: TM_ATB1_SEL[2:0]
E22: Reset Value | F22: 0 | G22: 0 | H22: 0 | I22: 0 | J22: 0 | K22: 0 | L22: 0 | M22: 0 | N22: 0 | O22: 0 | P22: 0 | Q22: 0
E23: Reset Source | F23: POR, SWRES
E24: Access | F24: RW | G24: RW | H24: RW | I24: RW | J24: RW | K24: RW | L24: RW | M24: RW | N24: RW | O24: RW | P24: RW | Q24: RW
E25: Bit Description | F25: TM_LP_MASK | H25: Masking Register for LP OSC (If enable this signal, when enter LP mode, LP OSC block is not disable)
F26: TM_IDDQ_ALL | H26: IDDQ Signal to disable All block
F27: TM_IDDQ_LDO_1P5V | H27: IDDQ Signal to disable 1.5V LDO block
F28: TM_IDDQ_LDO_VDD | H28: IDDQ Signal to disable 5.0V LDO block
F29: TM_FM_DAC_EN | H29: For test SSC Function (If enable this signal, SSC function set only Max or Min value)
F30: TM_FM_DAC_DATA | H30: For test SSC Function (0 : SSC Min / 1 : SSC Max)
F31: TM_TSD_OT | H31: TSD_TEST_Enable signal (ATB1_IN)
F32: TM_TSD_VCTAT | H32: TSD_TEST_Enable signal (ATB1_OUT)
F33: TM_ATB_BIAS_EN | H33: BIAS Block Test mode Path enable signal
F34: TM_ATB1_SEL[2:0] | H34: BIAS Block ATB Items [2:0] 000 : ATB_IBP530nA 001 : VBG_1p2_lvl 010 : IREF_TEST_3uA 011 : VREF_1p2V 100 : IPTAT_TEST_1uA 101 : ATB1_TSD_IN 110 : ATB1_TSD_OUT 111 : VREF_2p5v
B36: Address | C36: Name | F36: Bit 11 | G36: Bit 10 | H36: Bit 9 | I36: Bit 8 | J36: Bit 7 | K36: Bit 6 | L36: Bit 5 | M36: Bit 4 | N36: Bit 3 | O36: Bit 2 | P36: Bit 1 | Q36: Bit 0
B37: 0xE1 | C37: TEST_CONTROL2 | E37: Content | F37: TEST_E | G37: TM_F_SS_RESET_SEL | H37: TM_F_SS_RESET_EN | I37: TM_COMP_MSK | J37: TM_OTA_OFFSET | K37: TM_OTA_GM_DOWN_EN | L37: TM_CP_EN | M37: TM_CP_DISABLE | N37: TM_BUCK_SS_DISABLE | O37: TM_BUCK_SS_LATCH_EN | P37: TM_GATE_FORCE_OFF | Q37: TM_GATE_FORCE_ON
E38: Reset Value | F38: 0 | G38: 0 | H38: 0 | I38: 0 | J38: 0 | K38: 0 | L38: 0 | M38: 0 | N38: 0 | O38: 0 | P38: 0 | Q38: 0
E39: Reset Source | F39: POR, SWRES
E40: Access | F40: RW | G40: RW | H40: RW | I40: RW | J40: RW | K40: RW | L40: RW | M40: RW | N40: RW | O40: RW | P40: RW | Q40: RW
E41: Bit Description | F41: TEST_E | H41: Test Mode Register Lock Disable Function Register (0 : Lock All TM Register , 1 : Unlock All TM Register)
F42: TM_F_SS_RESET_SEL | H42: Work Around Point - SS_RESET_SEL Control BIT 0 : internal singal use (default) / 1 : TM_F_SS_RESET_EN
F43: TM_F_SS_RESET_EN | H43: Work Around Point - TM_F_SS_RESET_EN Control BIT
F44: TM_COMP_MSK | H44: Output of the HV OCP_COMP is blocked (Iout < approximately 3A)
F45: TM_OTA_OFFSET | H45: Internal OTA is connected as a unit-gain buffer
F46: TM_OTA_GM_DOWN_EN | H46: Gm of the internal OTA decreases. (80uS->60uS)
F47: TM_CP_EN | H47: Charge pump is enabled. (With 8MHz frequency)
F48: TM_CP_DISABLE | H48: Charge pump is disabled.
F49: TM_BUCK_SS_DISABLE | H49: Soft-start is disabled.
F50: TM_BUCK_SS_LATCH_EN | H50: At the end of the soft-start, the soft-start output is not connected to VDD5
F51: TM_GATE_FORCE_OFF | H51: The internal power switch is turned OFF.
